Workbook
Name linkkksss: INDIRECT(ADDRESS(1,1,,,Dashboard!A1))
Name sheet_link: INDIRECT(ADDRESS(7,3,,,Dashboard!DY1048576))
Name Shheet_Link: INDIRECT(ADDRESS(7,3,,,Dashboard!A1))
Name shshshs: INDIRECT(ADDRESS(1,1,,,Dashboard!A1))

Sheet Dashboard
C2: Income Statement
C3: Dashboard | R3: HQ
H7: YEAR TOTAL EXPENSES & YEAR TOTAL INCOME CHART
C8: Income Statement
C9: (YEAR TOTAL) | EJ9: =ADDRESS(7,3,,,R3) -> HQ!$C$7
C11: Total Sales Revenue | D11: : | E11: =AB42 -> 6.1514269e+08
C12: Total Cost of Sales | D12: : | E12: =AC42 -> 4.9701381e+08
C13: Gross Profit | D13: : | E13: =E11-E12 -> 1.1812888e+08
C14: Total Non-Operational Income | D14: : | E14: =AF42 -> 15963483
C15: TOTAL INCOME | D15: : | E15: =E13+E14 -> 1.3409236e+08
C18: TOTAL EXPENSES | D18: : | E18: =AE42 -> 1.1783265e+08 | EI18: تقرير المصروفات حسب الشهر
EI19: تقرير مصروفات إجمالية
EI20: تقرير إحصائية بحجم المبيعات
EI21: تقرير مجمعة حسب الشهر | EJ21: HQ
C22: NET PROFIT | D22: : | E22: =E15-E18 -> 16259709 | EI22: تقرير مصروفات حسب الفرع | EJ22: Aguza
EI23: مجمعة إجمالية | EJ23: October
EJ24: Batal
H25: December | EJ25: Nasr City
EJ26: Sweedy
C27: MONTH TOTAL | H27: EXPENSES DETAILS (MONTH TOTAL) | EJ27: Raya
C28: Income Statement | H28: Operating Expenses | EJ28: Etisalat
C29: =H25 -> December | H29: مرتبات الادارة | J29: =VLOOKUP($H$25,$AA$90:$EI$101,2,FALSE) -> 1313581.9 | K29: =J29/$E$36 -> 0.10384709 | M29: اعلان ودعاية - ايام دعاية | O29: =VLOOKUP($H$25,$AA$90:$EI$101,58,FALSE) -> 0 | P29: =O29/$E$36 -> 0 | AA29: Monthes | AB29: Total Sales Revenue | AC29: Total Cost of Sales | AD29: Total Income | AE29: Total Operating Expenses | AF29: Total Non-Operational Income | AG29: Net Profit | EJ29: Hazzem Hassan
H30: مرتبات الفروع | J30: =VLOOKUP($H$25,$AA$90:$EI$101,3,FALSE) -> 4020526.8 | K30: =J30/$E$36 -> 0.31784847 | M30: اكراميات - ايام دعاية | O30: =VLOOKUP($H$25,$AA$90:$EI$101,59,FALSE) -> 0 | P30: =O30/$E$36 -> 0 | AA30: January | AB30: ='تقرير مجمعة حسب الشهر'!G37 -> 40806682 | AC30: ='تقرير مجمعة حسب الشهر'!I37 -> 32885217 | AD30: ='تقرير مجمعة حسب الشهر'!J37 -> 7921465 | AE30: ='تقرير مجمعة حسب الشهر'!K37 -> 7206089.6 | AF30: ='تقرير مجمعة حسب الشهر'!M37 -> 499374.95 | AG30: =AD30-AE30+AF30 -> 1214750.4 | EJ30: Sena3ia
C31: Total Sales Revenue | D31: : | E31: =VLOOKUP(H25,AA30:AG41,MATCH(C31,AA29:AG29,0),0) -> 62205513 | H31: الكهرباء | J31: =VLOOKUP($H$25,$AA$90:$EI$101,4,FALSE) -> 70345 | K31: =J31/$E$36 -> 0.0055612241 | M31: وجبات وانتقال - ايام دعاية | O31: =VLOOKUP($H$25,$AA$90:$EI$101,60,FALSE) -> 0 | P31: =O31/$E$36 -> 0 | AA31: February | AB31: ='تقرير مجمعة حسب الشهر'!G72 -> 39943440 | AC31: ='تقرير مجمعة حسب الشهر'!I72 -> 32572061 | AD31: ='تقرير مجمعة حسب الشهر'!J72 -> 7371378.7 | AE31: ='تقرير مجمعة حسب الشهر'!K72 -> 7814841 | AF31: ='تقرير مجمعة حسب الشهر'!M72 -> 830716.73 | AG31: =AD31-AE31+AF31 -> 387254.39 | EJ31: Khargia
C32: Total Cost of Sales | D32: : | E32: =VLOOKUP(H25,AA30:AG41,MATCH(C32,AA29:AG29,0),0) -> 49741295 | H32: المياه | J32: =VLOOKUP($H$25,$AA$90:$EI$101,5,FALSE) -> 8069 | K32: =J32/$E$36 -> 0.00063790628 | M32: مكافات لجنة الجرد | O32: =VLOOKUP($H$25,$AA$90:$EI$101,61,FALSE) -> 57487 | P32: =O32/$E$36 -> 0.0045447166 | AA32: March | AB32: ='تقرير مجمعة حسب الشهر'!G108 -> 44391759 | AC32: ='تقرير مجمعة حسب الشهر'!I108 -> 36062858 | AD32: ='تقرير مجمعة حسب الشهر'!J108 -> 8328901.2 | AE32: ='تقرير مجمعة حسب الشهر'!K108 -> 8264417.5 | AF32: ='تقرير مجمعة حسب الشهر'!M108 -> 757642.93 | AG32: =AD32-AE32+AF32 -> 822126.6 | EJ32: Tagmou3
C33: Gross Profit | D33: : | E33: =E31-E32 -> 12464219 | H33: التليفون الارضي | J33: =VLOOKUP($H$25,$AA$90:$EI$101,6,FALSE) -> 0 | K33: =J33/$E$36 -> 0 | M33: انتقالات لجنة الجرد | O33: =VLOOKUP($H$25,$AA$90:$EI$101,62,FALSE) -> 0 | P33: =O33/$E$36 -> 0 | AA33: April | AB33: ='تقرير مجمعة حسب الشهر'!G144 -> 47015527 | AC33: ='تقرير مجمعة حسب الشهر'!I144 -> 38233327 | AD33: ='تقرير مجمعة حسب الشهر'!J144 -> 8782200.4 | AE33: ='تقرير مجمعة حسب الشهر'!K144 -> 8907714.6 | AF33: ='تقرير مجمعة حسب الشهر'!M144 -> 979531.25 | AG33: =AD33-AE33+AF33 -> 854017.1 | EJ33: Maadi
C34: Total Non-Operational Income | D34: : | E34: =VLOOKUP(H25,AA30:AG41,MATCH(C34,AA29:AG29,0),0) -> 5085004.7 | H34: الايجار - الصيدلية | J34: =VLOOKUP($H$25,$AA$90:$EI$101,7,FALSE) -> 510000 | K34: =J34/$E$36 -> 0.040318776 | M34: وجبات لجنة الجرد | O34: =VLOOKUP($H$25,$AA$90:$EI$101,63,FALSE) -> 8375 | P34: =O34/$E$36 -> 0.00066209754 | AA34: May | AB34: ='تقرير مجمعة حسب الشهر'!G180 -> 50394566 | AC34: ='تقرير مجمعة حسب الشهر'!I180 -> 40884079 | AD34: ='تقرير مجمعة حسب الشهر'!J180 -> 9510486.9 | AE34: ='تقرير مجمعة حسب الشهر'!K180 -> 8875833.8 | AF34: ='تقرير مجمعة حسب الشهر'!M180 -> 1545161.9 | AG34: =AD34-AE34+AF34 -> 2179815.1 | EJ34: Zaid
C35: TOTAL INCOME | D35: : | E35: =E33+E34 -> 17549224 | H35: الايجار - الادارة | J35: =VLOOKUP($H$25,$AA$90:$EI$101,8,FALSE) -> 50000 | K35: =J35/$E$36 -> 0.0039528212 | M35: مسروقات | O35: =VLOOKUP($H$25,$AA$90:$EI$101,64,FALSE) -> 0 | P35: =O35/$E$36 -> 0 | AA35: June | AB35: ='تقرير مجمعة حسب الشهر'!G216 -> 51071696 | AC35: ='تقرير مجمعة حسب الشهر'!I216 -> 41196730 | AD35: ='تقرير مجمعة حسب الشهر'!J216 -> 9874965.6 | AE35: ='تقرير مجمعة حسب الشهر'!K216 -> 10183140 | AF35: ='تقرير مجمعة حسب الشهر'!M216 -> 1123699.4 | AG35: =AD35-AE35+AF35 -> 815525.37 | EJ35: Sand Beach
C36: Total Operating Expenses | D36: : | E36: =VLOOKUP(H25,AA30:AG41,MATCH(C36,AA29:AG29,0),0) -> 12649194 | H36: ايجارات متنوعه | J36: =VLOOKUP($H$25,$AA$90:$EI$101,9,FALSE) -> 406756 | K36: =J36/$E$36 -> 0.032156674 | M36: غرامات | O36: =VLOOKUP($H$25,$AA$90:$EI$101,65,FALSE) -> 3005 | P36: =O36/$E$36 -> 0.00023756455 | AA36: July | AB36: ='تقرير مجمعة حسب الشهر'!G252 -> 53894045 | AC36: ='تقرير مجمعة حسب الشهر'!I252 -> 43477556 | AD36: ='تقرير مجمعة حسب الشهر'!J252 -> 10416489 | AE36: ='تقرير مجمعة حسب الشهر'!K252 -> 10168253 | AF36: ='تقرير مجمعة حسب الشهر'!M252 -> 864132.46 | AG36: =AD36-AE36+AF36 -> 1112367.7 | EJ36: Alamya
H37: ادوات مكتبية | J37: =VLOOKUP($H$25,$AA$90:$EI$101,10,FALSE) -> 23690 | K37: =J37/$E$36 -> 0.0018728467 | M37: مستلزمات كمبيوتر | O37: =VLOOKUP($H$25,$AA$90:$EI$101,66,FALSE) -> 15763.5 | P37: =O37/$E$36 -> 0.0012462059 | AA37: August | AB37: ='تقرير مجمعة حسب الشهر'!G288 -> 56253509 | AC37: ='تقرير مجمعة حسب الشهر'!I288 -> 45438716 | AD37: ='تقرير مجمعة حسب الشهر'!J288 -> 10814792 | AE37: ='تقرير مجمعة حسب الشهر'!K288 -> 10307079 | AF37: ='تقرير مجمعة حسب الشهر'!M288 -> 947444.07 | AG37: =AD37-AE37+AF37 -> 1455157.5 | EJ37: Online
C38: TOTAL EXPENSES | D38: : | E38: =E36+E37 -> 12649194 | H38: فواتير الموبايل | J38: =VLOOKUP($H$25,$AA$90:$EI$101,11,FALSE) -> 25005.69 | K38: =J38/$E$36 -> 0.0019768604 | M38: صيانة اجهزة كمبيوتر | O38: =VLOOKUP($H$25,$AA$90:$EI$101,67,FALSE) -> 168858 | P38: =O38/$E$36 -> 0.013349309 | AA38: September | AB38: ='تقرير مجمعة حسب الشهر'!G324 -> 52570347 | AC38: ='تقرير مجمعة حسب الشهر'!I324 -> 42515878 | AD38: ='تقرير مجمعة حسب الشهر'!J324 -> 10054469 | AE38: ='تقرير مجمعة حسب الشهر'!K324 -> 11127271 | AF38: ='تقرير مجمعة حسب الشهر'!M324 -> 1587116 | AG38: =AD38-AE38+AF38 -> 514313.42 | EJ38: Orange
H39: مكافات مبيعات الادوية | J39: =VLOOKUP($H$25,$AA$90:$EI$101,12,FALSE) -> 0 | K39: =J39/$E$36 -> 0 | M39: مطبوعات ورقية | O39: =VLOOKUP($H$25,$AA$90:$EI$101,68,FALSE) -> 0 | P39: =O39/$E$36 -> 0 | AA39: October | AB39: ='تقرير مجمعة حسب الشهر'!G360 -> 58202856 | AC39: ='تقرير مجمعة حسب الشهر'!I360 -> 46888176 | AD39: ='تقرير مجمعة حسب الشهر'!J360 -> 11314681 | AE39: ='تقرير مجمعة حسب الشهر'!K360 -> 11138990 | AF39: ='تقرير مجمعة حسب الشهر'!M360 -> 700625.77 | AG39: =AD39-AE39+AF39 -> 876316.71 | EJ39: Vod.Smart
C40: NET PROFIT | D40: : | E40: =E35-E38-E39 -> 4900030 | H40: مكافات مبيعات التجميل | J40: =VLOOKUP($H$25,$AA$90:$EI$101,13,FALSE) -> 28828.5 | K40: =J40/$E$36 -> 0.0022790781 | M40: شحن بضاعة | O40: =VLOOKUP($H$25,$AA$90:$EI$101,69,FALSE) -> 0 | P40: =O40/$E$36 -> 0 | AA40: November | AB40: ='تقرير مجمعة حسب الشهر'!G396 -> 58392748 | AC40: ='تقرير مجمعة حسب الشهر'!I396 -> 47117919 | AD40: ='تقرير مجمعة حسب الشهر'!J396 -> 11274829 | AE40: ='تقرير مجمعة حسب الشهر'!K396 -> 11189827 | AF40: ='تقرير مجمعة حسب الشهر'!M396 -> 1043032.8 | AG40: =AD40-AE40+AF40 -> 1128034.3 | EJ40: Vod.Zahraa
H41: بوفية وضيافة | J41: =VLOOKUP($H$25,$AA$90:$EI$101,14,FALSE) -> 18790 | K41: =J41/$E$36 -> 0.0014854702 | M41: عيديات ومناسبات | O41: =VLOOKUP($H$25,$AA$90:$EI$101,70,FALSE) -> 0 | P41: =O41/$E$36 -> 0 | AA41: December | AB41: ='تقرير مجمعة حسب الشهر'!G432 -> 62205513 | AC41: ='تقرير مجمعة حسب الشهر'!I432 -> 49741295 | AD41: ='تقرير مجمعة حسب الشهر'!J432 -> 12464219 | AE41: ='تقرير مجمعة حسب الشهر'!K432 -> 12649194 | AF41: ='تقرير مجمعة حسب الشهر'!M432 -> 5085004.7 | AG41: =AD41-AE41+AF41 -> 4900030 | EJ41: Mo7awelat
H42: رسوم وتراخيص وعمولات | J42: =VLOOKUP($H$25,$AA$90:$EI$101,15,FALSE) -> 24875 | K42: =J42/$E$36 -> 0.0019665285 | M42: بدلات متنوعه | O42: =VLOOKUP($H$25,$AA$90:$EI$101,71,FALSE) -> 265150 | P42: =O42/$E$36 -> 0.020961811 | AA42: Total | AB42: =SUM(AB30:AB41) -> 6.1514269e+08 | AC42: =SUM(AC30:AC41) -> 4.9701381e+08 | AD42: =SUM(AD30:AD41) -> 1.1812888e+08 | AE42: =SUM(AE30:AE41) -> 1.1783265e+08 | AF42: =SUM(AF30:AF41) -> 15963483 | AG42: =SUM(AG30:AG41) -> 16259709 | EJ42: Electric
H43: ورق طباعة | J43: =VLOOKUP($H$25,$AA$90:$EI$101,16,FALSE) -> 38500 | K43: =J43/$E$36 -> 0.0030436723 | M43: اجهزة ومستلزمات متنوعه | O43: =VLOOKUP($H$25,$AA$90:$EI$101,72,FALSE) -> 54285 | P43: =O43/$E$36 -> 0.0042915779 | EJ43: M.C.V
H44: بكر طباعة ريسيت | J44: =VLOOKUP($H$25,$AA$90:$EI$101,17,FALSE) -> 54240 | K44: =J44/$E$36 -> 0.0042880204 | M44: احبار طابعات | O44: =VLOOKUP($H$25,$AA$90:$EI$101,73,FALSE) -> 0 | P44: =O44/$E$36 -> 0 | EJ44: Egyplast
H45: بكر طباعة باركود | J45: =VLOOKUP($H$25,$AA$90:$EI$101,18,FALSE) -> 130 | K45: =J45/$E$36 -> 1.0277335e-05 | M45: الانترنت | O45: =VLOOKUP($H$25,$AA$90:$EI$101,74,FALSE) -> 12044.67 | P45: =O45/$E$36 -> 0.00095220853 | EJ45: Etisalat.Katamya
H46: اعلان ودعاية وتسويق | J46: =VLOOKUP($H$25,$AA$90:$EI$101,19,FALSE) -> 55892 | K46: =J46/$E$36 -> 0.0044186216 | M46: الدعم الفني - سوفتك | O46: =VLOOKUP($H$25,$AA$90:$EI$101,75,FALSE) -> 169125 | P46: =O46/$E$36 -> 0.013370418 | EJ46: CFC
H47: اكراميات | J47: =VLOOKUP($H$25,$AA$90:$EI$101,20,FALSE) -> 23831.75 | K47: =J47/$E$36 -> 0.0018840529 | M47: مصروف اهلاك مباني وانشاءات | O47: =VLOOKUP($H$25,$AA$90:$EI$101,76,FALSE) -> 0 | P47: =O47/$E$36 -> 0 | EJ47: North.Coast
...

Sheet HQ
C2: INCOME STATEMTN
G3: Income Statement For HQ
D6: Jan | E6: February | F6: March | G6: April | H6: May | I6: June | J6: July | K6: August | L6: September | M6: October | N6: November | O6: December | P6: Total
C7: INCOME DETAILS
C8: المبيعات | D8: =D9+D10+D11 -> 0 | E8: =E9+E10+E11 -> 0 | F8: =F9+F10+F11 -> 0 | G8: =G9+G10+G11 -> 0 | H8: =H9+H10+H11 -> 0 | I8: =I9+I10+I11 -> 0 | J8: =J9+J10+J11 -> 0 | K8: =K9+K10+K11 -> 0 | ... O8: =O9+O10+O11 -> 0 | P8: =SUM(D8:O8) -> 0
C9: نقدى | P9: =SUM(D9:O9) -> 0
C10: دليفرى | P10: =SUM(D10:O10) -> 0
C11: اجل | P11: =SUM(D11:O11) -> 0
C12: تكلفة البضاعة المباعة | P12: =SUM(D12:O12) -> 0
C13: مجمل الربح | D13: =D8-D12 -> 0 | E13: =E8-E12 -> 0 | F13: =F8-F12 -> 0 | G13: =G8-G12 -> 0 | H13: =H8-H12 -> 0 | I13: =I8-I12 -> 0 | J13: =J8-J12 -> 0 | K13: =K8-K12 -> 0 | ... O13: =O8-O12 -> 0 | P13: =SUM(D13:O13) -> 0
C14: خصم نقدى | D14: 223875.51 | E14: 337632.98 | F14: 289944.05 | G14: 78025.57 | H14: 402717.41 | I14: 369287.54 | J14: 218232.85 | K14: 402056.92 | L14: 224091.1 | M14: 152627.12 | N14: 79525.81 | O14: 223453.29 | P14: =SUM(D14:O14) -> 3001470.1
C15: ارباح صرف اصناف بيع اصول | E15: 365 | H15: 21851.9 | P15: =SUM(D15:O15) -> 22216.9
C16: فائض جرد | D16: 367.55 | E16: 21315.47 | F16: 3831.65 | G16: 536.91 | I16: 10453.73 | J16: 0 | P16: =SUM(D16:O16) -> 36505.31
C17: ايرادات اخرى | D17: 79417.32 | E17: =72208.32+20000 -> 92208.32 | F17: 170139.06 | G17: 469365.13 | H17: =116464.98+24250+475192.23 -> 615907.21 | I17: =98027.03+203257.17+56562+6111 -> 363957.2 | J17: =292309.63+3 -> 292312.63 | K17: 195965.83 | L17: 1022901.4 | M17: 139477.83 | N17: 365063.49 | O17: 4552194.2 | P17: =SUM(D17:O17) -> 8358909.6
C18: إجمالي الايرادات اخرى | D18: =SUM(D14:D17) -> 303660.38 | E18: =SUM(E14:E17) -> 451521.77 | F18: =SUM(F14:F17) -> 463914.76 | G18: =SUM(G14:G17) -> 547927.61 | H18: =SUM(H14:H17) -> 1040476.5 | I18: =SUM(I14:I17) -> 743698.47 | J18: =SUM(J14:J17) -> 510545.48 | K18: =SUM(K14:K17) -> 598022.75 | ... O18: =SUM(O14:O17) -> 4775647.5 | P18: =SUM(D18:O18) -> 11419102
C19: مجمل الربح | D19: =D13+D18 -> 303660.38 | E19: =E13+E18 -> 451521.77 | F19: =F13+F18 -> 463914.76 | G19: =G13+G18 -> 547927.61 | H19: =H13+H18 -> 1040476.5 | I19: =I13+I18 -> 743698.47 | J19: =J13+J18 -> 510545.48 | K19: =K13+K18 -> 598022.75 | ... P19: =P13+P18 -> 11419102 | Q19: =P19-P14 -> 8417631.8
C21: EXPENSE DETAILS
C22: مرتبات الادارة | D22: =IFERROR(VLOOKUP(C22,'تقرير المصروفات حسب الشهر'!$C$10:$AD$119,2,FALSE),0) -> 853477.34 | E22: =IFERROR(VLOOKUP(C22,'تقرير المصروفات حسب الشهر'!$C$135:$AD$252,2,FALSE),0) -> 899945.03 | F22: =_xlfn.XLOOKUP(C22,'تقرير المصروفات حسب الشهر'!C261:C373,'تقرير المصروفات حسب الشهر'!D261:D373,0,0) -> 896301.69 | G22: =IFERROR(VLOOKUP(C22,'تقرير المصروفات حسب الشهر'!$C$387:$AD$495,2,FALSE),0) -> 903218.51 | H22: =IFERROR(VLOOKUP(C22,'تقرير المصروفات حسب الشهر'!$C$512:$AD$620,2,FALSE),0) -> 994803.77 | I22: =IFERROR(VLOOKUP(C22,'تقرير المصروفات حسب الشهر'!$C$637:$AD$746,2,FALSE),0) -> 1006628.8 | J22: =IFERROR(VLOOKUP(C22,'تقرير المصروفات حسب الشهر'!$C$763:$AD$872,2,FALSE),0) -> 1108595.7 | K22: =IFERROR(VLOOKUP(C22,'تقرير المصروفات حسب الشهر'!$C$889:$D$999,2,FALSE),0) -> 1266314.5 | L22: =IFERROR(VLOOKUP(C22,'تقرير المصروفات حسب الشهر'!$C$1016:$AD$1126,2,FALSE),0) -> 1184810.4 | M22: =IFERROR(VLOOKUP(C22,'تقرير المصروفات حسب الشهر'!$C$1143:$AD$1254,2,FALSE),0) -> 1313118.6 | N22: =IFERROR(VLOOKUP(C22,'تقرير المصروفات حسب الشهر'!$C$1270:$AD$1381,2,FALSE),0) -> 1305040.6 | O22: =IFERROR(VLOOKUP(C22,'تقرير المصروفات حسب الشهر'!$C$1397:$AI$1512,2,FALSE),0) -> 1313581.9 | P22: =SUM(D22:O22) -> 13045837
C23: مرتبات الفروع | D23: =IFERROR(VLOOKUP(C23,'تقرير المصروفات حسب الشهر'!$C$10:$AD$119,2,FALSE),0) -> 0 | E23: =IFERROR(VLOOKUP(C23,'تقرير المصروفات حسب الشهر'!$C$135:$AD$252,2,FALSE),0) -> 365 | F23: =_xlfn.XLOOKUP(C23,'تقرير المصروفات حسب الشهر'!C262:C374,'تقرير المصروفات حسب الشهر'!D262:D374,0,0) -> 0 | G23: =IFERROR(VLOOKUP(C23,'تقرير المصروفات حسب الشهر'!$C$387:$AD$495,2,FALSE),0) -> 0 | H23: =IFERROR(VLOOKUP(C23,'تقرير المصروفات حسب الشهر'!$C$512:$AD$620,2,FALSE),0) -> 0 | I23: =IFERROR(VLOOKUP(C23,'تقرير المصروفات حسب الشهر'!$C$637:$AD$746,2,FALSE),0) -> 0 | J23: =IFERROR(VLOOKUP(C23,'تقرير المصروفات حسب الشهر'!$C$763:$AD$872,2,FALSE),0) -> 0 | K23: =IFERROR(VLOOKUP(C23,'تقرير المصروفات حسب الشهر'!$C$889:$D$999,2,FALSE),0) -> 0 | L23: =IFERROR(VLOOKUP(C23,'تقرير المصروفات حسب الشهر'!$C$1016:$AD$1126,2,FALSE),0) -> 0 | M23: =IFERROR(VLOOKUP(C23,'تقرير المصروفات حسب الشهر'!$C$1143:$AD$1254,2,FALSE),0) -> 0 | N23: =IFERROR(VLOOKUP(C23,'تقرير المصروفات حسب الشهر'!$C$1270:$AD$1381,2,FALSE),0) -> 0 | O23: =IFERROR(VLOOKUP(C23,'تقرير المصروفات حسب الشهر'!$C$1397:$AI$1512,2,FALSE),0) -> 0 | P23: =SUM(D23:O23) -> 365
C24: الكهرباء | D24: =IFERROR(VLOOKUP(C24,'تقرير المصروفات حسب الشهر'!$C$10:$AD$119,2,FALSE),0) -> 2925 | E24: =IFERROR(VLOOKUP(C24,'تقرير المصروفات حسب الشهر'!$C$135:$AD$252,2,FALSE),0) -> 1000 | F24: =_xlfn.XLOOKUP(C24,'تقرير المصروفات حسب الشهر'!C263:C375,'تقرير المصروفات حسب الشهر'!D263:D375,0,0) -> 17462 | G24: =IFERROR(VLOOKUP(C24,'تقرير المصروفات حسب الشهر'!$C$387:$AD$495,2,FALSE),0) -> 2000 | H24: =IFERROR(VLOOKUP(C24,'تقرير المصروفات حسب الشهر'!$C$512:$AD$620,2,FALSE),0) -> 6374 | I24: =IFERROR(VLOOKUP(C24,'تقرير المصروفات حسب الشهر'!$C$637:$AD$746,2,FALSE),0) -> 22158 | J24: =IFERROR(VLOOKUP(C24,'تقرير المصروفات حسب الشهر'!$C$763:$AD$872,2,FALSE),0) -> 18677 | K24: =IFERROR(VLOOKUP(C24,'تقرير المصروفات حسب الشهر'!$C$889:$D$999,2,FALSE),0) -> 12995 | L24: =IFERROR(VLOOKUP(C24,'تقرير المصروفات حسب الشهر'!$C$1016:$AD$1126,2,FALSE),0) -> 11244 | M24: =IFERROR(VLOOKUP(C24,'تقرير المصروفات حسب الشهر'!$C$1143:$AD$1254,2,FALSE),0) -> 42424.75 | N24: =IFERROR(VLOOKUP(C24,'تقرير المصروفات حسب الشهر'!$C$1270:$AD$1381,2,FALSE),0) -> 16611 | O24: =IFERROR(VLOOKUP(C24,'تقرير المصروفات حسب الشهر'!$C$1397:$AI$1512,2,FALSE),0) -> 8245 | P24: =SUM(D24:O24) -> 162115.75
C25: المياه | D25: =IFERROR(VLOOKUP(C25,'تقرير المصروفات حسب الشهر'!$C$10:$AD$119,2,FALSE),0) -> 0 | E25: =IFERROR(VLOOKUP(C25,'تقرير المصروفات حسب الشهر'!$C$135:$AD$252,2,FALSE),0) -> 0 | F25: =_xlfn.XLOOKUP(C25,'تقرير المصروفات حسب الشهر'!C264:C376,'تقرير المصروفات حسب الشهر'!D264:D376,0,0) -> 0 | G25: =IFERROR(VLOOKUP(C25,'تقرير المصروفات حسب الشهر'!$C$387:$AD$495,2,FALSE),0) -> 0 | H25: =IFERROR(VLOOKUP(C25,'تقرير المصروفات حسب الشهر'!$C$512:$AD$620,2,FALSE),0) -> 0 | I25: =IFERROR(VLOOKUP(C25,'تقرير المصروفات حسب الشهر'!$C$637:$AD$746,2,FALSE),0) -> 0 | J25: =IFERROR(VLOOKUP(C25,'تقرير المصروفات حسب الشهر'!$C$763:$AD$872,2,FALSE),0) -> 306 | K25: =IFERROR(VLOOKUP(C25,'تقرير المصروفات حسب الشهر'!$C$889:$D$999,2,FALSE),0) -> 0 | L25: =IFERROR(VLOOKUP(C25,'تقرير المصروفات حسب الشهر'!$C$1016:$AD$1126,2,FALSE),0) -> 0 | M25: =IFERROR(VLOOKUP(C25,'تقرير المصروفات حسب الشهر'!$C$1143:$AD$1254,2,FALSE),0) -> 0 | N25: =IFERROR(VLOOKUP(C25,'تقرير المصروفات حسب الشهر'!$C$1270:$AD$1381,2,FALSE),0) -> 0 | O25: =IFERROR(VLOOKUP(C25,'تقرير المصروفات حسب الشهر'!$C$1397:$AI$1512,2,FALSE),0) -> 0 | P25: =SUM(D25:O25) -> 306
C26: التليفون الارضي | D26: =IFERROR(VLOOKUP(C26,'تقرير المصروفات حسب الشهر'!$C$10:$AD$119,2,FALSE),0) -> 700 | E26: =IFERROR(VLOOKUP(C26,'تقرير المصروفات حسب الشهر'!$C$135:$AD$252,2,FALSE),0) -> 0 | F26: =_xlfn.XLOOKUP(C26,'تقرير المصروفات حسب الشهر'!C265:C377,'تقرير المصروفات حسب الشهر'!D265:D377,0,0) -> 800 | G26: =IFERROR(VLOOKUP(C26,'تقرير المصروفات حسب الشهر'!$C$387:$AD$495,2,FALSE),0) -> 0 | H26: =IFERROR(VLOOKUP(C26,'تقرير المصروفات حسب الشهر'!$C$512:$AD$620,2,FALSE),0) -> 0 | I26: =IFERROR(VLOOKUP(C26,'تقرير المصروفات حسب الشهر'!$C$637:$AD$746,2,FALSE),0) -> 1600 | J26: =IFERROR(VLOOKUP(C26,'تقرير المصروفات حسب الشهر'!$C$763:$AD$872,2,FALSE),0) -> 0 | K26: =IFERROR(VLOOKUP(C26,'تقرير المصروفات حسب الشهر'!$C$889:$D$999,2,FALSE),0) -> 0 | L26: =IFERROR(VLOOKUP(C26,'تقرير المصروفات حسب الشهر'!$C$1016:$AD$1126,2,FALSE),0) -> 0 | M26: =IFERROR(VLOOKUP(C26,'تقرير المصروفات حسب الشهر'!$C$1143:$AD$1254,2,FALSE),0) -> 920 | N26: =IFERROR(VLOOKUP(C26,'تقرير المصروفات حسب الشهر'!$C$1270:$AD$1381,2,FALSE),0) -> 600 | O26: =IFERROR(VLOOKUP(C26,'تقرير المصروفات حسب الشهر'!$C$1397:$AI$1512,2,FALSE),0) -> 0 | P26: =SUM(D26:O26) -> 4620
C27: الايجار - الصيدلية | D27: =IFERROR(VLOOKUP(C27,'تقرير المصروفات حسب الشهر'!$C$10:$AD$119,2,FALSE),0) -> 0 | E27: =IFERROR(VLOOKUP(C27,'تقرير المصروفات حسب الشهر'!$C$135:$AD$252,2,FALSE),0) -> 0 | F27: =_xlfn.XLOOKUP(C27,'تقرير المصروفات حسب الشهر'!C266:C378,'تقرير المصروفات حسب الشهر'!D266:D378,0,0) -> 0 | G27: =IFERROR(VLOOKUP(C27,'تقرير المصروفات حسب الشهر'!$C$387:$AD$495,2,FALSE),0) -> 0 | H27: =IFERROR(VLOOKUP(C27,'تقرير المصروفات حسب الشهر'!$C$512:$AD$620,2,FALSE),0) -> 0 | I27: =IFERROR(VLOOKUP(C27,'تقرير المصروفات حسب الشهر'!$C$637:$AD$746,2,FALSE),0) -> 0 | J27: =IFERROR(VLOOKUP(C27,'تقرير المصروفات حسب الشهر'!$C$763:$AD$872,2,FALSE),0) -> 0 | K27: =IFERROR(VLOOKUP(C27,'تقرير المصروفات حسب الشهر'!$C$889:$D$999,2,FALSE),0) -> 0 | L27: =IFERROR(VLOOKUP(C27,'تقرير المصروفات حسب الشهر'!$C$1016:$AD$1126,2,FALSE),0) -> 0 | M27: =IFERROR(VLOOKUP(C27,'تقرير المصروفات حسب الشهر'!$C$1143:$AD$1254,2,FALSE),0) -> 0 | N27: =IFERROR(VLOOKUP(C27,'تقرير المصروفات حسب الشهر'!$C$1270:$AD$1381,2,FALSE),0) -> 0 | O27: =IFERROR(VLOOKUP(C27,'تقرير المصروفات حسب الشهر'!$C$1397:$AI$1512,2,FALSE),0) -> 0 | P27: =SUM(D27:O27) -> 0
C28: الايجار - الادارة | D28: =IFERROR(VLOOKUP(C28,'تقرير المصروفات حسب الشهر'!$C$10:$AD$119,2,FALSE),0) -> 100000 | E28: =IFERROR(VLOOKUP(C28,'تقرير المصروفات حسب الشهر'!$C$135:$AD$252,2,FALSE),0) -> 100000 | F28: =_xlfn.XLOOKUP(C28,'تقرير المصروفات حسب الشهر'!C267:C379,'تقرير المصروفات حسب الشهر'!D267:D379,0,0) -> 100000 | G28: =IFERROR(VLOOKUP(C28,'تقرير المصروفات حسب الشهر'!$C$387:$AD$495,2,FALSE),0) -> 100000 | H28: =IFERROR(VLOOKUP(C28,'تقرير المصروفات حسب الشهر'!$C$512:$AD$620,2,FALSE),0) -> 100000 | I28: =IFERROR(VLOOKUP(C28,'تقرير المصروفات حسب الشهر'!$C$637:$AD$746,2,FALSE),0) -> 100000 | J28: =IFERROR(VLOOKUP(C28,'تقرير المصروفات حسب الشهر'!$C$763:$AD$872,2,FALSE),0) -> 100000 | K28: =IFERROR(VLOOKUP(C28,'تقرير المصروفات حسب الشهر'!$C$889:$D$999,2,FALSE),0) -> 100000 | L28: =IFERROR(VLOOKUP(C28,'تقرير المصروفات حسب الشهر'!$C$1016:$AD$1126,2,FALSE),0) -> 100000 | M28: =IFERROR(VLOOKUP(C28,'تقرير المصروفات حسب الشهر'!$C$1143:$AD$1254,2,FALSE),0) -> 100000 | N28: =IFERROR(VLOOKUP(C28,'تقرير المصروفات حسب الشهر'!$C$1270:$AD$1381,2,FALSE),0) -> 50000 | O28: =IFERROR(VLOOKUP(C28,'تقرير المصروفات حسب الشهر'!$C$1397:$AI$1512,2,FALSE),0) -> 50000 | P28: =SUM(D28:O28) -> 1100000
C29: ايجارات متنوعه | D29: =IFERROR(VLOOKUP(C29,'تقرير المصروفات حسب الشهر'!$C$10:$AD$119,2,FALSE),0) -> 40610 | E29: =IFERROR(VLOOKUP(C29,'تقرير المصروفات حسب الشهر'!$C$135:$AD$252,2,FALSE),0) -> 40610 | F29: =_xlfn.XLOOKUP(C29,'تقرير المصروفات حسب الشهر'!C268:C380,'تقرير المصروفات حسب الشهر'!D268:D380,0,0) -> 40610 | G29: =IFERROR(VLOOKUP(C29,'تقرير المصروفات حسب الشهر'!$C$387:$AD$495,2,FALSE),0) -> 40610 | H29: =IFERROR(VLOOKUP(C29,'تقرير المصروفات حسب الشهر'!$C$512:$AD$620,2,FALSE),0) -> 40610 | I29: =IFERROR(VLOOKUP(C29,'تقرير المصروفات حسب الشهر'!$C$637:$AD$746,2,FALSE),0) -> 40610 | J29: =IFERROR(VLOOKUP(C29,'تقرير المصروفات حسب الشهر'!$C$763:$AD$872,2,FALSE),0) -> 41900 | K29: =IFERROR(VLOOKUP(C29,'تقرير المصروفات حسب الشهر'!$C$889:$D$999,2,FALSE),0) -> 41900 | L29: =IFERROR(VLOOKUP(C29,'تقرير المصروفات حسب الشهر'!$C$1016:$AD$1126,2,FALSE),0) -> 43220 | M29: =IFERROR(VLOOKUP(C29,'تقرير المصروفات حسب الشهر'!$C$1143:$AD$1254,2,FALSE),0) -> 41900 | N29: =IFERROR(VLOOKUP(C29,'تقرير المصروفات حسب الشهر'!$C$1270:$AD$1381,2,FALSE),0) -> 43330 | O29: =IFERROR(VLOOKUP(C29,'تقرير المصروفات حسب الشهر'!$C$1397:$AI$1512,2,FALSE),0) -> 43330 | P29: =SUM(D29:O29) -> 499240
C30: ادوات مكتبية | D30: =IFERROR(VLOOKUP(C30,'تقرير المصروفات حسب الشهر'!$C$10:$AD$119,2,FALSE),0) -> 1255 | E30: =IFERROR(VLOOKUP(C30,'تقرير المصروفات حسب الشهر'!$C$135:$AD$252,2,FALSE),0) -> 7710 | F30: =_xlfn.XLOOKUP(C30,'تقرير المصروفات حسب الشهر'!C269:C381,'تقرير المصروفات حسب الشهر'!D269:D381,0,0) -> 3555.6 | G30: =IFERROR(VLOOKUP(C30,'تقرير المصروفات حسب الشهر'!$C$387:$AD$495,2,FALSE),0) -> 9375 | H30: =IFERROR(VLOOKUP(C30,'تقرير المصروفات حسب الشهر'!$C$512:$AD$620,2,FALSE),0) -> 2000 | I30: =IFERROR(VLOOKUP(C30,'تقرير المصروفات حسب الشهر'!$C$637:$AD$746,2,FALSE),0) -> 8290.25 | J30: =IFERROR(VLOOKUP(C30,'تقرير المصروفات حسب الشهر'!$C$763:$AD$872,2,FALSE),0) -> 1123 | K30: =IFERROR(VLOOKUP(C30,'تقرير المصروفات حسب الشهر'!$C$889:$D$999,2,FALSE),0) -> 12220 | L30: =IFERROR(VLOOKUP(C30,'تقرير المصروفات حسب الشهر'!$C$1016:$AD$1126,2,FALSE),0) -> 1000 | M30: =IFERROR(VLOOKUP(C30,'تقرير المصروفات حسب الشهر'!$C$1143:$AD$1254,2,FALSE),0) -> 1000 | N30: =IFERROR(VLOOKUP(C30,'تقرير المصروفات حسب الشهر'!$C$1270:$AD$1381,2,FALSE),0) -> 1650 | O30: =IFERROR(VLOOKUP(C30,'تقرير المصروفات حسب الشهر'!$C$1397:$AI$1512,2,FALSE),0) -> 10375 | P30: =SUM(D30:O30) -> 59553.85
C31: فواتير الموبايل | D31: =IFERROR(VLOOKUP(C31,'تقرير المصروفات حسب الشهر'!$C$10:$AD$119,2,FALSE),0) -> 11807.53 | E31: =IFERROR(VLOOKUP(C31,'تقرير المصروفات حسب الشهر'!$C$135:$AD$252,2,FALSE),0) -> 15279.64 | F31: =_xlfn.XLOOKUP(C31,'تقرير المصروفات حسب الشهر'!C270:C382,'تقرير المصروفات حسب الشهر'!D270:D382,0,0) -> 12903.64 | G31: =IFERROR(VLOOKUP(C31,'تقرير المصروفات حسب الشهر'!$C$387:$AD$495,2,FALSE),0) -> 12719.11 | H31: =IFERROR(VLOOKUP(C31,'تقرير المصروفات حسب الشهر'!$C$512:$AD$620,2,FALSE),0) -> 13043.11 | I31: =IFERROR(VLOOKUP(C31,'تقرير المصروفات حسب الشهر'!$C$637:$AD$746,2,FALSE),0) -> 11919.11 | J31: =IFERROR(VLOOKUP(C31,'تقرير المصروفات حسب الشهر'!$C$763:$AD$872,2,FALSE),0) -> 12253.64 | K31: =IFERROR(VLOOKUP(C31,'تقرير المصروفات حسب الشهر'!$C$889:$D$999,2,FALSE),0) -> 12260.68 | L31: =IFERROR(VLOOKUP(C31,'تقرير المصروفات حسب الشهر'!$C$1016:$AD$1126,2,FALSE),0) -> 12138.8 | M31: =IFERROR(VLOOKUP(C31,'تقرير المصروفات حسب الشهر'!$C$1143:$AD$1254,2,FALSE),0) -> 12580.61 | N31: =IFERROR(VLOOKUP(C31,'تقرير المصروفات حسب الشهر'!$C$1270:$AD$1381,2,FALSE),0) -> 12579.97 | O31: =IFERROR(VLOOKUP(C31,'تقرير المصروفات حسب الشهر'!$C$1397:$AI$1512,2,FALSE),0) -> 18165.74 | P31: =SUM(D31:O31) -> 157651.58
C32: مكافات مبيعات الادوية | D32: =IFERROR(VLOOKUP(C32,'تقرير المصروفات حسب الشهر'!$C$10:$AD$119,2,FALSE),0) -> 0 | E32: =IFERROR(VLOOKUP(C32,'تقرير المصروفات حسب الشهر'!$C$135:$AD$252,2,FALSE),0) -> 0 | F32: =_xlfn.XLOOKUP(C32,'تقرير المصروفات حسب الشهر'!C271:C383,'تقرير المصروفات حسب الشهر'!D271:D383,0,0) -> 0 | G32: =IFERROR(VLOOKUP(C32,'تقرير المصروفات حسب الشهر'!$C$387:$AD$495,2,FALSE),0) -> 0 | H32: =IFERROR(VLOOKUP(C32,'تقرير المصروفات حسب الشهر'!$C$512:$AD$620,2,FALSE),0) -> 0 | I32: =IFERROR(VLOOKUP(C32,'تقرير المصروفات حسب الشهر'!$C$637:$AD$746,2,FALSE),0) -> 0 | J32: =IFERROR(VLOOKUP(C32,'تقرير المصروفات حسب الشهر'!$C$763:$AD$872,2,FALSE),0) -> 275 | K32: =IFERROR(VLOOKUP(C32,'تقرير المصروفات حسب الشهر'!$C$889:$D$999,2,FALSE),0) -> 0 | L32: =IFERROR(VLOOKUP(C32,'تقرير المصروفات حسب الشهر'!$C$1016:$AD$1126,2,FALSE),0) -> 0 | M32: =IFERROR(VLOOKUP(C32,'تقرير المصروفات حسب الشهر'!$C$1143:$AD$1254,2,FALSE),0) -> 0 | N32: =IFERROR(VLOOKUP(C32,'تقرير المصروفات حسب الشهر'!$C$1270:$AD$1381,2,FALSE),0) -> 0 | O32: =IFERROR(VLOOKUP(C32,'تقرير المصروفات حسب الشهر'!$C$1397:$AI$1512,2,FALSE),0) -> 0 | P32: =SUM(D32:O32) -> 275
C33: مكافات مبيعات التجميل | D33: =IFERROR(VLOOKUP(C33,'تقرير المصروفات حسب الشهر'!$C$10:$AD$119,2,FALSE),0) -> 1000 | E33: =IFERROR(VLOOKUP(C33,'تقرير المصروفات حسب الشهر'!$C$135:$AD$252,2,FALSE),0) -> 3715 | F33: =_xlfn.XLOOKUP(C33,'تقرير المصروفات حسب الشهر'!C272:C384,'تقرير المصروفات حسب الشهر'!D272:D384,0,0) -> 1205 | G33: =IFERROR(VLOOKUP(C33,'تقرير المصروفات حسب الشهر'!$C$387:$AD$495,2,FALSE),0) -> 1500 | H33: =IFERROR(VLOOKUP(C33,'تقرير المصروفات حسب الشهر'!$C$512:$AD$620,2,FALSE),0) -> 13940 | I33: =IFERROR(VLOOKUP(C33,'تقرير المصروفات حسب الشهر'!$C$637:$AD$746,2,FALSE),0) -> 4862.5 | J33: =IFERROR(VLOOKUP(C33,'تقرير المصروفات حسب الشهر'!$C$763:$AD$872,2,FALSE),0) -> 26085 | K33: =IFERROR(VLOOKUP(C33,'تقرير المصروفات حسب الشهر'!$C$889:$D$999,2,FALSE),0) -> 4698 | L33: =IFERROR(VLOOKUP(C33,'تقرير المصروفات حسب الشهر'!$C$1016:$AD$1126,2,FALSE),0) -> 8555 | M33: =IFERROR(VLOOKUP(C33,'تقرير المصروفات حسب الشهر'!$C$1143:$AD$1254,2,FALSE),0) -> 31872 | N33: =IFERROR(VLOOKUP(C33,'تقرير المصروفات حسب الشهر'!$C$1270:$AD$1381,2,FALSE),0) -> 1900 | O33: =IFERROR(VLOOKUP(C33,'تقرير المصروفات حسب الشهر'!$C$1397:$AI$1512,2,FALSE),0) -> 24851 | P33: =SUM(D33:O33) -> 124183.5
... C131: فوائد القروض - بنك القاهرة BDC | D131: =IFERROR(VLOOKUP(C131,'تقرير المصروفات حسب الشهر'!$C$10:$AD$119,2,FALSE),0) -> 24094.78 | E131: =IFERROR(VLOOKUP(C131,'تقرير المصروفات حسب الشهر'!$C$135:$AD$252,2,FALSE),0) -> 24094.78 | F131: =_xlfn.XLOOKUP(C131,'تقرير المصروفات حسب الشهر'!C370:C482,'تقرير المصروفات حسب الشهر'!D370:D482,0,0) -> 24094.78 | G131: =IFERROR(VLOOKUP(C131,'تقرير المصروفات حسب الشهر'!$C$387:$AD$495,2,FALSE),0) -> 24094.78 | H131: =IFERROR(VLOOKUP(C131,'تقرير المصروفات حسب الشهر'!$C$512:$AD$620,2,FALSE),0) -> 24094.78 | I131: =IFERROR(VLOOKUP(C131,'تقرير المصروفات حسب الشهر'!$C$637:$AD$746,2,FALSE),0) -> 24094.78 | J131: =IFERROR(VLOOKUP(C131,'تقرير المصروفات حسب الشهر'!$C$763:$AD$872,2,FALSE),0) -> 24094.78 | K131: =IFERROR(VLOOKUP(C131,'تقرير المصروفات حسب الشهر'!$C$889:$D$999,2,FALSE),0) -> 19385.65 | L131: =IFERROR(VLOOKUP(C131,'تقرير المصروفات حسب الشهر'!$C$1016:$AD$1126,2,FALSE),0) -> 18941.97 | M131: =IFERROR(VLOOKUP(C131,'تقرير المصروفات حسب الشهر'!$C$1143:$AD$1254,2,FALSE),0) -> 18489.74 | N131: =IFERROR(VLOOKUP(C131,'تقرير المصروفات حسب الشهر'!$C$1270:$AD$1381,2,FALSE),0) -> 18028.79 | O131: =IFERROR(VLOOKUP(C131,'تقرير المصروفات حسب الشهر'!$C$1397:$AI$1512,2,FALSE),0) -> 17558.96 | P131: =SUM(D131:O131) -> 261068.57
C132: اتعاب محاماه | D132: =IFERROR(VLOOKUP(C132,'تقرير المصروفات حسب الشهر'!$C$10:$AD$124,2,FALSE),0) -> 18700 | E132: =IFERROR(VLOOKUP(C132,'تقرير المصروفات حسب الشهر'!$C$135:$AD$252,2,FALSE),0) -> 28000 | F132: =_xlfn.XLOOKUP(C132,'تقرير المصروفات حسب الشهر'!C371:C483,'تقرير المصروفات حسب الشهر'!D371:D483,0,0) -> 6000 | G132: =IFERROR(VLOOKUP(C132,'تقرير المصروفات حسب الشهر'!$C$387:$AD$495,2,FALSE),0) -> 0 | H132: =IFERROR(VLOOKUP(C132,'تقرير المصروفات حسب الشهر'!$C$512:$AD$621,2,FALSE),0) -> 530 | I132: =IFERROR(VLOOKUP(C132,'تقرير المصروفات حسب الشهر'!$C$637:$AD$746,2,FALSE),0) -> 20000 | J132: =IFERROR(VLOOKUP(C132,'تقرير المصروفات حسب الشهر'!$C$763:$AD$872,2,FALSE),0) -> 10000 | K132: =IFERROR(VLOOKUP(C132,'تقرير المصروفات حسب الشهر'!$C$889:$D$999,2,FALSE),0) -> 500 | L132: =IFERROR(VLOOKUP(C132,'تقرير المصروفات حسب الشهر'!$C$1016:$AD$1126,2,FALSE),0) -> 0 | M132: =IFERROR(VLOOKUP(C132,'تقرير المصروفات حسب الشهر'!$C$1143:$AD$1254,2,FALSE),0) -> 0 | N132: =IFERROR(VLOOKUP(C132,'تقرير المصروفات حسب الشهر'!$C$1270:$AD$1381,2,FALSE),0) -> 0 | O132: =IFERROR(VLOOKUP(C132,'تقرير المصروفات حسب الشهر'!$C$1397:$AI$1512,2,FALSE),0) -> 11470 | P132: =SUM(D132:O132) -> 95200
C133: خصم أبليكيشن | D133: =IFERROR(VLOOKUP(C133,'تقرير المصروفات حسب الشهر'!$C$10:$AD$119,2,FALSE),0) -> 0 | E133: =IFERROR(VLOOKUP(C133,'تقرير المصروفات حسب الشهر'!$C$135:$AD$252,2,FALSE),0) -> 0 | F133: =_xlfn.XLOOKUP(C133,'تقرير المصروفات حسب الشهر'!C372:C484,'تقرير المصروفات حسب الشهر'!D372:D484,0,0) -> 0 | G133: =IFERROR(VLOOKUP(C133,'تقرير المصروفات حسب الشهر'!$C$387:$AD$495,2,FALSE),0) -> 0 | H133: =IFERROR(VLOOKUP(C133,'تقرير المصروفات حسب الشهر'!$C$512:$AD$620,2,FALSE),0) -> 0 | I133: =IFERROR(VLOOKUP(C133,'تقرير المصروفات حسب الشهر'!$C$637:$AD$746,2,FALSE),0) -> 0 | J133: =IFERROR(VLOOKUP(C133,'تقرير المصروفات حسب الشهر'!$C$763:$AD$872,2,FALSE),0) -> 0 | K133: =IFERROR(VLOOKUP(C133,'تقرير المصروفات حسب الشهر'!$C$889:$D$999,2,FALSE),0) -> 0 | L133: =IFERROR(VLOOKUP(C133,'تقرير المصروفات حسب الشهر'!$C$1016:$AD$1126,2,FALSE),0) -> 0 | M133: =IFERROR(VLOOKUP(C133,'تقرير المصروفات حسب الشهر'!$C$1143:$AD$1254,2,FALSE),0) -> 0 | N133: =IFERROR(VLOOKUP(C133,'تقرير المصروفات حسب الشهر'!$C$1270:$AD$1381,2,FALSE),0) -> 0 | O133: =IFERROR(VLOOKUP(C133,'تقرير المصروفات حسب الشهر'!$C$1397:$AI$1512,2,FALSE),0) -> 0 | P133: =SUM(D133:O133) -> 0
C134: عمولات ادارية | D134: =IFERROR(VLOOKUP(C134,'تقرير المصروفات حسب الشهر'!$C$10:$AD$121,2,FALSE),0) -> 0 | E134: =IFERROR(VLOOKUP(C134,'تقرير المصروفات حسب الشهر'!$C$135:$AD$252,2,FALSE),0) -> 145389.75 | F134: =_xlfn.XLOOKUP(C134,'تقرير المصروفات حسب الشهر'!C373:C485,'تقرير المصروفات حسب الشهر'!D373:D485,0,0) -> 145389.75 | G134: =IFERROR(VLOOKUP(C134,'تقرير المصروفات حسب الشهر'!$C$387:$AD$498,2,FALSE),0) -> 145389.75 | H134: =IFERROR(VLOOKUP(C134,'تقرير المصروفات حسب الشهر'!$C$512:$AD$628,2,FALSE),0) -> 145389.75 | I134: =IFERROR(VLOOKUP(C134,'تقرير المصروفات حسب الشهر'!$C$637:$AD$749,2,FALSE),0) -> 145389.75 | J134: =IFERROR(VLOOKUP(C134,'تقرير المصروفات حسب الشهر'!$C$763:$AD$878,2,FALSE),0) -> 145389.75 | K134: =IFERROR(VLOOKUP(C134,'تقرير المصروفات حسب الشهر'!$C$889:$D$1005,2,FALSE),0) -> 145389.75 | L134: =IFERROR(VLOOKUP(C134,'تقرير المصروفات حسب الشهر'!$C$1016:$AD$1130,2,FALSE),0) -> 145389.75 | M134: =IFERROR(VLOOKUP(C134,'تقرير المصروفات حسب الشهر'!$C$1143:$AD$1259,2,FALSE),0) -> 145389.75 | N134: =IFERROR(VLOOKUP(C134,'تقرير المصروفات حسب الشهر'!$C$1270:$AD$1384,2,FALSE),0) -> 145389.75 | O134: =IFERROR(VLOOKUP(C134,'تقرير المصروفات حسب الشهر'!$C$1397:$AI$1512,2,FALSE),0) -> 92000 | P134: =SUM(D134:O134) -> 1545897.5
D135: =IFERROR(VLOOKUP(C135,'تقرير المصروفات حسب الشهر'!$C$10:$AD$119,2,FALSE),0) -> 0 | E135: =IFERROR(VLOOKUP(C135,'تقرير المصروفات حسب الشهر'!$C$135:$AD$252,2,FALSE),0) -> 0 | F135: =_xlfn.XLOOKUP(C135,'تقرير المصروفات حسب الشهر'!C374:C486,'تقرير المصروفات حسب الشهر'!D374:D486,0,0) -> 0 | G135: =IFERROR(VLOOKUP(C135,'تقرير المصروفات حسب الشهر'!$C$387:$AD$495,2,FALSE),0) -> 0 | H135: =IFERROR(VLOOKUP(C135,'تقرير المصروفات حسب الشهر'!$C$512:$AD$620,2,FALSE),0) -> 0 | I135: =IFERROR(VLOOKUP(C135,'تقرير المصروفات حسب الشهر'!$C$637:$AD$746,2,FALSE),0) -> 0 | J135: =IFERROR(VLOOKUP(C135,'تقرير المصروفات حسب الشهر'!$C$763:$AD$872,2,FALSE),0) -> 0 | K135: =IFERROR(VLOOKUP(C135,'تقرير المصروفات حسب الشهر'!$C$889:$D$999,2,FALSE),0) -> 0 | L135: =IFERROR(VLOOKUP(C135,'تقرير المصروفات حسب الشهر'!$C$1016:$AD$1126,2,FALSE),0) -> 0 | M135: =IFERROR(VLOOKUP(C135,'تقرير المصروفات حسب الشهر'!$C$1143:$AD$1254,2,FALSE),0) -> 0 | N135: =IFERROR(VLOOKUP(C135,'تقرير المصروفات حسب الشهر'!$C$1270:$AD$1381,2,FALSE),0) -> 0 | O135: =IFERROR(VLOOKUP(C135,'تقرير المصروفات حسب الشهر'!$C$1397:$AI$1512,2,FALSE),0) -> 0 | P135: =SUM(D135:O135) -> 0
D136: =IFERROR(VLOOKUP(C136,'تقرير المصروفات حسب الشهر'!$C$10:$AD$119,2,FALSE),0) -> 0 | E136: =IFERROR(VLOOKUP(C136,'تقرير المصروفات حسب الشهر'!$C$135:$AD$252,2,FALSE),0) -> 0 | F136: =_xlfn.XLOOKUP(C136,'تقرير المصروفات حسب الشهر'!C375:C487,'تقرير المصروفات حسب الشهر'!D375:D487,0,0) -> 0 | G136: =IFERROR(VLOOKUP(C136,'تقرير المصروفات حسب الشهر'!$C$387:$AD$495,2,FALSE),0) -> 0 | H136: =IFERROR(VLOOKUP(C136,'تقرير المصروفات حسب الشهر'!$C$512:$AD$620,2,FALSE),0) -> 0 | I136: =IFERROR(VLOOKUP(C136,'تقرير المصروفات حسب الشهر'!$C$637:$AD$746,2,FALSE),0) -> 0 | J136: =IFERROR(VLOOKUP(C136,'تقرير المصروفات حسب الشهر'!$C$763:$AD$872,2,FALSE),0) -> 0 | K136: =IFERROR(VLOOKUP(C136,'تقرير المصروفات حسب الشهر'!$C$889:$D$999,2,FALSE),0) -> 0 | L136: =IFERROR(VLOOKUP(C136,'تقرير المصروفات حسب الشهر'!$C$1016:$AD$1126,2,FALSE),0) -> 0 | M136: =IFERROR(VLOOKUP(C136,'تقرير المصروفات حسب الشهر'!$C$1143:$AD$1254,2,FALSE),0) -> 0 | N136: =IFERROR(VLOOKUP(C136,'تقرير المصروفات حسب الشهر'!$C$1270:$AD$1381,2,FALSE),0) -> 0 | O136: =IFERROR(VLOOKUP(C136,'تقرير المصروفات حسب الشهر'!$C$1397:$AI$1512,2,FALSE),0) -> 0 | P136: =SUM(D136:O136) -> 0
D137: =IFERROR(VLOOKUP(C137,'تقرير المصروفات حسب الشهر'!$C$10:$AD$119,2,FALSE),0) -> 0 | E137: =IFERROR(VLOOKUP(C137,'تقرير المصروفات حسب الشهر'!$C$135:$AD$252,2,FALSE),0) -> 0 | F137: =_xlfn.XLOOKUP(C137,'تقرير المصروفات حسب الشهر'!C376:C488,'تقرير المصروفات حسب الشهر'!D376:D488,0,0) -> 0 | G137: =IFERROR(VLOOKUP(C137,'تقرير المصروفات حسب الشهر'!$C$387:$AD$495,2,FALSE),0) -> 0 | H137: =IFERROR(VLOOKUP(C137,'تقرير المصروفات حسب الشهر'!$C$512:$AD$620,2,FALSE),0) -> 0 | I137: =IFERROR(VLOOKUP(C137,'تقرير المصروفات حسب الشهر'!$C$637:$AD$746,2,FALSE),0) -> 0 | J137: =IFERROR(VLOOKUP(C137,'تقرير المصروفات حسب الشهر'!$C$763:$AD$872,2,FALSE),0) -> 0 | K137: =IFERROR(VLOOKUP(C137,'تقرير المصروفات حسب الشهر'!$C$889:$D$999,2,FALSE),0) -> 0 | L137: =IFERROR(VLOOKUP(C137,'تقرير المصروفات حسب الشهر'!$C$1016:$AD$1126,2,FALSE),0) -> 0 | M137: =IFERROR(VLOOKUP(C137,'تقرير المصروفات حسب الشهر'!$C$1143:$AD$1254,2,FALSE),0) -> 0 | N137: =IFERROR(VLOOKUP(C137,'تقرير المصروفات حسب الشهر'!$C$1270:$AD$1381,2,FALSE),0) -> 0 | O137: =IFERROR(VLOOKUP(C137,'تقرير المصروفات حسب الشهر'!$C$1397:$AI$1512,2,FALSE),0) -> 0 | P137: =SUM(D137:O137) -> 0
D138: =IFERROR(VLOOKUP(C138,'تقرير المصروفات حسب الشهر'!$C$10:$AD$119,2,FALSE),0) -> 0 | E138: =IFERROR(VLOOKUP(C138,'تقرير المصروفات حسب الشهر'!$C$135:$AD$252,2,FALSE),0) -> 0 | F138: =_xlfn.XLOOKUP(C138,'تقرير المصروفات حسب الشهر'!C377:C489,'تقرير المصروفات حسب الشهر'!D377:D489,0,0) -> 0 | G138: =IFERROR(VLOOKUP(C138,'تقرير المصروفات حسب الشهر'!$C$387:$AD$495,2,FALSE),0) -> 0 | H138: =IFERROR(VLOOKUP(C138,'تقرير المصروفات حسب الشهر'!$C$512:$AD$620,2,FALSE),0) -> 0 | I138: =IFERROR(VLOOKUP(C138,'تقرير المصروفات حسب الشهر'!$C$637:$AD$746,2,FALSE),0) -> 0 | J138: =IFERROR(VLOOKUP(C138,'تقرير المصروفات حسب الشهر'!$C$763:$AD$872,2,FALSE),0) -> 0 | K138: =IFERROR(VLOOKUP(C138,'تقرير المصروفات حسب الشهر'!$C$889:$D$999,2,FALSE),0) -> 0 | L138: =IFERROR(VLOOKUP(C138,'تقرير المصروفات حسب الشهر'!$C$1016:$AD$1126,2,FALSE),0) -> 0 | M138: =IFERROR(VLOOKUP(C138,'تقرير المصروفات حسب الشهر'!$C$1143:$AD$1254,2,FALSE),0) -> 0 | N138: =IFERROR(VLOOKUP(C138,'تقرير المصروفات حسب الشهر'!$C$1270:$AD$1381,2,FALSE),0) -> 0 | O138: =IFERROR(VLOOKUP(C138,'تقرير المصروفات حسب الشهر'!$C$1397:$AI$1512,2,FALSE),0) -> 0 | P138: =SUM(D138:O138) -> 0
D139: =IFERROR(VLOOKUP(C139,'تقرير المصروفات حسب الشهر'!$C$10:$AD$119,2,FALSE),0) -> 0 | E139: =IFERROR(VLOOKUP(C139,'تقرير المصروفات حسب الشهر'!$C$135:$AD$252,2,FALSE),0) -> 0 | F139: =_xlfn.XLOOKUP(C139,'تقرير المصروفات حسب الشهر'!C378:C490,'تقرير المصروفات حسب الشهر'!D378:D490,0,0) -> 0 | G139: =IFERROR(VLOOKUP(C139,'تقرير المصروفات حسب الشهر'!$C$387:$AD$495,2,FALSE),0) -> 0 | H139: =IFERROR(VLOOKUP(C139,'تقرير المصروفات حسب الشهر'!$C$512:$AD$620,2,FALSE),0) -> 0 | I139: =IFERROR(VLOOKUP(C139,'تقرير المصروفات حسب الشهر'!$C$637:$AD$746,2,FALSE),0) -> 0 | J139: =IFERROR(VLOOKUP(C139,'تقرير المصروفات حسب الشهر'!$C$763:$AD$872,2,FALSE),0) -> 0 | K139: =IFERROR(VLOOKUP(C139,'تقرير المصروفات حسب الشهر'!$C$889:$D$999,2,FALSE),0) -> 0 | L139: =IFERROR(VLOOKUP(C139,'تقرير المصروفات حسب الشهر'!$C$1016:$AD$1126,2,FALSE),0) -> 0 | M139: =IFERROR(VLOOKUP(C139,'تقرير المصروفات حسب الشهر'!$C$1143:$AD$1254,2,FALSE),0) -> 0 | N139: =IFERROR(VLOOKUP(C139,'تقرير المصروفات حسب الشهر'!$C$1270:$AD$1381,2,FALSE),0) -> 0 | O139: =IFERROR(VLOOKUP(C139,'تقرير المصروفات حسب الشهر'!$C$1397:$AI$1512,2,FALSE),0) -> 0 | P139: =SUM(D139:O139) -> 0
C140: إجمالي المصروفات | D140: =SUM(D22:D139) -> 2115892.6 | E140: =SUM(E22:E139) -> 2113613.3 | F140: =SUM(F22:F139) -> 2233776.5 | G140: =SUM(G22:G139) -> 2115627.4 | H140: =SUM(H22:H139) -> 2137158.9 | I140: =SUM(I22:I139) -> 2344883.1 | J140: =SUM(J22:J139) -> 2516501.7 | K140: =SUM(K22:K139) -> 2613856.8 | ... O140: =SUM(O22:O139) -> 2630894.9 | P140: =SUM(D140:O140) -> 28311683
C142: مجمل الربح | D142: =D19 -> 303660.38 | E142: =E19 -> 451521.77 | F142: =F19 -> 463914.76 | G142: =G19 -> 547927.61 | H142: =H19 -> 1040476.5 | I142: =I19 -> 743698.47 | J142: =J19 -> 510545.48 | K142: =K19 -> 598022.75 | ... P142: =P19 -> 11419102
...

Sheet Aguza
C2: INCOME STATEMTN
F3: Income Statement For AGOUZA
D6: Jan | E6: February | F6: March | G6: April | H6: May | I6: June | J6: July | K6: August | L6: September | M6: October | N6: November | O6: December | P6: TOTAL
C7: INCOME DETAILS
A8: العجوزة | C8: المبيعات | D8: =D9+D10+D11 -> 4953092.3 | E8: =E9+E10+E11 -> 4819082.3 | F8: =F9+F10+F11 -> 5158662.2 | G8: =G9+G10+G11 -> 5613128.2 | H8: =H9+H10+H11 -> 5842714.7 | I8: =I9+I10+I11 -> 6079990.5 | J8: =J9+J10+J11 -> 6096124.6 | K8: =K9+K10+K11 -> 6860530.2 | ... O8: =O9+O10+O11 -> 7710153 | P8: =SUM(D8:O8) -> 74585539
C9: نقدى | D9: =VLOOKUP($A$8,'تقرير إحصائية بحجم المبيعات'!$B$7:$L$31,2,FALSE) -> 3046708.7 | E9: =VLOOKUP($A$8,'تقرير إحصائية بحجم المبيعات'!$B$42:$G$73,2,FALSE) -> 2960938.7 | F9: =VLOOKUP($A$8,'تقرير إحصائية بحجم المبيعات'!$B$78:$E$103,2,FALSE) -> 3363349.8 | G9: =VLOOKUP($A$8,'تقرير إحصائية بحجم المبيعات'!$B$112:$G$137,2,FALSE) -> 3828803.9 | H9: =VLOOKUP($A$8,'تقرير إحصائية بحجم المبيعات'!$B$147:$G$177,2,FALSE) -> 3884393.1 | I9: =VLOOKUP($A$8,'تقرير إحصائية بحجم المبيعات'!$B$182:$G$212,2,FALSE) -> 4309083.3 | J9: =VLOOKUP($A$8,'تقرير إحصائية بحجم المبيعات'!$B$217:$L$243,2,FALSE) -> 4185966 | K9: =VLOOKUP($A$8,'تقرير إحصائية بحجم المبيعات'!$B$252:$L$278,2,FALSE) -> 4835066.8 | L9: =VLOOKUP($A$8,'تقرير إحصائية بحجم المبيعات'!$B$287:$L$313,2,FALSE) -> 4505534.6 | M9: =VLOOKUP($A$8,'تقرير إحصائية بحجم المبيعات'!$B$322:$L$347,2,FALSE) -> 4705280.6 | N9: =VLOOKUP($A$8,'تقرير إحصائية بحجم المبيعات'!$B$357:$L$383,2,FALSE) -> 4700429.7 | O9: =VLOOKUP($A$8,'تقرير إحصائية بحجم المبيعات'!$B$391:$L$420,2,FALSE) -> 5046522.8 | P9: =SUM(D9:O9) -> 49372078
C10: دليفرى | D10: =VLOOKUP($A$8,'تقرير إحصائية بحجم المبيعات'!$B$7:$L$31,3,FALSE) -> 686579.51 | E10: =VLOOKUP($A$8,'تقرير إحصائية بحجم المبيعات'!$B$42:$G$73,3,FALSE) -> 664076.69 | F10: =VLOOKUP($A$8,'تقرير إحصائية بحجم المبيعات'!$B$78:$E$103,3,FALSE) -> 531594.93 | G10: =VLOOKUP($A$8,'تقرير إحصائية بحجم المبيعات'!$B$112:$G$137,3,FALSE) -> 669148.36 | H10: =VLOOKUP($A$8,'تقرير إحصائية بحجم المبيعات'!$B$147:$G$177,3,FALSE) -> 678401.42 | I10: =VLOOKUP($A$8,'تقرير إحصائية بحجم المبيعات'!$B$182:$G$212,3,FALSE) -> 657047.38 | J10: =VLOOKUP($A$8,'تقرير إحصائية بحجم المبيعات'!$B$217:$L$243,3,FALSE) -> 668506.5 | K10: =VLOOKUP($A$8,'تقرير إحصائية بحجم المبيعات'!$B$252:$L$278,3,FALSE) -> 653473.9 | L10: =VLOOKUP($A$8,'تقرير إحصائية بحجم المبيعات'!$B$287:$L$313,3,FALSE) -> 651093.14 | M10: =VLOOKUP($A$8,'تقرير إحصائية بحجم المبيعات'!$B$322:$L$347,3,FALSE) -> 837640.09 | N10: =VLOOKUP($A$8,'تقرير إحصائية بحجم المبيعات'!$B$357:$L$383,3,FALSE) -> 751344.31 | O10: =VLOOKUP($A$8,'تقرير إحصائية بحجم المبيعات'!$B$391:$L$420,3,FALSE) -> 817456.55 | P10: =SUM(D10:O10) -> 8266362.8
C11: اجل | D11: =VLOOKUP($A$8,'تقرير إحصائية بحجم المبيعات'!$B$7:$L$31,4,FALSE) -> 1219804.1 | E11: =VLOOKUP($A$8,'تقرير إحصائية بحجم المبيعات'!$B$42:$G$73,4,FALSE) -> 1194066.9 | F11: =VLOOKUP($A$8,'تقرير إحصائية بحجم المبيعات'!$B$78:$E$103,4,FALSE) -> 1263717.5 | G11: =VLOOKUP($A$8,'تقرير إحصائية بحجم المبيعات'!$B$112:$G$137,4,FALSE) -> 1115175.9 | H11: =VLOOKUP($A$8,'تقرير إحصائية بحجم المبيعات'!$B$147:$G$177,4,FALSE) -> 1279920.1 | I11: =VLOOKUP($A$8,'تقرير إحصائية بحجم المبيعات'!$B$182:$G$212,4,FALSE) -> 1113859.8 | J11: =VLOOKUP($A$8,'تقرير إحصائية بحجم المبيعات'!$B$217:$L$243,4,FALSE) -> 1241652.1 | K11: =VLOOKUP($A$8,'تقرير إحصائية بحجم المبيعات'!$B$252:$L$278,4,FALSE) -> 1371989.5 | L11: =VLOOKUP($A$8,'تقرير إحصائية بحجم المبيعات'!$B$287:$L$313,4,FALSE) -> 1817721.6 | M11: =VLOOKUP($A$8,'تقرير إحصائية بحجم المبيعات'!$B$322:$L$347,4,FALSE) -> 1949631.8 | N11: =VLOOKUP($A$8,'تقرير إحصائية بحجم المبيعات'!$B$357:$L$383,4,FALSE) -> 1533385.2 | O11: =VLOOKUP($A$8,'تقرير إحصائية بحجم المبيعات'!$B$391:$L$420,4,FALSE) -> 1846173.6 | P11: =SUM(D11:O11) -> 16947098
C12: تكلفة البضاعة المباعة | D12: =VLOOKUP($A$8,'تقرير إحصائية بحجم المبيعات'!$B$7:$L$31,11,FALSE) -> 3962640.4 | E12: =VLOOKUP($A$8,'تقرير إحصائية بحجم المبيعات'!$B$42:$L$73,11,FALSE) -> 3883691 | F12: =VLOOKUP($A$8,'تقرير إحصائية بحجم المبيعات'!$B$78:$L$103,11,FALSE) -> 4146557.4 | G12: =VLOOKUP($A$8,'تقرير إحصائية بحجم المبيعات'!$B$112:$L$137,11,FALSE) -> 4499900.3 | H12: =VLOOKUP($A$8,'تقرير إحصائية بحجم المبيعات'!$B$147:$L$177,11,FALSE) -> 4660011.1 | I12: =VLOOKUP($A$8,'تقرير إحصائية بحجم المبيعات'!$B$182:$L$212,11,FALSE) -> 4834090.2 | J12: =VLOOKUP($A$8,'تقرير إحصائية بحجم المبيعات'!$B$217:$L$243,11,FALSE) -> 4883642.4 | K12: =VLOOKUP($A$8,'تقرير إحصائية بحجم المبيعات'!$B$252:$L$278,11,FALSE) -> 5509486.1 | L12: =VLOOKUP($A$8,'تقرير إحصائية بحجم المبيعات'!$B$287:$L$313,11,FALSE) -> 5611199.8 | M12: =VLOOKUP($A$8,'تقرير إحصائية بحجم المبيعات'!$B$322:$L$347,11,FALSE) -> 5952639.3 | N12: =VLOOKUP($A$8,'تقرير إحصائية بحجم المبيعات'!$B$357:$L$383,11,FALSE) -> 5564222 | O12: =VLOOKUP($A$8,'تقرير إحصائية بحجم المبيعات'!$B$391:$L$420,11,FALSE) -> 6048273.5 | P12: =SUM(D12:O12) -> 59556353
C13: مجمل الربح | D13: =D8-D12 -> 990451.96 | E13: =E8-E12 -> 935391.28 | F13: =F8-F12 -> 1012104.8 | G13: =G8-G12 -> 1113227.9 | H13: =H8-H12 -> 1182703.5 | I13: =I8-I12 -> 1245900.2 | J13: =J8-J12 -> 1212482.2 | K13: =K8-K12 -> 1351044.2 | ... O13: =O8-O12 -> 1661879.5 | P13: =SUM(D13:O13) -> 15029186
C14: خصم نقدى | P14: =SUM(D14:O14) -> 0
C15: ارباح صرف اصناف بيع اصول | P15: =SUM(D15:O15) -> 0
C16: فائض جرد | D16: 16005.5 | E16: =1784.79-7.67 -> 1777.12 | F16: -0.21 | I16: 15.63 | K16: 0.01 | L16: 0.76 | N16: 1216.82 | P16: =SUM(D16:O16) -> 19015.63
C17: ايرادات اخرى | H17: 3850 | J17: 26300 | L17: 14000 | M17: -2000 | N17: 9000 | O17: -3200 | P17: =SUM(D17:O17) -> 47950
C18: إجمالي الايرادات اخرى | D18: =SUM(D14:D17) -> 16005.5 | E18: =SUM(E14:E17) -> 1777.12 | F18: =SUM(F14:F17) -> -0.21 | G18: =SUM(G14:G17) -> 0 | H18: =SUM(H14:H17) -> 3850 | I18: =SUM(I14:I17) -> 15.63 | J18: =SUM(J14:J17) -> 26300 | K18: =SUM(K14:K17) -> 0.01 | ... O18: =SUM(O14:O17) -> -3200 | P18: =SUM(D18:O18) -> 66965.63
C19: مجمل الربح | D19: =D13+D18 -> 1006457.5 | E19: =E13+E18 -> 937168.4 | F19: =F13+F18 -> 1012104.6 | G19: =G13+G18 -> 1113227.9 | H19: =H13+H18 -> 1186553.5 | I19: =I13+I18 -> 1245915.8 | J19: =J13+J18 -> 1238782.2 | K19: =K13+K18 -> 1351044.2 | ... O19: =O13+O18 -> 1658679.5 | P19: =SUM(D19:O19) -> 15096151
C21: EXPENSE DETAILS | D21: =D23/D8 -> 0.050035944
C22: مرتبات الادارة | D22: =IFERROR(VLOOKUP(C22,'تقرير المصروفات حسب الشهر'!$C$10:$AD$119,3,FALSE),0) -> 0 | E22: =IFERROR(VLOOKUP(C22,'تقرير المصروفات حسب الشهر'!$C$135:$AD$244,3,FALSE),0) -> 0 | F22: 0 | G22: =IFERROR(VLOOKUP(C22,'تقرير المصروفات حسب الشهر'!$C$387:$AD$495,3,FALSE),0) -> 0 | H22: =IFERROR(VLOOKUP(C22,'تقرير المصروفات حسب الشهر'!$C$512:$AD$620,3,FALSE),0) -> 0 | I22: =IFERROR(VLOOKUP(C22,'تقرير المصروفات حسب الشهر'!$C$637:$AD$746,3,FALSE),0) -> 0 | J22: =IFERROR(VLOOKUP(C22,'تقرير المصروفات حسب الشهر'!$C$763:$AD$872,3,FALSE),0) -> 0 | K22: =IFERROR(VLOOKUP(C22,'تقرير المصروفات حسب الشهر'!$C$890:$AD$999,3,FALSE),0) -> 0 | L22: =IFERROR(VLOOKUP(C22,'تقرير المصروفات حسب الشهر'!$C$1016:$AD$1126,3,FALSE),0) -> 0 | M22: =IFERROR(VLOOKUP(C22,'تقرير المصروفات حسب الشهر'!$C$1143:$AD$1254,3,FALSE),0) -> 0 | N22: =IFERROR(VLOOKUP(C22,'تقرير المصروفات حسب الشهر'!$C$1270:$AD$1381,3,FALSE),0) -> 0 | O22: =IFERROR(VLOOKUP(C22,'تقرير المصروفات حسب الشهر'!$C$1397:$AI$1512,3,FALSE),0) -> 0 | P22: =SUM(D22:O22) -> 0
C23: مرتبات الفروع | D23: =IFERROR(VLOOKUP(C23,'تقرير المصروفات حسب الشهر'!$C$10:$AD$119,3,FALSE),0) -> 247832.65 | E23: =IFERROR(VLOOKUP(C23,'تقرير المصروفات حسب الشهر'!$C$135:$AD$244,3,FALSE),0) -> 252633.85 | F23: 267258.59 | G23: =IFERROR(VLOOKUP(C23,'تقرير المصروفات حسب الشهر'!$C$387:$AD$495,3,FALSE),0) -> 268532.35 | H23: =IFERROR(VLOOKUP(C23,'تقرير المصروفات حسب الشهر'!$C$512:$AD$620,3,FALSE),0) -> 282215.71 | I23: =IFERROR(VLOOKUP(C23,'تقرير المصروفات حسب الشهر'!$C$637:$AD$746,3,FALSE),0) -> 301672.18 | J23: =IFERROR(VLOOKUP(C23,'تقرير المصروفات حسب الشهر'!$C$763:$AD$872,3,FALSE),0) -> 324699.23 | K23: =IFERROR(VLOOKUP(C23,'تقرير المصروفات حسب الشهر'!$C$890:$AD$999,3,FALSE),0) -> 323117.12 | L23: =IFERROR(VLOOKUP(C23,'تقرير المصروفات حسب الشهر'!$C$1016:$AD$1126,3,FALSE),0) -> 366497.25 | M23: =IFERROR(VLOOKUP(C23,'تقرير المصروفات حسب الشهر'!$C$1143:$AD$1254,3,FALSE),0) -> 370937.51 | N23: =IFERROR(VLOOKUP(C23,'تقرير المصروفات حسب الشهر'!$C$1270:$AD$1381,3,FALSE),0) -> 386501.24 | O23: =IFERROR(VLOOKUP(C23,'تقرير المصروفات حسب الشهر'!$C$1397:$AI$1512,3,FALSE),0) -> 397777.67 | P23: =SUM(D23:O23) -> 3789675.3
C24: الكهرباء | D24: =IFERROR(VLOOKUP(C24,'تقرير المصروفات حسب الشهر'!$C$10:$AD$119,3,FALSE),0) -> 6809 | E24: =IFERROR(VLOOKUP(C24,'تقرير المصروفات حسب الشهر'!$C$135:$AD$244,3,FALSE),0) -> 0 | F24: 5553 | G24: =IFERROR(VLOOKUP(C24,'تقرير المصروفات حسب الشهر'!$C$387:$AD$495,3,FALSE),0) -> 0 | H24: =IFERROR(VLOOKUP(C24,'تقرير المصروفات حسب الشهر'!$C$512:$AD$620,3,FALSE),0) -> 5902 | I24: =IFERROR(VLOOKUP(C24,'تقرير المصروفات حسب الشهر'!$C$637:$AD$746,3,FALSE),0) -> 4084 | J24: =IFERROR(VLOOKUP(C24,'تقرير المصروفات حسب الشهر'!$C$763:$AD$872,3,FALSE),0) -> 5313 | K24: =IFERROR(VLOOKUP(C24,'تقرير المصروفات حسب الشهر'!$C$890:$AD$999,3,FALSE),0) -> 7215 | L24: =IFERROR(VLOOKUP(C24,'تقرير المصروفات حسب الشهر'!$C$1016:$AD$1126,3,FALSE),0) -> 8346 | M24: =IFERROR(VLOOKUP(C24,'تقرير المصروفات حسب الشهر'!$C$1143:$AD$1254,3,FALSE),0) -> 7871 | N24: =IFERROR(VLOOKUP(C24,'تقرير المصروفات حسب الشهر'!$C$1270:$AD$1381,3,FALSE),0) -> 5587 | O24: =IFERROR(VLOOKUP(C24,'تقرير المصروفات حسب الشهر'!$C$1397:$AI$1512,3,FALSE),0) -> 0 | P24: =SUM(D24:O24) -> 56680
C25: المياه | D25: =IFERROR(VLOOKUP(C25,'تقرير المصروفات حسب الشهر'!$C$10:$AD$119,3,FALSE),0) -> 200 | E25: =IFERROR(VLOOKUP(C25,'تقرير المصروفات حسب الشهر'!$C$135:$AD$244,3,FALSE),0) -> 200 | F25: 200 | G25: =IFERROR(VLOOKUP(C25,'تقرير المصروفات حسب الشهر'!$C$387:$AD$495,3,FALSE),0) -> 200 | H25: =IFERROR(VLOOKUP(C25,'تقرير المصروفات حسب الشهر'!$C$512:$AD$620,3,FALSE),0) -> 0 | I25: =IFERROR(VLOOKUP(C25,'تقرير المصروفات حسب الشهر'!$C$637:$AD$746,3,FALSE),0) -> 215 | J25: =IFERROR(VLOOKUP(C25,'تقرير المصروفات حسب الشهر'!$C$763:$AD$872,3,FALSE),0) -> 0 | K25: =IFERROR(VLOOKUP(C25,'تقرير المصروفات حسب الشهر'!$C$890:$AD$999,3,FALSE),0) -> 569 | L25: =IFERROR(VLOOKUP(C25,'تقرير المصروفات حسب الشهر'!$C$1016:$AD$1126,3,FALSE),0) -> 490 | M25: =IFERROR(VLOOKUP(C25,'تقرير المصروفات حسب الشهر'!$C$1143:$AD$1254,3,FALSE),0) -> 500 | N25: =IFERROR(VLOOKUP(C25,'تقرير المصروفات حسب الشهر'!$C$1270:$AD$1381,3,FALSE),0) -> 842 | O25: =IFERROR(VLOOKUP(C25,'تقرير المصروفات حسب الشهر'!$C$1397:$AI$1512,3,FALSE),0) -> 831 | P25: =SUM(D25:O25) -> 4247
C26: التليفون الارضي | D26: =IFERROR(VLOOKUP(C26,'تقرير المصروفات حسب الشهر'!$C$10:$AD$119,3,FALSE),0) -> 500 | E26: =IFERROR(VLOOKUP(C26,'تقرير المصروفات حسب الشهر'!$C$135:$AD$244,3,FALSE),0) -> 0 | F26: 350 | G26: =IFERROR(VLOOKUP(C26,'تقرير المصروفات حسب الشهر'!$C$387:$AD$495,3,FALSE),0) -> 0 | H26: =IFERROR(VLOOKUP(C26,'تقرير المصروفات حسب الشهر'!$C$512:$AD$620,3,FALSE),0) -> 0 | I26: =IFERROR(VLOOKUP(C26,'تقرير المصروفات حسب الشهر'!$C$637:$AD$746,3,FALSE),0) -> 800 | J26: =IFERROR(VLOOKUP(C26,'تقرير المصروفات حسب الشهر'!$C$763:$AD$872,3,FALSE),0) -> 0 | K26: =IFERROR(VLOOKUP(C26,'تقرير المصروفات حسب الشهر'!$C$890:$AD$999,3,FALSE),0) -> 0 | L26: =IFERROR(VLOOKUP(C26,'تقرير المصروفات حسب الشهر'!$C$1016:$AD$1126,3,FALSE),0) -> 0 | M26: =IFERROR(VLOOKUP(C26,'تقرير المصروفات حسب الشهر'!$C$1143:$AD$1254,3,FALSE),0) -> 0 | N26: =IFERROR(VLOOKUP(C26,'تقرير المصروفات حسب الشهر'!$C$1270:$AD$1381,3,FALSE),0) -> 400 | O26: =IFERROR(VLOOKUP(C26,'تقرير المصروفات حسب الشهر'!$C$1397:$AI$1512,3,FALSE),0) -> 0 | P26: =SUM(D26:O26) -> 2050
C27: الايجار - الصيدلية | D27: =IFERROR(VLOOKUP(C27,'تقرير المصروفات حسب الشهر'!$C$10:$AD$119,3,FALSE),0) -> 100000 | E27: =IFERROR(VLOOKUP(C27,'تقرير المصروفات حسب الشهر'!$C$135:$AD$244,3,FALSE),0) -> 100000 | F27: 100000 | G27: =IFERROR(VLOOKUP(C27,'تقرير المصروفات حسب الشهر'!$C$387:$AD$495,3,FALSE),0) -> 100000 | H27: =IFERROR(VLOOKUP(C27,'تقرير المصروفات حسب الشهر'!$C$512:$AD$620,3,FALSE),0) -> 100000 | I27: =IFERROR(VLOOKUP(C27,'تقرير المصروفات حسب الشهر'!$C$637:$AD$746,3,FALSE),0) -> 100000 | J27: =IFERROR(VLOOKUP(C27,'تقرير المصروفات حسب الشهر'!$C$763:$AD$872,3,FALSE),0) -> 100000 | K27: =IFERROR(VLOOKUP(C27,'تقرير المصروفات حسب الشهر'!$C$890:$AD$999,3,FALSE),0) -> 100000 | L27: =IFERROR(VLOOKUP(C27,'تقرير المصروفات حسب الشهر'!$C$1016:$AD$1126,3,FALSE),0) -> 100000 | M27: =IFERROR(VLOOKUP(C27,'تقرير المصروفات حسب الشهر'!$C$1143:$AD$1254,3,FALSE),0) -> 100000 | N27: =IFERROR(VLOOKUP(C27,'تقرير المصروفات حسب الشهر'!$C$1270:$AD$1381,3,FALSE),0) -> 170000 | O27: =IFERROR(VLOOKUP(C27,'تقرير المصروفات حسب الشهر'!$C$1397:$AI$1512,3,FALSE),0) -> 170000 | P27: =SUM(D27:O27) -> 1340000
C28: الايجار - الادارة | D28: =IFERROR(VLOOKUP(C28,'تقرير المصروفات حسب الشهر'!$C$10:$AD$119,3,FALSE),0) -> 0 | E28: =IFERROR(VLOOKUP(C28,'تقرير المصروفات حسب الشهر'!$C$135:$AD$244,3,FALSE),0) -> 0 | F28: 0 | G28: =IFERROR(VLOOKUP(C28,'تقرير المصروفات حسب الشهر'!$C$387:$AD$495,3,FALSE),0) -> 0 | H28: =IFERROR(VLOOKUP(C28,'تقرير المصروفات حسب الشهر'!$C$512:$AD$620,3,FALSE),0) -> 0 | I28: =IFERROR(VLOOKUP(C28,'تقرير المصروفات حسب الشهر'!$C$637:$AD$746,3,FALSE),0) -> 0 | J28: =IFERROR(VLOOKUP(C28,'تقرير المصروفات حسب الشهر'!$C$763:$AD$872,3,FALSE),0) -> 0 | K28: =IFERROR(VLOOKUP(C28,'تقرير المصروفات حسب الشهر'!$C$890:$AD$999,3,FALSE),0) -> 0 | L28: =IFERROR(VLOOKUP(C28,'تقرير المصروفات حسب الشهر'!$C$1016:$AD$1126,3,FALSE),0) -> 0 | M28: =IFERROR(VLOOKUP(C28,'تقرير المصروفات حسب الشهر'!$C$1143:$AD$1254,3,FALSE),0) -> 0 | N28: =IFERROR(VLOOKUP(C28,'تقرير المصروفات حسب الشهر'!$C$1270:$AD$1381,3,FALSE),0) -> 0 | O28: =IFERROR(VLOOKUP(C28,'تقرير المصروفات حسب الشهر'!$C$1397:$AI$1512,3,FALSE),0) -> 0 | P28: =SUM(D28:O28) -> 0
C29: ايجارات متنوعه | D29: =IFERROR(VLOOKUP(C29,'تقرير المصروفات حسب الشهر'!$C$10:$AD$119,3,FALSE),0) -> 0 | E29: =IFERROR(VLOOKUP(C29,'تقرير المصروفات حسب الشهر'!$C$135:$AD$244,3,FALSE),0) -> 0 | F29: 0 | G29: =IFERROR(VLOOKUP(C29,'تقرير المصروفات حسب الشهر'!$C$387:$AD$495,3,FALSE),0) -> 0 | H29: =IFERROR(VLOOKUP(C29,'تقرير المصروفات حسب الشهر'!$C$512:$AD$620,3,FALSE),0) -> 0 | I29: =IFERROR(VLOOKUP(C29,'تقرير المصروفات حسب الشهر'!$C$637:$AD$746,3,FALSE),0) -> 0 | J29: =IFERROR(VLOOKUP(C29,'تقرير المصروفات حسب الشهر'!$C$763:$AD$872,3,FALSE),0) -> 0 | K29: =IFERROR(VLOOKUP(C29,'تقرير المصروفات حسب الشهر'!$C$890:$AD$999,3,FALSE),0) -> 0 | L29: =IFERROR(VLOOKUP(C29,'تقرير المصروفات حسب الشهر'!$C$1016:$AD$1126,3,FALSE),0) -> 0 | M29: =IFERROR(VLOOKUP(C29,'تقرير المصروفات حسب الشهر'!$C$1143:$AD$1254,3,FALSE),0) -> 0 | N29: =IFERROR(VLOOKUP(C29,'تقرير المصروفات حسب الشهر'!$C$1270:$AD$1381,3,FALSE),0) -> 0 | O29: =IFERROR(VLOOKUP(C29,'تقرير المصروفات حسب الشهر'!$C$1397:$AI$1512,3,FALSE),0) -> 0 | P29: =SUM(D29:O29) -> 0
C30: ادوات مكتبية | D30: =IFERROR(VLOOKUP(C30,'تقرير المصروفات حسب الشهر'!$C$10:$AD$119,3,FALSE),0) -> 0 | E30: =IFERROR(VLOOKUP(C30,'تقرير المصروفات حسب الشهر'!$C$135:$AD$244,3,FALSE),0) -> 65 | F30: 925.25 | G30: =IFERROR(VLOOKUP(C30,'تقرير المصروفات حسب الشهر'!$C$387:$AD$495,3,FALSE),0) -> 65 | H30: =IFERROR(VLOOKUP(C30,'تقرير المصروفات حسب الشهر'!$C$512:$AD$620,3,FALSE),0) -> 0 | I30: =IFERROR(VLOOKUP(C30,'تقرير المصروفات حسب الشهر'!$C$637:$AD$746,3,FALSE),0) -> 988.25 | J30: =IFERROR(VLOOKUP(C30,'تقرير المصروفات حسب الشهر'!$C$763:$AD$872,3,FALSE),0) -> 70 | K30: =IFERROR(VLOOKUP(C30,'تقرير المصروفات حسب الشهر'!$C$890:$AD$999,3,FALSE),0) -> 0 | L30: =IFERROR(VLOOKUP(C30,'تقرير المصروفات حسب الشهر'!$C$1016:$AD$1126,3,FALSE),0) -> 80 | M30: =IFERROR(VLOOKUP(C30,'تقرير المصروفات حسب الشهر'!$C$1143:$AD$1254,3,FALSE),0) -> 967.5 | N30: =IFERROR(VLOOKUP(C30,'تقرير المصروفات حسب الشهر'!$C$1270:$AD$1381,3,FALSE),0) -> 0 | O30: =IFERROR(VLOOKUP(C30,'تقرير المصروفات حسب الشهر'!$C$1397:$AI$1512,3,FALSE),0) -> 1200 | P30: =SUM(D30:O30) -> 4361
C31: فواتير الموبايل | D31: =IFERROR(VLOOKUP(C31,'تقرير المصروفات حسب الشهر'!$C$10:$AD$119,3,FALSE),0) -> 783.54 | E31: =IFERROR(VLOOKUP(C31,'تقرير المصروفات حسب الشهر'!$C$135:$AD$244,3,FALSE),0) -> 783.54 | F31: 783.54 | G31: =IFERROR(VLOOKUP(C31,'تقرير المصروفات حسب الشهر'!$C$387:$AD$495,3,FALSE),0) -> 791.98 | H31: =IFERROR(VLOOKUP(C31,'تقرير المصروفات حسب الشهر'!$C$512:$AD$620,3,FALSE),0) -> 721.98 | I31: =IFERROR(VLOOKUP(C31,'تقرير المصروفات حسب الشهر'!$C$637:$AD$746,3,FALSE),0) -> 721.98 | J31: =IFERROR(VLOOKUP(C31,'تقرير المصروفات حسب الشهر'!$C$763:$AD$872,3,FALSE),0) -> 721.98 | K31: =IFERROR(VLOOKUP(C31,'تقرير المصروفات حسب الشهر'!$C$890:$AD$999,3,FALSE),0) -> 721.98 | L31: =IFERROR(VLOOKUP(C31,'تقرير المصروفات حسب الشهر'!$C$1016:$AD$1126,3,FALSE),0) -> 871.98 | M31: =IFERROR(VLOOKUP(C31,'تقرير المصروفات حسب الشهر'!$C$1143:$AD$1254,3,FALSE),0) -> 721.98 | N31: =IFERROR(VLOOKUP(C31,'تقرير المصروفات حسب الشهر'!$C$1270:$AD$1381,3,FALSE),0) -> 1071.98 | O31: =IFERROR(VLOOKUP(C31,'تقرير المصروفات حسب الشهر'!$C$1397:$AI$1512,3,FALSE),0) -> 721.98 | P31: =SUM(D31:O31) -> 9418.44
C32: مكافات مبيعات الادوية | D32: =IFERROR(VLOOKUP(C32,'تقرير المصروفات حسب الشهر'!$C$10:$AD$119,3,FALSE),0) -> 0 | E32: =IFERROR(VLOOKUP(C32,'تقرير المصروفات حسب الشهر'!$C$135:$AD$244,3,FALSE),0) -> 0 | F32: 0 | G32: =IFERROR(VLOOKUP(C32,'تقرير المصروفات حسب الشهر'!$C$387:$AD$495,3,FALSE),0) -> 0 | H32: =IFERROR(VLOOKUP(C32,'تقرير المصروفات حسب الشهر'!$C$512:$AD$620,3,FALSE),0) -> 0 | I32: =IFERROR(VLOOKUP(C32,'تقرير المصروفات حسب الشهر'!$C$637:$AD$746,3,FALSE),0) -> 0 | J32: =IFERROR(VLOOKUP(C32,'تقرير المصروفات حسب الشهر'!$C$763:$AD$872,3,FALSE),0) -> 0 | K32: =IFERROR(VLOOKUP(C32,'تقرير المصروفات حسب الشهر'!$C$890:$AD$999,3,FALSE),0) -> 0 | L32: =IFERROR(VLOOKUP(C32,'تقرير المصروفات حسب الشهر'!$C$1016:$AD$1126,3,FALSE),0) -> 0 | M32: =IFERROR(VLOOKUP(C32,'تقرير المصروفات حسب الشهر'!$C$1143:$AD$1254,3,FALSE),0) -> 0 | N32: =IFERROR(VLOOKUP(C32,'تقرير المصروفات حسب الشهر'!$C$1270:$AD$1381,3,FALSE),0) -> 0 | O32: =IFERROR(VLOOKUP(C32,'تقرير المصروفات حسب الشهر'!$C$1397:$AI$1512,3,FALSE),0) -> 0 | P32: =SUM(D32:O32) -> 0
C33: مكافات مبيعات التجميل | D33: =IFERROR(VLOOKUP(C33,'تقرير المصروفات حسب الشهر'!$C$10:$AD$119,3,FALSE),0) -> 1500 | E33: =IFERROR(VLOOKUP(C33,'تقرير المصروفات حسب الشهر'!$C$135:$AD$244,3,FALSE),0) -> 1400 | F33: 1400 | G33: =IFERROR(VLOOKUP(C33,'تقرير المصروفات حسب الشهر'!$C$387:$AD$495,3,FALSE),0) -> 1400 | H33: =IFERROR(VLOOKUP(C33,'تقرير المصروفات حسب الشهر'!$C$512:$AD$620,3,FALSE),0) -> 2200 | I33: =IFERROR(VLOOKUP(C33,'تقرير المصروفات حسب الشهر'!$C$637:$AD$746,3,FALSE),0) -> 1400 | J33: =IFERROR(VLOOKUP(C33,'تقرير المصروفات حسب الشهر'!$C$763:$AD$872,3,FALSE),0) -> 2200 | K33: =IFERROR(VLOOKUP(C33,'تقرير المصروفات حسب الشهر'!$C$890:$AD$999,3,FALSE),0) -> 0 | L33: =IFERROR(VLOOKUP(C33,'تقرير المصروفات حسب الشهر'!$C$1016:$AD$1126,3,FALSE),0) -> 500 | M33: =IFERROR(VLOOKUP(C33,'تقرير المصروفات حسب الشهر'!$C$1143:$AD$1254,3,FALSE),0) -> 0 | N33: =IFERROR(VLOOKUP(C33,'تقرير المصروفات حسب الشهر'!$C$1270:$AD$1381,3,FALSE),0) -> 1150 | O33: =IFERROR(VLOOKUP(C33,'تقرير المصروفات حسب الشهر'!$C$1397:$AI$1512,3,FALSE),0) -> 0 | P33: =SUM(D33:O33) -> 13150
... C130: فوائد القروض - التجارى وفا بنك AWB | D130: =IFERROR(VLOOKUP(C130,'تقرير المصروفات حسب الشهر'!$C$10:$AD$119,3,FALSE),0) -> 0 | E130: =IFERROR(VLOOKUP(C130,'تقرير المصروفات حسب الشهر'!$C$135:$AD$244,3,FALSE),0) -> 0 | F130: 0 | G130: =IFERROR(VLOOKUP(C130,'تقرير المصروفات حسب الشهر'!$C$387:$AD$495,3,FALSE),0) -> 0 | H130: =IFERROR(VLOOKUP(C130,'تقرير المصروفات حسب الشهر'!$C$512:$AD$620,3,FALSE),0) -> 0 | I130: =IFERROR(VLOOKUP(C130,'تقرير المصروفات حسب الشهر'!$C$637:$AD$746,3,FALSE),0) -> 0 | J130: =IFERROR(VLOOKUP(C130,'تقرير المصروفات حسب الشهر'!$C$763:$AD$872,3,FALSE),0) -> 0 | K130: =IFERROR(VLOOKUP(C130,'تقرير المصروفات حسب الشهر'!$C$890:$AD$999,3,FALSE),0) -> 0 | L130: =IFERROR(VLOOKUP(C130,'تقرير المصروفات حسب الشهر'!$C$1016:$AD$1126,3,FALSE),0) -> 0 | M130: =IFERROR(VLOOKUP(C130,'تقرير المصروفات حسب الشهر'!$C$1143:$AD$1254,3,FALSE),0) -> 0 | N130: =IFERROR(VLOOKUP(C130,'تقرير المصروفات حسب الشهر'!$C$1270:$AD$1381,3,FALSE),0) -> 0 | O130: =IFERROR(VLOOKUP(C130,'تقرير المصروفات حسب الشهر'!$C$1397:$AI$1512,3,FALSE),0) -> 0 | P130: =SUM(D130:O130) -> 0
C131: فوائد القروض - بنك القاهرة BDC | D131: =IFERROR(VLOOKUP(C131,'تقرير المصروفات حسب الشهر'!$C$10:$AD$119,3,FALSE),0) -> 0 | E131: =IFERROR(VLOOKUP(C131,'تقرير المصروفات حسب الشهر'!$C$135:$AD$244,3,FALSE),0) -> 0 | F131: 0 | G131: =IFERROR(VLOOKUP(C131,'تقرير المصروفات حسب الشهر'!$C$387:$AD$495,3,FALSE),0) -> 0 | H131: =IFERROR(VLOOKUP(C131,'تقرير المصروفات حسب الشهر'!$C$512:$AD$620,3,FALSE),0) -> 0 | I131: =IFERROR(VLOOKUP(C131,'تقرير المصروفات حسب الشهر'!$C$637:$AD$746,3,FALSE),0) -> 0 | J131: =IFERROR(VLOOKUP(C131,'تقرير المصروفات حسب الشهر'!$C$763:$AD$872,3,FALSE),0) -> 0 | K131: =IFERROR(VLOOKUP(C131,'تقرير المصروفات حسب الشهر'!$C$890:$AD$999,3,FALSE),0) -> 0 | L131: =IFERROR(VLOOKUP(C131,'تقرير المصروفات حسب الشهر'!$C$1016:$AI$1128,3,FALSE),0) -> 0 | M131: =IFERROR(VLOOKUP(C131,'تقرير المصروفات حسب الشهر'!$C$1143:$AD$1254,3,FALSE),0) -> 0 | N131: =IFERROR(VLOOKUP(C131,'تقرير المصروفات حسب الشهر'!$C$1270:$AD$1381,3,FALSE),0) -> 0 | O131: =IFERROR(VLOOKUP(C131,'تقرير المصروفات حسب الشهر'!$C$1397:$AI$1512,3,FALSE),0) -> 0 | P131: =SUM(D131:O131) -> 0
