Workbook
Name linkkksss: INDIRECT(ADDRESS(1,1,,,Dashboard!A1))
Name sheet_link: INDIRECT(ADDRESS(7,3,,,Dashboard!DY1048576))
Name Shheet_Link: INDIRECT(ADDRESS(7,3,,,Dashboard!A1))
Name shshshs: INDIRECT(ADDRESS(1,1,,,Dashboard!A1))

Sheet Dashboard
C2: Income Statement
C3: Dashboard | R3: HQ
H7: YEAR TOTAL EXPENSES & YEAR TOTAL INCOME CHART
C8: Income Statement
C9: (YEAR TOTAL) | EJ9: =ADDRESS(7,3,,,R3) -> HQ!$C$7
C11: Total Sales Revenue | D11: : | E11: =AB42 -> 5.2493549e+08
C12: Total Cost of Sales | D12: : | E12: =AC42 -> 2.5952038e+08
C13: Gross Profit | D13: : | E13: =E11-E12 -> 2.6541512e+08
C14: Total Non-Operational Income | D14: : | E14: =AF42 -> 5626802.9
C15: TOTAL INCOME | D15: : | E15: =E13+E14 -> 2.7104192e+08
C18: TOTAL EXPENSES | D18: : | E18: =AE42 -> 1.3979296e+08 | EI18: تقرير المصروفات حسب الشهر
EI19: تقرير مصروفات إجمالية
EI20: تقرير إحصائية بحجم المبيعات
EI21: تقرير مجمعة حسب الشهر | EJ21: HQ
C22: NET PROFIT | D22: : | E22: =E15-E18 -> 1.3124896e+08 | EI22: تقرير مصروفات حسب الفرع | EJ22: Aguza
EI23: مجمعة إجمالية | EJ23: October
E24: =2125593.24-E22 -> -1.2912337e+08 | EJ24: Batal
H25: April | EJ25: Nasr City
EJ26: Sweedy
C27: MONTH TOTAL | H27: EXPENSES DETAILS (MONTH TOTAL) | EJ27: Raya
C28: Income Statement | H28: Operating Expenses | EJ28: Etisalat
C29: =H25 -> April | H29: مرتبات الادارة | J29: =VLOOKUP($H$25,$AA$90:$EI$101,2,FALSE) -> 1600742 | K29: =J29/$E$36 -> 0.1145087 | M29: اعلان ودعاية - ايام دعاية | O29: =VLOOKUP($H$25,$AA$90:$EI$101,58,FALSE) -> 0 | P29: =O29/$E$36 -> 0 | AA29: Monthes | AB29: Total Sales Revenue | AC29: Total Cost of Sales | AD29: Total Income | AE29: Total Operating Expenses | AF29: Total Non-Operational Income | AG29: Net Profit | EJ29: Hazzem Hassan
H30: مرتبات الفروع | J30: =VLOOKUP($H$25,$AA$90:$EI$101,3,FALSE) -> 4557559.9 | K30: =J30/$E$36 -> 0.32602396 | M30: اكراميات - ايام دعاية | O30: =VLOOKUP($H$25,$AA$90:$EI$101,59,FALSE) -> 0 | P30: =O30/$E$36 -> 0 | AA30: January | AB30: ='تقرير مجمعة حسب الشهر'!G37 -> 62570428 | AC30: ='تقرير مجمعة حسب الشهر'!I37 -> 50036279 | AD30: ='تقرير مجمعة حسب الشهر'!J37 -> 12534149 | AE30: ='تقرير مجمعة حسب الشهر'!K37 -> 13391338 | AF30: ='تقرير مجمعة حسب الشهر'!M37 -> 955778.8 | AG30: ='تقرير مجمعة حسب الشهر'!N37 -> 98589.467 | EJ30: Sena3ia
C31: Total Sales Revenue | D31: : | E31: =VLOOKUP(H25,AA30:AG41,MATCH(C31,AA29:AG29,0),0) -> 67586212 | H31: الكهرباء | J31: =VLOOKUP($H$25,$AA$90:$EI$101,4,FALSE) -> 41973 | K31: =J31/$E$36 -> 0.0030025285 | M31: وجبات وانتقال - ايام دعاية | O31: =VLOOKUP($H$25,$AA$90:$EI$101,60,FALSE) -> 0 | P31: =O31/$E$36 -> 0 | AA31: February | AB31: ='تقرير مجمعة حسب الشهر'!G72 -> 53972140 | AC31: ='تقرير مجمعة حسب الشهر'!I72 -> 43447228 | AD31: ='تقرير مجمعة حسب الشهر'!J72 -> 10524912 | AE31: ='تقرير مجمعة حسب الشهر'!K72 -> 12519614 | AF31: ='تقرير مجمعة حسب الشهر'!M72 -> 1458073.2 | AG31: =AD31-AE31+AF31 -> -536628.66 | EJ31: Khargia
C32: Total Cost of Sales | D32: : | E32: =VLOOKUP(H25,AA30:AG41,MATCH(C32,AA29:AG29,0),0) -> 54356704 | H32: المياه | J32: =VLOOKUP($H$25,$AA$90:$EI$101,5,FALSE) -> 1993 | K32: =J32/$E$36 -> 0.00014256878 | M32: مكافات لجنة الجرد | O32: =VLOOKUP($H$25,$AA$90:$EI$101,61,FALSE) -> 35716 | P32: =O32/$E$36 -> 0.0025549355 | AA32: March | AB32: ='تقرير مجمعة حسب الشهر'!G108 -> 67087109 | AC32: ='تقرير مجمعة حسب الشهر'!I108 -> 53880856 | AD32: ='تقرير مجمعة حسب الشهر'!J108 -> 13206253 | AE32: ='تقرير مجمعة حسب الشهر'!K108 -> 13105861 | AF32: ='تقرير مجمعة حسب الشهر'!M108 -> 918992.67 | AG32: =AD32-AE32+AF32 -> 1019383.7 | EJ32: Tagmou3
C33: Gross Profit | D33: : | E33: =E31-E32 -> 13229508 | H33: التليفون الارضي | J33: =VLOOKUP($H$25,$AA$90:$EI$101,6,FALSE) -> 0 | K33: =J33/$E$36 -> 0 | M33: انتقالات لجنة الجرد | O33: =VLOOKUP($H$25,$AA$90:$EI$101,62,FALSE) -> 0 | P33: =O33/$E$36 -> 0 | AA33: April | AB33: ='تقرير مجمعة حسب الشهر'!G144 -> 67586212 | AC33: ='تقرير مجمعة حسب الشهر'!I144 -> 54356704 | AD33: ='تقرير مجمعة حسب الشهر'!J144 -> 13229508 | AE33: ='تقرير مجمعة حسب الشهر'!K144 -> 13979218 | AF33: ='تقرير مجمعة حسب الشهر'!M144 -> 2293958.2 | AG33: =AD33-AE33+AF33 -> 1544248.7 | EJ33: Maadi
C34: Total Non-Operational Income | D34: : | E34: =VLOOKUP(H25,AA30:AG41,MATCH(C34,AA29:AG29,0),0) -> 2293958.2 | H34: الايجار - الصيدلية | J34: =VLOOKUP($H$25,$AA$90:$EI$101,7,FALSE) -> 510000 | K34: =J34/$E$36 -> 0.036482728 | M34: وجبات لجنة الجرد | O34: =VLOOKUP($H$25,$AA$90:$EI$101,63,FALSE) -> 0 | P34: =O34/$E$36 -> 0 | AA34: May | AB34: ='تقرير مجمعة حسب الشهر'!G180 -> 72719603 | AC34: ='تقرير مجمعة حسب الشهر'!I180 -> 57799309 | AD34: ='تقرير مجمعة حسب الشهر'!J180 -> 14920294 | AE34: ='تقرير مجمعة حسب الشهر'!K180 -> 7696926.8 | AF34: ='تقرير مجمعة حسب الشهر'!M180 -> 0 | AG34: =AD34-AE34+AF34 -> 7223367.3 | EJ34: Zaid
C35: TOTAL INCOME | D35: : | E35: =E33+E34 -> 15523467 | H35: الايجار - الادارة | J35: =VLOOKUP($H$25,$AA$90:$EI$101,8,FALSE) -> 50000 | K35: =J35/$E$36 -> 0.003576738 | M35: مسروقات | O35: =VLOOKUP($H$25,$AA$90:$EI$101,64,FALSE) -> 0 | P35: =O35/$E$36 -> 0 | AA35: June | AB35: ='تقرير مجمعة حسب الشهر'!G216 -> 29000000 | AC35: ='تقرير مجمعة حسب الشهر'!I216 -> 0 | AD35: ='تقرير مجمعة حسب الشهر'!J216 -> 29000000 | AE35: ='تقرير مجمعة حسب الشهر'!K216 -> 11300000 | AF35: ='تقرير مجمعة حسب الشهر'!M216 -> 0 | AG35: =AD35-AE35+AF35 -> 17700000 | EJ35: Sand Beach
C36: Total Operating Expenses | D36: : | E36: =VLOOKUP(H25,AA30:AG41,MATCH(C36,AA29:AG29,0),0) -> 13979218 | H36: ايجارات متنوعه | J36: =VLOOKUP($H$25,$AA$90:$EI$101,9,FALSE) -> 438636 | K36: =J36/$E$36 -> 0.031377721 | M36: غرامات | O36: =VLOOKUP($H$25,$AA$90:$EI$101,65,FALSE) -> 0 | P36: =O36/$E$36 -> 0 | AA36: July | AB36: ='تقرير مجمعة حسب الشهر'!G252 -> 29000000 | AC36: ='تقرير مجمعة حسب الشهر'!I252 -> 0 | AD36: ='تقرير مجمعة حسب الشهر'!J252 -> 29000000 | AE36: ='تقرير مجمعة حسب الشهر'!K252 -> 11300000 | AF36: ='تقرير مجمعة حسب الشهر'!M252 -> 0 | AG36: =AD36-AE36+AF36 -> 17700000 | EJ36: Alamya
H37: ادوات مكتبية | J37: =VLOOKUP($H$25,$AA$90:$EI$101,10,FALSE) -> 11417 | K37: =J37/$E$36 -> 0.00081671236 | M37: مستلزمات كمبيوتر | O37: =VLOOKUP($H$25,$AA$90:$EI$101,66,FALSE) -> 35519.5 | P37: =O37/$E$36 -> 0.0025408789 | AA37: August | AB37: ='تقرير مجمعة حسب الشهر'!G288 -> 29000000 | AC37: ='تقرير مجمعة حسب الشهر'!I288 -> 0 | AD37: ='تقرير مجمعة حسب الشهر'!J288 -> 29000000 | AE37: ='تقرير مجمعة حسب الشهر'!K288 -> 11300000 | AF37: ='تقرير مجمعة حسب الشهر'!M288 -> 0 | AG37: =AD37-AE37+AF37 -> 17700000 | EJ37: Online
C38: TOTAL EXPENSES | D38: : | E38: =E36+E37 -> 13979218 | H38: فواتير الموبايل | J38: =VLOOKUP($H$25,$AA$90:$EI$101,11,FALSE) -> 20522 | K38: =J38/$E$36 -> 0.0014680364 | M38: صيانة اجهزة كمبيوتر | O38: =VLOOKUP($H$25,$AA$90:$EI$101,67,FALSE) -> 0 | P38: =O38/$E$36 -> 0 | AA38: September | AB38: ='تقرير مجمعة حسب الشهر'!G324 -> 29000000 | AC38: ='تقرير مجمعة حسب الشهر'!I324 -> 0 | AD38: ='تقرير مجمعة حسب الشهر'!J324 -> 29000000 | AE38: ='تقرير مجمعة حسب الشهر'!K324 -> 11300000 | AF38: ='تقرير مجمعة حسب الشهر'!M324 -> 0 | AG38: =AD38-AE38+AF38 -> 17700000 | EJ38: Orange
H39: مكافات مبيعات الادوية | J39: =VLOOKUP($H$25,$AA$90:$EI$101,12,FALSE) -> 0 | K39: =J39/$E$36 -> 0 | M39: مطبوعات ورقية | O39: =VLOOKUP($H$25,$AA$90:$EI$101,68,FALSE) -> 3500 | P39: =O39/$E$36 -> 0.00025037166 | AA39: October | AB39: ='تقرير مجمعة حسب الشهر'!G360 -> 29000000 | AC39: ='تقرير مجمعة حسب الشهر'!I360 -> 0 | AD39: ='تقرير مجمعة حسب الشهر'!J360 -> 29000000 | AE39: ='تقرير مجمعة حسب الشهر'!K360 -> 11300000 | AF39: ='تقرير مجمعة حسب الشهر'!M360 -> 0 | AG39: =AD39-AE39+AF39 -> 17700000 | EJ39: Vod.Smart
C40: NET PROFIT | D40: : | E40: =E35-E38-E39 -> 1544248.7 | H40: مكافات مبيعات التجميل | J40: =VLOOKUP($H$25,$AA$90:$EI$101,13,FALSE) -> 5040 | K40: =J40/$E$36 -> 0.00036053519 | M40: شحن بضاعة | O40: =VLOOKUP($H$25,$AA$90:$EI$101,69,FALSE) -> 0 | P40: =O40/$E$36 -> 0 | AA40: November | AB40: ='تقرير مجمعة حسب الشهر'!G396 -> 28000000 | AC40: ='تقرير مجمعة حسب الشهر'!I396 -> 0 | AD40: ='تقرير مجمعة حسب الشهر'!J396 -> 28000000 | AE40: ='تقرير مجمعة حسب الشهر'!K396 -> 11300000 | AF40: ='تقرير مجمعة حسب الشهر'!M396 -> 0 | AG40: =AD40-AE40+AF40 -> 16700000 | EJ40: Vod.Zahraa
H41: بوفية وضيافة | J41: =VLOOKUP($H$25,$AA$90:$EI$101,14,FALSE) -> 9856 | K41: =J41/$E$36 -> 0.0007050466 | M41: عيديات ومناسبات | O41: =VLOOKUP($H$25,$AA$90:$EI$101,70,FALSE) -> 0 | P41: =O41/$E$36 -> 0 | AA41: December | AB41: ='تقرير مجمعة حسب الشهر'!G432 -> 28000000 | AC41: ='تقرير مجمعة حسب الشهر'!I432 -> 0 | AD41: ='تقرير مجمعة حسب الشهر'!J432 -> 28000000 | AE41: ='تقرير مجمعة حسب الشهر'!K432 -> 11300000 | AF41: ='تقرير مجمعة حسب الشهر'!M432 -> 0 | AG41: =AD41-AE41+AF41 -> 16700000 | EJ41: Mo7awelat
H42: رسوم وتراخيص وعمولات | J42: =VLOOKUP($H$25,$AA$90:$EI$101,15,FALSE) -> 18457 | K42: =J42/$E$36 -> 0.0013203171 | M42: بدلات متنوعه | O42: =VLOOKUP($H$25,$AA$90:$EI$101,71,FALSE) -> 280665 | P42: =O42/$E$36 -> 0.020077304 | AA42: Total | AB42: =SUM(AB30:AB41) -> 5.2493549e+08 | AC42: =SUM(AC30:AC41) -> 2.5952038e+08 | AD42: =SUM(AD30:AD41) -> 2.6541512e+08 | AE42: =SUM(AE30:AE41) -> 1.3979296e+08 | AF42: =SUM(AF30:AF41) -> 5626802.9 | AG42: =SUM(AG30:AG41) -> 1.3124896e+08 | EJ42: Electric
H43: ورق طباعة | J43: =VLOOKUP($H$25,$AA$90:$EI$101,16,FALSE) -> 0 | K43: =J43/$E$36 -> 0 | M43: اجهزة ومستلزمات متنوعه | O43: =VLOOKUP($H$25,$AA$90:$EI$101,72,FALSE) -> 10173.5 | P43: =O43/$E$36 -> 0.00072775889 | EJ43: M.C.V
H44: بكر طباعة ريسيت | J44: =VLOOKUP($H$25,$AA$90:$EI$101,17,FALSE) -> 0 | K44: =J44/$E$36 -> 0 | M44: احبار طابعات | O44: =VLOOKUP($H$25,$AA$90:$EI$101,73,FALSE) -> 32915.24 | P44: =O44/$E$36 -> 0.0023545838 | EJ44: Egyplast
H45: بكر طباعة باركود | J45: =VLOOKUP($H$25,$AA$90:$EI$101,18,FALSE) -> 0 | K45: =J45/$E$36 -> 0 | M45: الانترنت | O45: =VLOOKUP($H$25,$AA$90:$EI$101,74,FALSE) -> 47623.35 | P45: =O45/$E$36 -> 0.0034067249 | EJ45: Etisalat.Katamya
H46: اعلان ودعاية وتسويق | J46: =VLOOKUP($H$25,$AA$90:$EI$101,19,FALSE) -> 38632 | K46: =J46/$E$36 -> 0.0027635309 | M46: الدعم الفني - سوفتك | O46: =VLOOKUP($H$25,$AA$90:$EI$101,75,FALSE) -> 53370 | P46: =O46/$E$36 -> 0.0038178102 | EJ46: CFC
H47: اكراميات | J47: =VLOOKUP($H$25,$AA$90:$EI$101,20,FALSE) -> 26730.47 | K47: =J47/$E$36 -> 0.0019121578 | M47: مصروف اهلاك مباني وانشاءات | O47: =VLOOKUP($H$25,$AA$90:$EI$101,76,FALSE) -> 73.33 | P47: =O47/$E$36 -> 5.245644e-06 | EJ47: North.Coast
...

Sheet HQ
C2: INCOME STATEMTN
G3: Income Statement For HQ
D6: Jan | E6: February | F6: March | G6: April | H6: May | I6: June | J6: July | K6: August | L6: September | M6: October | N6: November | O6: December | P6: Total
C7: INCOME DETAILS
C8: المبيعات | D8: =D9+D10+D11 -> 0 | E8: =E9+E10+E11 -> 0 | F8: =F9+F10+F11 -> 0 | G8: =G9+G10+G11 -> 0 | H8: =H9+H10+H11 -> 0 | I8: =I9+I10+I11 -> 0 | J8: =J9+J10+J11 -> 0 | K8: =K9+K10+K11 -> 0 | ... O8: =O9+O10+O11 -> 0 | P8: =SUM(D8:O8) -> 0
C9: نقدى | P9: =SUM(D9:O9) -> 0
C10: دليفرى | P10: =SUM(D10:O10) -> 0
C11: اجل | P11: =SUM(D11:O11) -> 0
C12: تكلفة البضاعة المباعة | P12: =SUM(D12:O12) -> 0
C13: مجمل الربح | D13: =D8-D12 -> 0 | E13: =E8-E12 -> 0 | F13: =F8-F12 -> 0 | G13: =G8-G12 -> 0 | H13: =H8-H12 -> 0 | I13: =I8-I12 -> 0 | J13: =J8-J12 -> 0 | K13: =K8-K12 -> 0 | ... O13: =O8-O12 -> 0 | P13: =SUM(D13:O13) -> 0
C14: خصم نقدى | D14: 260331.75 | E14: 395534.66 | F14: 456251.66 | G14: 303920.72 | P14: =SUM(D14:O14) -> 1416038.8
C15: ارباح صرف اصناف بيع اصول | P15: =SUM(D15:O15) -> 0
C16: فائض جرد | P16: =SUM(D16:O16) -> 0
C17: ايرادات اخرى | D17: 447413.49 | E17: 684132.79 | F17: 360780.84 | G17: 1502257.9 | P17: =SUM(D17:O17) -> 2994585
C18: إجمالي الايرادات اخرى | D18: =SUM(D14:D17) -> 707745.24 | E18: =SUM(E14:E17) -> 1079667.5 | F18: =SUM(F14:F17) -> 817032.5 | G18: =SUM(G14:G17) -> 1806178.7 | H18: =SUM(H14:H17) -> 0 | I18: =SUM(I14:I17) -> 0 | J18: =SUM(J14:J17) -> 0 | K18: =SUM(K14:K17) -> 0 | ... O18: =SUM(O14:O17) -> 0 | P18: =SUM(D18:O18) -> 4410623.8
C19: مجمل الربح | D19: =D13+D18 -> 707745.24 | E19: =E13+E18 -> 1079667.5 | F19: =F13+F18 -> 817032.5 | G19: =G13+G18 -> 1806178.7 | H19: =H13+H18 -> 0 | I19: =I13+I18 -> 0 | J19: =J13+J18 -> 0 | K19: =K13+K18 -> 0 | ... P19: =P13+P18 -> 4410623.8 | Q19: =P19-P14 -> 2994585
C21: EXPENSE DETAILS
C22: مرتبات الادارة | D22: =IFERROR(VLOOKUP(C22,'تقرير المصروفات حسب الشهر'!$C$10:$AD$119,2,FALSE),0) -> 1554391.1 | E22: =IFERROR(VLOOKUP(C22,'تقرير المصروفات حسب الشهر'!$C$136:$AD$254,2,FALSE),0) -> 1494705.5 | F22: =_xlfn.XLOOKUP(C22,'تقرير المصروفات حسب الشهر'!C262:C378,'تقرير المصروفات حسب الشهر'!D262:D378,0,0) -> 1468661.1 | G22: =IFERROR(VLOOKUP(C22,'تقرير المصروفات حسب الشهر'!$C$391:$AD$510,2,FALSE),0) -> 1600742 | H22: =IFERROR(VLOOKUP(C22,'تقرير المصروفات حسب الشهر'!$C$519:$AD$627,2,FALSE),0) -> 1389895.6 | I22: =IFERROR(VLOOKUP(C22,'تقرير المصروفات حسب الشهر'!$C$644:$AD$753,2,FALSE),0) -> 100000 | J22: =IFERROR(VLOOKUP(C22,'تقرير المصروفات حسب الشهر'!$C$770:$AD$879,2,FALSE),0) -> 100000 | K22: =IFERROR(VLOOKUP(C22,'تقرير المصروفات حسب الشهر'!$C$896:$D$1006,2,FALSE),0) -> 100000 | L22: =IFERROR(VLOOKUP(C22,'تقرير المصروفات حسب الشهر'!$C$1023:$AD$1133,2,FALSE),0) -> 100000 | M22: =IFERROR(VLOOKUP(C22,'تقرير المصروفات حسب الشهر'!$C$1150:$AD$1261,2,FALSE),0) -> 100000 | N22: =IFERROR(VLOOKUP(C22,'تقرير المصروفات حسب الشهر'!$C$1277:$AD$1388,2,FALSE),0) -> 100000 | O22: =IFERROR(VLOOKUP(C22,'تقرير المصروفات حسب الشهر'!$C$1404:$AI$1519,2,FALSE),0) -> 100000 | P22: =SUM(D22:O22) -> 8208395.2
C23: مرتبات الفروع | D23: =IFERROR(VLOOKUP(C23,'تقرير المصروفات حسب الشهر'!$C$10:$AD$119,2,FALSE),0) -> 0 | E23: =IFERROR(VLOOKUP(C23,'تقرير المصروفات حسب الشهر'!$C$136:$AD$254,2,FALSE),0) -> 0 | F23: =_xlfn.XLOOKUP(C23,'تقرير المصروفات حسب الشهر'!C263:C379,'تقرير المصروفات حسب الشهر'!D263:D379,0,0) -> 0 | G23: =IFERROR(VLOOKUP(C23,'تقرير المصروفات حسب الشهر'!$C$391:$AD$510,2,FALSE),0) -> 0 | H23: =IFERROR(VLOOKUP(C23,'تقرير المصروفات حسب الشهر'!$C$519:$AD$627,2,FALSE),0) -> 30907.7 | I23: =IFERROR(VLOOKUP(C23,'تقرير المصروفات حسب الشهر'!$C$644:$AD$753,2,FALSE),0) -> 100000 | J23: =IFERROR(VLOOKUP(C23,'تقرير المصروفات حسب الشهر'!$C$770:$AD$879,2,FALSE),0) -> 100000 | K23: =IFERROR(VLOOKUP(C23,'تقرير المصروفات حسب الشهر'!$C$896:$D$1006,2,FALSE),0) -> 100000 | L23: =IFERROR(VLOOKUP(C23,'تقرير المصروفات حسب الشهر'!$C$1023:$AD$1133,2,FALSE),0) -> 100000 | M23: =IFERROR(VLOOKUP(C23,'تقرير المصروفات حسب الشهر'!$C$1150:$AD$1261,2,FALSE),0) -> 100000 | N23: =IFERROR(VLOOKUP(C23,'تقرير المصروفات حسب الشهر'!$C$1277:$AD$1388,2,FALSE),0) -> 100000 | O23: =IFERROR(VLOOKUP(C23,'تقرير المصروفات حسب الشهر'!$C$1404:$AI$1519,2,FALSE),0) -> 100000 | P23: =SUM(D23:O23) -> 730907.7
C24: الكهرباء | D24: =IFERROR(VLOOKUP(C24,'تقرير المصروفات حسب الشهر'!$C$10:$AD$119,2,FALSE),0) -> 10837 | E24: =IFERROR(VLOOKUP(C24,'تقرير المصروفات حسب الشهر'!$C$136:$AD$254,2,FALSE),0) -> 5299 | F24: =_xlfn.XLOOKUP(C24,'تقرير المصروفات حسب الشهر'!C264:C380,'تقرير المصروفات حسب الشهر'!D264:D380,0,0) -> 5446 | G24: =IFERROR(VLOOKUP(C24,'تقرير المصروفات حسب الشهر'!$C$391:$AD$510,2,FALSE),0) -> 8611 | H24: =IFERROR(VLOOKUP(C24,'تقرير المصروفات حسب الشهر'!$C$519:$AD$627,2,FALSE),0) -> 11826 | I24: =IFERROR(VLOOKUP(C24,'تقرير المصروفات حسب الشهر'!$C$644:$AD$753,2,FALSE),0) -> 100000 | J24: =IFERROR(VLOOKUP(C24,'تقرير المصروفات حسب الشهر'!$C$770:$AD$879,2,FALSE),0) -> 100000 | K24: =IFERROR(VLOOKUP(C24,'تقرير المصروفات حسب الشهر'!$C$896:$D$1006,2,FALSE),0) -> 100000 | L24: =IFERROR(VLOOKUP(C24,'تقرير المصروفات حسب الشهر'!$C$1023:$AD$1133,2,FALSE),0) -> 100000 | M24: =IFERROR(VLOOKUP(C24,'تقرير المصروفات حسب الشهر'!$C$1150:$AD$1261,2,FALSE),0) -> 100000 | N24: =IFERROR(VLOOKUP(C24,'تقرير المصروفات حسب الشهر'!$C$1277:$AD$1388,2,FALSE),0) -> 100000 | O24: =IFERROR(VLOOKUP(C24,'تقرير المصروفات حسب الشهر'!$C$1404:$AI$1519,2,FALSE),0) -> 100000 | P24: =SUM(D24:O24) -> 742019
C25: المياه | D25: =IFERROR(VLOOKUP(C25,'تقرير المصروفات حسب الشهر'!$C$10:$AD$119,2,FALSE),0) -> 0 | E25: =IFERROR(VLOOKUP(C25,'تقرير المصروفات حسب الشهر'!$C$136:$AD$254,2,FALSE),0) -> 0 | F25: =_xlfn.XLOOKUP(C25,'تقرير المصروفات حسب الشهر'!C265:C381,'تقرير المصروفات حسب الشهر'!D265:D381,0,0) -> 0 | G25: =IFERROR(VLOOKUP(C25,'تقرير المصروفات حسب الشهر'!$C$391:$AD$510,2,FALSE),0) -> 585 | H25: =IFERROR(VLOOKUP(C25,'تقرير المصروفات حسب الشهر'!$C$519:$AD$627,2,FALSE),0) -> 0 | I25: =IFERROR(VLOOKUP(C25,'تقرير المصروفات حسب الشهر'!$C$644:$AD$753,2,FALSE),0) -> 100000 | J25: =IFERROR(VLOOKUP(C25,'تقرير المصروفات حسب الشهر'!$C$770:$AD$879,2,FALSE),0) -> 100000 | K25: =IFERROR(VLOOKUP(C25,'تقرير المصروفات حسب الشهر'!$C$896:$D$1006,2,FALSE),0) -> 100000 | L25: =IFERROR(VLOOKUP(C25,'تقرير المصروفات حسب الشهر'!$C$1023:$AD$1133,2,FALSE),0) -> 100000 | M25: =IFERROR(VLOOKUP(C25,'تقرير المصروفات حسب الشهر'!$C$1150:$AD$1261,2,FALSE),0) -> 100000 | N25: =IFERROR(VLOOKUP(C25,'تقرير المصروفات حسب الشهر'!$C$1277:$AD$1388,2,FALSE),0) -> 100000 | O25: =IFERROR(VLOOKUP(C25,'تقرير المصروفات حسب الشهر'!$C$1404:$AI$1519,2,FALSE),0) -> 100000 | P25: =SUM(D25:O25) -> 700585
C26: التليفون الارضي | D26: =IFERROR(VLOOKUP(C26,'تقرير المصروفات حسب الشهر'!$C$10:$AD$119,2,FALSE),0) -> 0 | E26: =IFERROR(VLOOKUP(C26,'تقرير المصروفات حسب الشهر'!$C$136:$AD$254,2,FALSE),0) -> 2400 | F26: =_xlfn.XLOOKUP(C26,'تقرير المصروفات حسب الشهر'!C266:C382,'تقرير المصروفات حسب الشهر'!D266:D382,0,0) -> 274.63 | G26: =IFERROR(VLOOKUP(C26,'تقرير المصروفات حسب الشهر'!$C$391:$AD$510,2,FALSE),0) -> 0 | H26: =IFERROR(VLOOKUP(C26,'تقرير المصروفات حسب الشهر'!$C$519:$AD$627,2,FALSE),0) -> 0 | I26: =IFERROR(VLOOKUP(C26,'تقرير المصروفات حسب الشهر'!$C$644:$AD$753,2,FALSE),0) -> 100000 | J26: =IFERROR(VLOOKUP(C26,'تقرير المصروفات حسب الشهر'!$C$770:$AD$879,2,FALSE),0) -> 100000 | K26: =IFERROR(VLOOKUP(C26,'تقرير المصروفات حسب الشهر'!$C$896:$D$1006,2,FALSE),0) -> 100000 | L26: =IFERROR(VLOOKUP(C26,'تقرير المصروفات حسب الشهر'!$C$1023:$AD$1133,2,FALSE),0) -> 100000 | M26: =IFERROR(VLOOKUP(C26,'تقرير المصروفات حسب الشهر'!$C$1150:$AD$1261,2,FALSE),0) -> 100000 | N26: =IFERROR(VLOOKUP(C26,'تقرير المصروفات حسب الشهر'!$C$1277:$AD$1388,2,FALSE),0) -> 100000 | O26: =IFERROR(VLOOKUP(C26,'تقرير المصروفات حسب الشهر'!$C$1404:$AI$1519,2,FALSE),0) -> 100000 | P26: =SUM(D26:O26) -> 702674.63
C27: الايجار - الصيدلية | D27: =IFERROR(VLOOKUP(C27,'تقرير المصروفات حسب الشهر'!$C$10:$AD$119,2,FALSE),0) -> 0 | E27: =IFERROR(VLOOKUP(C27,'تقرير المصروفات حسب الشهر'!$C$136:$AD$254,2,FALSE),0) -> 0 | F27: =_xlfn.XLOOKUP(C27,'تقرير المصروفات حسب الشهر'!C267:C383,'تقرير المصروفات حسب الشهر'!D267:D383,0,0) -> 0 | G27: =IFERROR(VLOOKUP(C27,'تقرير المصروفات حسب الشهر'!$C$391:$AD$510,2,FALSE),0) -> 0 | H27: =IFERROR(VLOOKUP(C27,'تقرير المصروفات حسب الشهر'!$C$519:$AD$627,2,FALSE),0) -> 0 | I27: =IFERROR(VLOOKUP(C27,'تقرير المصروفات حسب الشهر'!$C$644:$AD$753,2,FALSE),0) -> 100000 | J27: =IFERROR(VLOOKUP(C27,'تقرير المصروفات حسب الشهر'!$C$770:$AD$879,2,FALSE),0) -> 100000 | K27: =IFERROR(VLOOKUP(C27,'تقرير المصروفات حسب الشهر'!$C$896:$D$1006,2,FALSE),0) -> 100000 | L27: =IFERROR(VLOOKUP(C27,'تقرير المصروفات حسب الشهر'!$C$1023:$AD$1133,2,FALSE),0) -> 100000 | M27: =IFERROR(VLOOKUP(C27,'تقرير المصروفات حسب الشهر'!$C$1150:$AD$1261,2,FALSE),0) -> 100000 | N27: =IFERROR(VLOOKUP(C27,'تقرير المصروفات حسب الشهر'!$C$1277:$AD$1388,2,FALSE),0) -> 100000 | O27: =IFERROR(VLOOKUP(C27,'تقرير المصروفات حسب الشهر'!$C$1404:$AI$1519,2,FALSE),0) -> 100000 | P27: =SUM(D27:O27) -> 700000
C28: الايجار - الادارة | D28: =IFERROR(VLOOKUP(C28,'تقرير المصروفات حسب الشهر'!$C$10:$AD$119,2,FALSE),0) -> 50000 | E28: =IFERROR(VLOOKUP(C28,'تقرير المصروفات حسب الشهر'!$C$136:$AD$254,2,FALSE),0) -> 50000 | F28: =_xlfn.XLOOKUP(C28,'تقرير المصروفات حسب الشهر'!C268:C384,'تقرير المصروفات حسب الشهر'!D268:D384,0,0) -> 50000 | G28: =IFERROR(VLOOKUP(C28,'تقرير المصروفات حسب الشهر'!$C$391:$AD$510,2,FALSE),0) -> 50000 | H28: =IFERROR(VLOOKUP(C28,'تقرير المصروفات حسب الشهر'!$C$519:$AD$627,2,FALSE),0) -> 50000 | I28: =IFERROR(VLOOKUP(C28,'تقرير المصروفات حسب الشهر'!$C$644:$AD$753,2,FALSE),0) -> 100000 | J28: =IFERROR(VLOOKUP(C28,'تقرير المصروفات حسب الشهر'!$C$770:$AD$879,2,FALSE),0) -> 100000 | K28: =IFERROR(VLOOKUP(C28,'تقرير المصروفات حسب الشهر'!$C$896:$D$1006,2,FALSE),0) -> 100000 | L28: =IFERROR(VLOOKUP(C28,'تقرير المصروفات حسب الشهر'!$C$1023:$AD$1133,2,FALSE),0) -> 100000 | M28: =IFERROR(VLOOKUP(C28,'تقرير المصروفات حسب الشهر'!$C$1150:$AD$1261,2,FALSE),0) -> 100000 | N28: =IFERROR(VLOOKUP(C28,'تقرير المصروفات حسب الشهر'!$C$1277:$AD$1388,2,FALSE),0) -> 100000 | O28: =IFERROR(VLOOKUP(C28,'تقرير المصروفات حسب الشهر'!$C$1404:$AI$1519,2,FALSE),0) -> 100000 | P28: =SUM(D28:O28) -> 950000
C29: ايجارات متنوعه | D29: =IFERROR(VLOOKUP(C29,'تقرير المصروفات حسب الشهر'!$C$10:$AD$119,2,FALSE),0) -> 43330 | E29: =IFERROR(VLOOKUP(C29,'تقرير المصروفات حسب الشهر'!$C$136:$AD$254,2,FALSE),0) -> 64330 | F29: =_xlfn.XLOOKUP(C29,'تقرير المصروفات حسب الشهر'!C269:C385,'تقرير المصروفات حسب الشهر'!D269:D385,0,0) -> 50730 | G29: =IFERROR(VLOOKUP(C29,'تقرير المصروفات حسب الشهر'!$C$391:$AD$510,2,FALSE),0) -> 48130 | H29: =IFERROR(VLOOKUP(C29,'تقرير المصروفات حسب الشهر'!$C$519:$AD$627,2,FALSE),0) -> 48130 | I29: =IFERROR(VLOOKUP(C29,'تقرير المصروفات حسب الشهر'!$C$644:$AD$753,2,FALSE),0) -> 100000 | J29: =IFERROR(VLOOKUP(C29,'تقرير المصروفات حسب الشهر'!$C$770:$AD$879,2,FALSE),0) -> 100000 | K29: =IFERROR(VLOOKUP(C29,'تقرير المصروفات حسب الشهر'!$C$896:$D$1006,2,FALSE),0) -> 100000 | L29: =IFERROR(VLOOKUP(C29,'تقرير المصروفات حسب الشهر'!$C$1023:$AD$1133,2,FALSE),0) -> 100000 | M29: =IFERROR(VLOOKUP(C29,'تقرير المصروفات حسب الشهر'!$C$1150:$AD$1261,2,FALSE),0) -> 100000 | N29: =IFERROR(VLOOKUP(C29,'تقرير المصروفات حسب الشهر'!$C$1277:$AD$1388,2,FALSE),0) -> 100000 | O29: =IFERROR(VLOOKUP(C29,'تقرير المصروفات حسب الشهر'!$C$1404:$AI$1519,2,FALSE),0) -> 100000 | P29: =SUM(D29:O29) -> 954650
C30: ادوات مكتبية | D30: =IFERROR(VLOOKUP(C30,'تقرير المصروفات حسب الشهر'!$C$10:$AD$119,2,FALSE),0) -> 8820 | E30: =IFERROR(VLOOKUP(C30,'تقرير المصروفات حسب الشهر'!$C$136:$AD$254,2,FALSE),0) -> 6850 | F30: =_xlfn.XLOOKUP(C30,'تقرير المصروفات حسب الشهر'!C270:C386,'تقرير المصروفات حسب الشهر'!D270:D386,0,0) -> 4585 | G30: =IFERROR(VLOOKUP(C30,'تقرير المصروفات حسب الشهر'!$C$391:$AD$510,2,FALSE),0) -> 11185 | H30: =IFERROR(VLOOKUP(C30,'تقرير المصروفات حسب الشهر'!$C$519:$AD$627,2,FALSE),0) -> 3009 | I30: =IFERROR(VLOOKUP(C30,'تقرير المصروفات حسب الشهر'!$C$644:$AD$753,2,FALSE),0) -> 100000 | J30: =IFERROR(VLOOKUP(C30,'تقرير المصروفات حسب الشهر'!$C$770:$AD$879,2,FALSE),0) -> 100000 | K30: =IFERROR(VLOOKUP(C30,'تقرير المصروفات حسب الشهر'!$C$896:$D$1006,2,FALSE),0) -> 100000 | L30: =IFERROR(VLOOKUP(C30,'تقرير المصروفات حسب الشهر'!$C$1023:$AD$1133,2,FALSE),0) -> 100000 | M30: =IFERROR(VLOOKUP(C30,'تقرير المصروفات حسب الشهر'!$C$1150:$AD$1261,2,FALSE),0) -> 100000 | N30: =IFERROR(VLOOKUP(C30,'تقرير المصروفات حسب الشهر'!$C$1277:$AD$1388,2,FALSE),0) -> 100000 | O30: =IFERROR(VLOOKUP(C30,'تقرير المصروفات حسب الشهر'!$C$1404:$AI$1519,2,FALSE),0) -> 100000 | P30: =SUM(D30:O30) -> 734449
C31: فواتير الموبايل | D31: =IFERROR(VLOOKUP(C31,'تقرير المصروفات حسب الشهر'!$C$10:$AD$119,2,FALSE),0) -> 13985.85 | E31: =IFERROR(VLOOKUP(C31,'تقرير المصروفات حسب الشهر'!$C$136:$AD$254,2,FALSE),0) -> 15312 | F31: =_xlfn.XLOOKUP(C31,'تقرير المصروفات حسب الشهر'!C271:C387,'تقرير المصروفات حسب الشهر'!D271:D387,0,0) -> 13024.09 | G31: =IFERROR(VLOOKUP(C31,'تقرير المصروفات حسب الشهر'!$C$391:$AD$510,2,FALSE),0) -> 13279.72 | H31: =IFERROR(VLOOKUP(C31,'تقرير المصروفات حسب الشهر'!$C$519:$AD$627,2,FALSE),0) -> 13946.98 | I31: =IFERROR(VLOOKUP(C31,'تقرير المصروفات حسب الشهر'!$C$644:$AD$753,2,FALSE),0) -> 100000 | J31: =IFERROR(VLOOKUP(C31,'تقرير المصروفات حسب الشهر'!$C$770:$AD$879,2,FALSE),0) -> 100000 | K31: =IFERROR(VLOOKUP(C31,'تقرير المصروفات حسب الشهر'!$C$896:$D$1006,2,FALSE),0) -> 100000 | L31: =IFERROR(VLOOKUP(C31,'تقرير المصروفات حسب الشهر'!$C$1023:$AD$1133,2,FALSE),0) -> 100000 | M31: =IFERROR(VLOOKUP(C31,'تقرير المصروفات حسب الشهر'!$C$1150:$AD$1261,2,FALSE),0) -> 100000 | N31: =IFERROR(VLOOKUP(C31,'تقرير المصروفات حسب الشهر'!$C$1277:$AD$1388,2,FALSE),0) -> 100000 | O31: =IFERROR(VLOOKUP(C31,'تقرير المصروفات حسب الشهر'!$C$1404:$AI$1519,2,FALSE),0) -> 100000 | P31: =SUM(D31:O31) -> 769548.64
C32: مكافات مبيعات الادوية | D32: =IFERROR(VLOOKUP(C32,'تقرير المصروفات حسب الشهر'!$C$10:$AD$119,2,FALSE),0) -> 0 | E32: =IFERROR(VLOOKUP(C32,'تقرير المصروفات حسب الشهر'!$C$136:$AD$254,2,FALSE),0) -> 0 | F32: =_xlfn.XLOOKUP(C32,'تقرير المصروفات حسب الشهر'!C272:C388,'تقرير المصروفات حسب الشهر'!D272:D388,0,0) -> 0 | G32: =IFERROR(VLOOKUP(C32,'تقرير المصروفات حسب الشهر'!$C$391:$AD$510,2,FALSE),0) -> 0 | H32: =IFERROR(VLOOKUP(C32,'تقرير المصروفات حسب الشهر'!$C$519:$AD$627,2,FALSE),0) -> 0 | I32: =IFERROR(VLOOKUP(C32,'تقرير المصروفات حسب الشهر'!$C$644:$AD$753,2,FALSE),0) -> 100000 | J32: =IFERROR(VLOOKUP(C32,'تقرير المصروفات حسب الشهر'!$C$770:$AD$879,2,FALSE),0) -> 100000 | K32: =IFERROR(VLOOKUP(C32,'تقرير المصروفات حسب الشهر'!$C$896:$D$1006,2,FALSE),0) -> 100000 | L32: =IFERROR(VLOOKUP(C32,'تقرير المصروفات حسب الشهر'!$C$1023:$AD$1133,2,FALSE),0) -> 100000 | M32: =IFERROR(VLOOKUP(C32,'تقرير المصروفات حسب الشهر'!$C$1150:$AD$1261,2,FALSE),0) -> 100000 | N32: =IFERROR(VLOOKUP(C32,'تقرير المصروفات حسب الشهر'!$C$1277:$AD$1388,2,FALSE),0) -> 100000 | O32: =IFERROR(VLOOKUP(C32,'تقرير المصروفات حسب الشهر'!$C$1404:$AI$1519,2,FALSE),0) -> 100000 | P32: =SUM(D32:O32) -> 700000
C33: مكافات مبيعات التجميل | D33: =IFERROR(VLOOKUP(C33,'تقرير المصروفات حسب الشهر'!$C$10:$AD$119,2,FALSE),0) -> 22129 | E33: =IFERROR(VLOOKUP(C33,'تقرير المصروفات حسب الشهر'!$C$136:$AD$254,2,FALSE),0) -> 4615 | F33: =_xlfn.XLOOKUP(C33,'تقرير المصروفات حسب الشهر'!C273:C389,'تقرير المصروفات حسب الشهر'!D273:D389,0,0) -> 17210 | G33: =IFERROR(VLOOKUP(C33,'تقرير المصروفات حسب الشهر'!$C$391:$AD$510,2,FALSE),0) -> 2692 | H33: =IFERROR(VLOOKUP(C33,'تقرير المصروفات حسب الشهر'!$C$519:$AD$627,2,FALSE),0) -> 21980 | I33: =IFERROR(VLOOKUP(C33,'تقرير المصروفات حسب الشهر'!$C$644:$AD$753,2,FALSE),0) -> 100000 | J33: =IFERROR(VLOOKUP(C33,'تقرير المصروفات حسب الشهر'!$C$770:$AD$879,2,FALSE),0) -> 100000 | K33: =IFERROR(VLOOKUP(C33,'تقرير المصروفات حسب الشهر'!$C$896:$D$1006,2,FALSE),0) -> 100000 | L33: =IFERROR(VLOOKUP(C33,'تقرير المصروفات حسب الشهر'!$C$1023:$AD$1133,2,FALSE),0) -> 100000 | M33: =IFERROR(VLOOKUP(C33,'تقرير المصروفات حسب الشهر'!$C$1150:$AD$1261,2,FALSE),0) -> 100000 | N33: =IFERROR(VLOOKUP(C33,'تقرير المصروفات حسب الشهر'!$C$1277:$AD$1388,2,FALSE),0) -> 100000 | O33: =IFERROR(VLOOKUP(C33,'تقرير المصروفات حسب الشهر'!$C$1404:$AI$1519,2,FALSE),0) -> 100000 | P33: =SUM(D33:O33) -> 768626
... C134: عروض مبيعات ابليكشن | D134: =IFERROR(VLOOKUP(C134,'تقرير المصروفات حسب الشهر'!$C$10:$AD$119,2,FALSE),0) -> 0 | E134: =IFERROR(VLOOKUP(C134,'تقرير المصروفات حسب الشهر'!$C$136:$AD$254,2,FALSE),0) -> 0 | F134: =_xlfn.XLOOKUP(C134,'تقرير المصروفات حسب الشهر'!C374:C490,'تقرير المصروفات حسب الشهر'!D374:D490,0,0) -> 0 | G134: =IFERROR(VLOOKUP(C134,'تقرير المصروفات حسب الشهر'!$C$391:$AD$510,2,FALSE),0) -> 0 | H134: =IFERROR(VLOOKUP(C134,'تقرير المصروفات حسب الشهر'!$C$519:$AD$627,2,FALSE),0) -> 0 | I134: =IFERROR(VLOOKUP(C134,'تقرير المصروفات حسب الشهر'!$C$644:$AD$753,2,FALSE),0) -> 0 | J134: =IFERROR(VLOOKUP(C134,'تقرير المصروفات حسب الشهر'!$C$770:$AD$879,2,FALSE),0) -> 0 | K134: =IFERROR(VLOOKUP(C134,'تقرير المصروفات حسب الشهر'!$C$896:$D$1006,2,FALSE),0) -> 0 | L134: =IFERROR(VLOOKUP(C134,'تقرير المصروفات حسب الشهر'!$C$1023:$AD$1133,2,FALSE),0) -> 0 | M134: =IFERROR(VLOOKUP(C134,'تقرير المصروفات حسب الشهر'!$C$1150:$AD$1261,2,FALSE),0) -> 0 | N134: =IFERROR(VLOOKUP(C134,'تقرير المصروفات حسب الشهر'!$C$1277:$AD$1388,2,FALSE),0) -> 0 | O134: =IFERROR(VLOOKUP(C134,'تقرير المصروفات حسب الشهر'!$C$1404:$AI$1519,2,FALSE),0) -> 100000 | P134: =SUM(D134:O134) -> 100000
C135: عمولات ادارية | D135: =IFERROR(VLOOKUP(C135,'تقرير المصروفات حسب الشهر'!$C$10:$AD$125,2,FALSE),0) -> 92000 | E135: =IFERROR(VLOOKUP(C135,'تقرير المصروفات حسب الشهر'!$C$136:$AD$254,2,FALSE),0) -> 0 | F135: =_xlfn.XLOOKUP(C135,'تقرير المصروفات حسب الشهر'!C375:C491,'تقرير المصروفات حسب الشهر'!D375:D491,0,0) -> 142000 | G135: =IFERROR(VLOOKUP(C135,'تقرير المصروفات حسب الشهر'!$C$391:$AD$510,2,FALSE),0) -> 92000 | H135: =IFERROR(VLOOKUP(C135,'تقرير المصروفات حسب الشهر'!$C$519:$AD$627,2,FALSE),0) -> 0 | I135: =IFERROR(VLOOKUP(C135,'تقرير المصروفات حسب الشهر'!$C$644:$AD$753,2,FALSE),0) -> 0 | J135: =IFERROR(VLOOKUP(C135,'تقرير المصروفات حسب الشهر'!$C$770:$AD$879,2,FALSE),0) -> 0 | K135: =IFERROR(VLOOKUP(C135,'تقرير المصروفات حسب الشهر'!$C$896:$D$1006,2,FALSE),0) -> 0 | L135: =IFERROR(VLOOKUP(C135,'تقرير المصروفات حسب الشهر'!$C$1023:$AD$1133,2,FALSE),0) -> 0 | M135: =IFERROR(VLOOKUP(C135,'تقرير المصروفات حسب الشهر'!$C$1150:$AD$1261,2,FALSE),0) -> 0 | N135: =IFERROR(VLOOKUP(C135,'تقرير المصروفات حسب الشهر'!$C$1277:$AD$1388,2,FALSE),0) -> 0 | O135: =IFERROR(VLOOKUP(C135,'تقرير المصروفات حسب الشهر'!$C$1404:$AI$1519,2,FALSE),0) -> 0 | P135: =SUM(D135:O135) -> 326000
D136: =IFERROR(VLOOKUP(C136,'تقرير المصروفات حسب الشهر'!$C$10:$AD$119,2,FALSE),0) -> 0 | E136: =IFERROR(VLOOKUP(C136,'تقرير المصروفات حسب الشهر'!$C$136:$AD$254,2,FALSE),0) -> 0 | F136: =_xlfn.XLOOKUP(C136,'تقرير المصروفات حسب الشهر'!C376:C492,'تقرير المصروفات حسب الشهر'!D376:D492,0,0) -> 0 | G136: =IFERROR(VLOOKUP(C136,'تقرير المصروفات حسب الشهر'!$C$391:$AD$510,2,FALSE),0) -> 0 | H136: =IFERROR(VLOOKUP(C136,'تقرير المصروفات حسب الشهر'!$C$519:$AD$627,2,FALSE),0) -> 0 | I136: =IFERROR(VLOOKUP(C136,'تقرير المصروفات حسب الشهر'!$C$644:$AD$753,2,FALSE),0) -> 0 | J136: =IFERROR(VLOOKUP(C136,'تقرير المصروفات حسب الشهر'!$C$770:$AD$879,2,FALSE),0) -> 0 | K136: =IFERROR(VLOOKUP(C136,'تقرير المصروفات حسب الشهر'!$C$896:$D$1006,2,FALSE),0) -> 0 | L136: =IFERROR(VLOOKUP(C136,'تقرير المصروفات حسب الشهر'!$C$1023:$AD$1133,2,FALSE),0) -> 0 | M136: =IFERROR(VLOOKUP(C136,'تقرير المصروفات حسب الشهر'!$C$1150:$AD$1261,2,FALSE),0) -> 0 | N136: =IFERROR(VLOOKUP(C136,'تقرير المصروفات حسب الشهر'!$C$1277:$AD$1388,2,FALSE),0) -> 0 | O136: =IFERROR(VLOOKUP(C136,'تقرير المصروفات حسب الشهر'!$C$1404:$AI$1519,2,FALSE),0) -> 0 | P136: =SUM(D136:O136) -> 0
D137: =IFERROR(VLOOKUP(C137,'تقرير المصروفات حسب الشهر'!$C$10:$AD$119,2,FALSE),0) -> 0 | E137: =IFERROR(VLOOKUP(C137,'تقرير المصروفات حسب الشهر'!$C$136:$AD$254,2,FALSE),0) -> 0 | F137: =_xlfn.XLOOKUP(C137,'تقرير المصروفات حسب الشهر'!C377:C493,'تقرير المصروفات حسب الشهر'!D377:D493,0,0) -> 0 | G137: =IFERROR(VLOOKUP(C137,'تقرير المصروفات حسب الشهر'!$C$391:$AD$510,2,FALSE),0) -> 0 | H137: =IFERROR(VLOOKUP(C137,'تقرير المصروفات حسب الشهر'!$C$519:$AD$627,2,FALSE),0) -> 0 | I137: =IFERROR(VLOOKUP(C137,'تقرير المصروفات حسب الشهر'!$C$644:$AD$753,2,FALSE),0) -> 0 | J137: =IFERROR(VLOOKUP(C137,'تقرير المصروفات حسب الشهر'!$C$770:$AD$879,2,FALSE),0) -> 0 | K137: =IFERROR(VLOOKUP(C137,'تقرير المصروفات حسب الشهر'!$C$896:$D$1006,2,FALSE),0) -> 0 | L137: =IFERROR(VLOOKUP(C137,'تقرير المصروفات حسب الشهر'!$C$1023:$AD$1133,2,FALSE),0) -> 0 | M137: =IFERROR(VLOOKUP(C137,'تقرير المصروفات حسب الشهر'!$C$1150:$AD$1261,2,FALSE),0) -> 0 | N137: =IFERROR(VLOOKUP(C137,'تقرير المصروفات حسب الشهر'!$C$1277:$AD$1388,2,FALSE),0) -> 0 | O137: =IFERROR(VLOOKUP(C137,'تقرير المصروفات حسب الشهر'!$C$1404:$AI$1519,2,FALSE),0) -> 0 | P137: =SUM(D137:O137) -> 0
D138: =IFERROR(VLOOKUP(C138,'تقرير المصروفات حسب الشهر'!$C$10:$AD$119,2,FALSE),0) -> 0 | E138: =IFERROR(VLOOKUP(C138,'تقرير المصروفات حسب الشهر'!$C$136:$AD$254,2,FALSE),0) -> 0 | F138: =_xlfn.XLOOKUP(C138,'تقرير المصروفات حسب الشهر'!C378:C494,'تقرير المصروفات حسب الشهر'!D378:D494,0,0) -> 0 | G138: =IFERROR(VLOOKUP(C138,'تقرير المصروفات حسب الشهر'!$C$391:$AD$510,2,FALSE),0) -> 0 | H138: =IFERROR(VLOOKUP(C138,'تقرير المصروفات حسب الشهر'!$C$519:$AD$627,2,FALSE),0) -> 0 | I138: =IFERROR(VLOOKUP(C138,'تقرير المصروفات حسب الشهر'!$C$644:$AD$753,2,FALSE),0) -> 0 | J138: =IFERROR(VLOOKUP(C138,'تقرير المصروفات حسب الشهر'!$C$770:$AD$879,2,FALSE),0) -> 0 | K138: =IFERROR(VLOOKUP(C138,'تقرير المصروفات حسب الشهر'!$C$896:$D$1006,2,FALSE),0) -> 0 | L138: =IFERROR(VLOOKUP(C138,'تقرير المصروفات حسب الشهر'!$C$1023:$AD$1133,2,FALSE),0) -> 0 | M138: =IFERROR(VLOOKUP(C138,'تقرير المصروفات حسب الشهر'!$C$1150:$AD$1261,2,FALSE),0) -> 0 | N138: =IFERROR(VLOOKUP(C138,'تقرير المصروفات حسب الشهر'!$C$1277:$AD$1388,2,FALSE),0) -> 0 | O138: =IFERROR(VLOOKUP(C138,'تقرير المصروفات حسب الشهر'!$C$1404:$AI$1519,2,FALSE),0) -> 0 | P138: =SUM(D138:O138) -> 0
D139: =IFERROR(VLOOKUP(C139,'تقرير المصروفات حسب الشهر'!$C$10:$AD$119,2,FALSE),0) -> 0 | E139: =IFERROR(VLOOKUP(C139,'تقرير المصروفات حسب الشهر'!$C$136:$AD$254,2,FALSE),0) -> 0 | F139: =_xlfn.XLOOKUP(C139,'تقرير المصروفات حسب الشهر'!C379:C495,'تقرير المصروفات حسب الشهر'!D379:D495,0,0) -> 0 | G139: =IFERROR(VLOOKUP(C139,'تقرير المصروفات حسب الشهر'!$C$391:$AD$510,2,FALSE),0) -> 0 | H139: =IFERROR(VLOOKUP(C139,'تقرير المصروفات حسب الشهر'!$C$519:$AD$627,2,FALSE),0) -> 0 | I139: =IFERROR(VLOOKUP(C139,'تقرير المصروفات حسب الشهر'!$C$644:$AD$753,2,FALSE),0) -> 0 | J139: =IFERROR(VLOOKUP(C139,'تقرير المصروفات حسب الشهر'!$C$770:$AD$879,2,FALSE),0) -> 0 | K139: =IFERROR(VLOOKUP(C139,'تقرير المصروفات حسب الشهر'!$C$896:$D$1006,2,FALSE),0) -> 0 | L139: =IFERROR(VLOOKUP(C139,'تقرير المصروفات حسب الشهر'!$C$1023:$AD$1133,2,FALSE),0) -> 0 | M139: =IFERROR(VLOOKUP(C139,'تقرير المصروفات حسب الشهر'!$C$1150:$AD$1261,2,FALSE),0) -> 0 | N139: =IFERROR(VLOOKUP(C139,'تقرير المصروفات حسب الشهر'!$C$1277:$AD$1388,2,FALSE),0) -> 0 | O139: =IFERROR(VLOOKUP(C139,'تقرير المصروفات حسب الشهر'!$C$1404:$AI$1519,2,FALSE),0) -> 0 | P139: =SUM(D139:O139) -> 0
C140: إجمالي المصروفات | D140: =SUM(D22:D139) -> 2880668.4 | E140: =SUM(E22:E139) -> 2812755.2 | F140: =SUM(F22:F139) -> 3008191 | G140: =SUM(G22:G139) -> 3011282.7 | H140: =SUM(H22:H139) -> 2506583.5 | I140: =SUM(I22:I139) -> 11000000 | J140: =SUM(J22:J139) -> 11000000 | K140: =SUM(K22:K139) -> 11000000 | ... O140: =SUM(O22:O139) -> 11300000 | P140: =SUM(D140:O140) -> 91719481
C142: مجمل الربح | D142: =D19 -> 707745.24 | E142: =E19 -> 1079667.5 | F142: =F19 -> 817032.5 | G142: =G19 -> 1806178.7 | H142: =H19 -> 0 | I142: =I19 -> 0 | J142: =J19 -> 0 | K142: =K19 -> 0 | ... P142: =P19 -> 4410623.8
C145: صافي الربح / الخسارة | D145: =D142-D140 -> -2172923.2 | E145: =E142-E140 -> -1733087.8 | F145: =F142-F140 -> -2191158.5 | G145: =G142-G140 -> -1205104.1 | H145: =H142-H140 -> -2506583.5 | I145: =I142-I140 -> -11000000 | J145: =J142-J140 -> -11000000 | K145: =K142-K140 -> -11000000 | ... P145: =P142-P140 -> -87308857
G149: =-1205104.06-G145 -> 0

Sheet Aguza
C2: INCOME STATEMTN
F3: Income Statement For AGOUZA
D6: Jan | E6: February | F6: March | G6: April | H6: May | I6: June | J6: July | K6: August | L6: September | M6: October | N6: November | O6: December | P6: TOTAL
C7: INCOME DETAILS
A8: العجوزة | C8: المبيعات | D8: =D9+D10+D11 -> 7433176.6 | E8: =E9+E10+E11 -> 6302491.1 | F8: =F9+F10+F11 -> 8102573.4 | G8: =G9+G10+G11 -> 8394480.6 | H8: =H9+H10+H11 -> 9610286.1 | I8: =I9+I10+I11 -> 1000000 | J8: =J9+J10+J11 -> 1000000 | K8: =K9+K10+K11 -> 1000000 | ... O8: =O9+O10+O11 -> 1000000 | P8: =SUM(D8:O8) -> 46843008
C9: نقدى | D9: =VLOOKUP($A$8,'تقرير إحصائية بحجم المبيعات'!$B$7:$L$31,2,FALSE) -> 4910885.3 | E9: =VLOOKUP($A$8,'تقرير إحصائية بحجم المبيعات'!$B$42:$G$73,2,FALSE) -> 4136232.3 | F9: =VLOOKUP($A$8,'تقرير إحصائية بحجم المبيعات'!$B$78:$E$103,2,FALSE) -> 4997934.7 | G9: =VLOOKUP($A$8,'تقرير إحصائية بحجم المبيعات'!$B$112:$G$137,2,FALSE) -> 5094880.8 | H9: =VLOOKUP($A$8,'تقرير إحصائية بحجم المبيعات'!$B$147:$G$177,2,FALSE) -> 5883566.6 | I9: =VLOOKUP($A$8,'تقرير إحصائية بحجم المبيعات'!$B$182:$G$212,2,FALSE) -> 1000000 | J9: =VLOOKUP($A$8,'تقرير إحصائية بحجم المبيعات'!$B$217:$L$243,2,FALSE) -> 1000000 | K9: =VLOOKUP($A$8,'تقرير إحصائية بحجم المبيعات'!$B$252:$L$278,2,FALSE) -> 1000000 | L9: =VLOOKUP($A$8,'تقرير إحصائية بحجم المبيعات'!$B$287:$L$313,2,FALSE) -> 1000000 | M9: =VLOOKUP($A$8,'تقرير إحصائية بحجم المبيعات'!$B$322:$L$347,2,FALSE) -> 1000000 | N9: =VLOOKUP($A$8,'تقرير إحصائية بحجم المبيعات'!$B$357:$L$383,2,FALSE) -> 1000000 | O9: =VLOOKUP($A$8,'تقرير إحصائية بحجم المبيعات'!$B$391:$L$420,2,FALSE) -> 1000000 | P9: =SUM(D9:O9) -> 32023500
C10: دليفرى | D10: =VLOOKUP($A$8,'تقرير إحصائية بحجم المبيعات'!$B$7:$L$31,3,FALSE) -> 691551.39 | E10: =VLOOKUP($A$8,'تقرير إحصائية بحجم المبيعات'!$B$42:$G$73,3,FALSE) -> 548271.11 | F10: =VLOOKUP($A$8,'تقرير إحصائية بحجم المبيعات'!$B$78:$E$103,3,FALSE) -> 833928.87 | G10: =VLOOKUP($A$8,'تقرير إحصائية بحجم المبيعات'!$B$112:$G$137,3,FALSE) -> 774333.25 | H10: =VLOOKUP($A$8,'تقرير إحصائية بحجم المبيعات'!$B$147:$G$177,3,FALSE) -> 735167.98 | I10: =VLOOKUP($A$8,'تقرير إحصائية بحجم المبيعات'!$B$182:$G$212,3,FALSE) -> 0 | J10: =VLOOKUP($A$8,'تقرير إحصائية بحجم المبيعات'!$B$217:$L$243,3,FALSE) -> 0 | K10: =VLOOKUP($A$8,'تقرير إحصائية بحجم المبيعات'!$B$252:$L$278,3,FALSE) -> 0 | L10: =VLOOKUP($A$8,'تقرير إحصائية بحجم المبيعات'!$B$287:$L$313,3,FALSE) -> 0 | M10: =VLOOKUP($A$8,'تقرير إحصائية بحجم المبيعات'!$B$322:$L$347,3,FALSE) -> 0 | N10: =VLOOKUP($A$8,'تقرير إحصائية بحجم المبيعات'!$B$357:$L$383,3,FALSE) -> 0 | O10: =VLOOKUP($A$8,'تقرير إحصائية بحجم المبيعات'!$B$391:$L$420,3,FALSE) -> 0 | P10: =SUM(D10:O10) -> 3583252.6
C11: اجل | D11: =VLOOKUP($A$8,'تقرير إحصائية بحجم المبيعات'!$B$7:$L$31,4,FALSE) -> 1830740 | E11: =VLOOKUP($A$8,'تقرير إحصائية بحجم المبيعات'!$B$42:$G$73,4,FALSE) -> 1617987.7 | F11: =VLOOKUP($A$8,'تقرير إحصائية بحجم المبيعات'!$B$78:$E$103,4,FALSE) -> 2270709.9 | G11: =VLOOKUP($A$8,'تقرير إحصائية بحجم المبيعات'!$B$112:$G$137,4,FALSE) -> 2525266.6 | H11: =VLOOKUP($A$8,'تقرير إحصائية بحجم المبيعات'!$B$147:$G$177,4,FALSE) -> 2991551.5 | I11: =VLOOKUP($A$8,'تقرير إحصائية بحجم المبيعات'!$B$182:$G$212,4,FALSE) -> 0 | J11: =VLOOKUP($A$8,'تقرير إحصائية بحجم المبيعات'!$B$217:$L$243,4,FALSE) -> 0 | K11: =VLOOKUP($A$8,'تقرير إحصائية بحجم المبيعات'!$B$252:$L$278,4,FALSE) -> 0 | L11: =VLOOKUP($A$8,'تقرير إحصائية بحجم المبيعات'!$B$287:$L$313,4,FALSE) -> 0 | M11: =VLOOKUP($A$8,'تقرير إحصائية بحجم المبيعات'!$B$322:$L$347,4,FALSE) -> 0 | N11: =VLOOKUP($A$8,'تقرير إحصائية بحجم المبيعات'!$B$357:$L$383,4,FALSE) -> 0 | O11: =VLOOKUP($A$8,'تقرير إحصائية بحجم المبيعات'!$B$391:$L$420,4,FALSE) -> 0 | P11: =SUM(D11:O11) -> 11236256
C12: تكلفة البضاعة المباعة | D12: =VLOOKUP($A$8,'تقرير إحصائية بحجم المبيعات'!$B$7:$L$31,11,FALSE) -> 5833081.1 | E12: =VLOOKUP($A$8,'تقرير إحصائية بحجم المبيعات'!$B$42:$L$73,11,FALSE) -> 4993948.6 | F12: =VLOOKUP($A$8,'تقرير إحصائية بحجم المبيعات'!$B$78:$L$103,11,FALSE) -> 6465151.2 | G12: =VLOOKUP($A$8,'تقرير إحصائية بحجم المبيعات'!$B$112:$L$137,11,FALSE) -> 6707669.3 | H12: =VLOOKUP($A$8,'تقرير إحصائية بحجم المبيعات'!$B$147:$L$177,11,FALSE) -> 7518966.6 | I12: =VLOOKUP($A$8,'تقرير إحصائية بحجم المبيعات'!$B$182:$L$212,11,FALSE) -> 0 | J12: =VLOOKUP($A$8,'تقرير إحصائية بحجم المبيعات'!$B$217:$L$243,11,FALSE) -> 0 | K12: =VLOOKUP($A$8,'تقرير إحصائية بحجم المبيعات'!$B$252:$L$278,11,FALSE) -> 0 | L12: =VLOOKUP($A$8,'تقرير إحصائية بحجم المبيعات'!$B$287:$L$313,11,FALSE) -> 0 | M12: =VLOOKUP($A$8,'تقرير إحصائية بحجم المبيعات'!$B$322:$L$347,11,FALSE) -> 0 | N12: =VLOOKUP($A$8,'تقرير إحصائية بحجم المبيعات'!$B$357:$L$383,11,FALSE) -> 0 | O12: =VLOOKUP($A$8,'تقرير إحصائية بحجم المبيعات'!$B$391:$L$420,11,FALSE) -> 0 | P12: =SUM(D12:O12) -> 31518817
C13: مجمل الربح | D13: =D8-D12 -> 1600095.5 | E13: =E8-E12 -> 1308542.5 | F13: =F8-F12 -> 1637422.2 | G13: =G8-G12 -> 1686811.3 | H13: =H8-H12 -> 2091319.5 | I13: =I8-I12 -> 1000000 | J13: =J8-J12 -> 1000000 | K13: =K8-K12 -> 1000000 | ... O13: =O8-O12 -> 1000000 | P13: =SUM(D13:O13) -> 15324191
C14: خصم نقدى | P14: =SUM(D14:O14) -> 0
C15: ارباح صرف اصناف بيع اصول | P15: =SUM(D15:O15) -> 0
C16: فائض جرد | E16: 2690.8 | F16: 0.16 | P16: =SUM(D16:O16) -> 2690.96
C17: ايرادات اخرى | E17: 2340 | P17: =SUM(D17:O17) -> 2340
C18: إجمالي الايرادات اخرى | D18: =SUM(D14:D17) -> 0 | E18: =SUM(E14:E17) -> 5030.8 | F18: =SUM(F14:F17) -> 0.16 | G18: =SUM(G14:G17) -> 0 | H18: =SUM(H14:H17) -> 0 | I18: =SUM(I14:I17) -> 0 | J18: =SUM(J14:J17) -> 0 | K18: =SUM(K14:K17) -> 0 | ... O18: =SUM(O14:O17) -> 0 | P18: =SUM(D18:O18) -> 5030.96
C19: مجمل الربح | D19: =D13+D18 -> 1600095.5 | E19: =E13+E18 -> 1313573.3 | F19: =F13+F18 -> 1637422.3 | G19: =G13+G18 -> 1686811.3 | H19: =H13+H18 -> 2091319.5 | I19: =I13+I18 -> 1000000 | J19: =J13+J18 -> 1000000 | K19: =K13+K18 -> 1000000 | ... O19: =O13+O18 -> 1000000 | P19: =SUM(D19:O19) -> 15329222
C21: EXPENSE DETAILS | D21: =D23/D8 -> 0.063338422
C22: مرتبات الادارة | D22: =IFERROR(VLOOKUP(C22,'تقرير المصروفات حسب الشهر'!$C$10:$AD$119,3,FALSE),0) -> 0 | E22: =IFERROR(VLOOKUP(C22,'تقرير المصروفات حسب الشهر'!$C$136:$AD$245,3,FALSE),0) -> 0 | F22: =VLOOKUP(C22,'تقرير المصروفات حسب الشهر'!C262:AI378,3,0) -> 0 | G22: =IFERROR(VLOOKUP(C22,'تقرير المصروفات حسب الشهر'!$C$391:$AD$510,3,FALSE),0) -> 0 | H22: =IFERROR(VLOOKUP(C22,'تقرير المصروفات حسب الشهر'!$C$519:$AD$627,3,FALSE),0) -> 0 | I22: =IFERROR(VLOOKUP(C22,'تقرير المصروفات حسب الشهر'!$C$644:$AD$753,3,FALSE),0) -> 0 | J22: =IFERROR(VLOOKUP(C22,'تقرير المصروفات حسب الشهر'!$C$770:$AD$879,3,FALSE),0) -> 0 | K22: =IFERROR(VLOOKUP(C22,'تقرير المصروفات حسب الشهر'!$C$897:$AD$1006,3,FALSE),0) -> 0 | L22: =IFERROR(VLOOKUP(C22,'تقرير المصروفات حسب الشهر'!$C$1023:$AD$1133,3,FALSE),0) -> 0 | M22: =IFERROR(VLOOKUP(C22,'تقرير المصروفات حسب الشهر'!$C$1150:$AD$1261,3,FALSE),0) -> 0 | N22: =IFERROR(VLOOKUP(C22,'تقرير المصروفات حسب الشهر'!$C$1277:$AD$1388,3,FALSE),0) -> 0 | O22: =IFERROR(VLOOKUP(C22,'تقرير المصروفات حسب الشهر'!$C$1404:$AI$1519,3,FALSE),0) -> 0 | P22: =SUM(D22:O22) -> 0
C23: مرتبات الفروع | D23: =IFERROR(VLOOKUP(C23,'تقرير المصروفات حسب الشهر'!$C$10:$AD$119,3,FALSE),0) -> 470805.68 | E23: =IFERROR(VLOOKUP(C23,'تقرير المصروفات حسب الشهر'!$C$136:$AD$245,3,FALSE),0) -> 438097.43 | F23: =VLOOKUP(C23,'تقرير المصروفات حسب الشهر'!C263:AI379,3,0) -> 437682.06 | G23: =IFERROR(VLOOKUP(C23,'تقرير المصروفات حسب الشهر'!$C$391:$AD$510,3,FALSE),0) -> 473266.56 | H23: =IFERROR(VLOOKUP(C23,'تقرير المصروفات حسب الشهر'!$C$519:$AD$627,3,FALSE),0) -> 325607.85 | I23: =IFERROR(VLOOKUP(C23,'تقرير المصروفات حسب الشهر'!$C$644:$AD$753,3,FALSE),0) -> 0 | J23: =IFERROR(VLOOKUP(C23,'تقرير المصروفات حسب الشهر'!$C$770:$AD$879,3,FALSE),0) -> 0 | K23: =IFERROR(VLOOKUP(C23,'تقرير المصروفات حسب الشهر'!$C$897:$AD$1006,3,FALSE),0) -> 0 | L23: =IFERROR(VLOOKUP(C23,'تقرير المصروفات حسب الشهر'!$C$1023:$AD$1133,3,FALSE),0) -> 0 | M23: =IFERROR(VLOOKUP(C23,'تقرير المصروفات حسب الشهر'!$C$1150:$AD$1261,3,FALSE),0) -> 0 | N23: =IFERROR(VLOOKUP(C23,'تقرير المصروفات حسب الشهر'!$C$1277:$AD$1388,3,FALSE),0) -> 0 | O23: =IFERROR(VLOOKUP(C23,'تقرير المصروفات حسب الشهر'!$C$1404:$AI$1519,3,FALSE),0) -> 0 | P23: =SUM(D23:O23) -> 2145459.6
C24: الكهرباء | D24: =IFERROR(VLOOKUP(C24,'تقرير المصروفات حسب الشهر'!$C$10:$AD$119,3,FALSE),0) -> 9191 | E24: =IFERROR(VLOOKUP(C24,'تقرير المصروفات حسب الشهر'!$C$136:$AD$245,3,FALSE),0) -> 3414 | F24: =VLOOKUP(C24,'تقرير المصروفات حسب الشهر'!C264:AI380,3,0) -> 0 | G24: =IFERROR(VLOOKUP(C24,'تقرير المصروفات حسب الشهر'!$C$391:$AD$510,3,FALSE),0) -> 7277 | H24: =IFERROR(VLOOKUP(C24,'تقرير المصروفات حسب الشهر'!$C$519:$AD$627,3,FALSE),0) -> 5455 | I24: =IFERROR(VLOOKUP(C24,'تقرير المصروفات حسب الشهر'!$C$644:$AD$753,3,FALSE),0) -> 0 | J24: =IFERROR(VLOOKUP(C24,'تقرير المصروفات حسب الشهر'!$C$770:$AD$879,3,FALSE),0) -> 0 | K24: =IFERROR(VLOOKUP(C24,'تقرير المصروفات حسب الشهر'!$C$897:$AD$1006,3,FALSE),0) -> 0 | L24: =IFERROR(VLOOKUP(C24,'تقرير المصروفات حسب الشهر'!$C$1023:$AD$1133,3,FALSE),0) -> 0 | M24: =IFERROR(VLOOKUP(C24,'تقرير المصروفات حسب الشهر'!$C$1150:$AD$1261,3,FALSE),0) -> 0 | N24: =IFERROR(VLOOKUP(C24,'تقرير المصروفات حسب الشهر'!$C$1277:$AD$1388,3,FALSE),0) -> 0 | O24: =IFERROR(VLOOKUP(C24,'تقرير المصروفات حسب الشهر'!$C$1404:$AI$1519,3,FALSE),0) -> 0 | P24: =SUM(D24:O24) -> 25337
C25: المياه | D25: =IFERROR(VLOOKUP(C25,'تقرير المصروفات حسب الشهر'!$C$10:$AD$119,3,FALSE),0) -> 650 | E25: =IFERROR(VLOOKUP(C25,'تقرير المصروفات حسب الشهر'!$C$136:$AD$245,3,FALSE),0) -> 650 | F25: =VLOOKUP(C25,'تقرير المصروفات حسب الشهر'!C265:AI381,3,0) -> 600 | G25: =IFERROR(VLOOKUP(C25,'تقرير المصروفات حسب الشهر'!$C$391:$AD$510,3,FALSE),0) -> 0 | H25: =IFERROR(VLOOKUP(C25,'تقرير المصروفات حسب الشهر'!$C$519:$AD$627,3,FALSE),0) -> 960 | I25: =IFERROR(VLOOKUP(C25,'تقرير المصروفات حسب الشهر'!$C$644:$AD$753,3,FALSE),0) -> 0 | J25: =IFERROR(VLOOKUP(C25,'تقرير المصروفات حسب الشهر'!$C$770:$AD$879,3,FALSE),0) -> 0 | K25: =IFERROR(VLOOKUP(C25,'تقرير المصروفات حسب الشهر'!$C$897:$AD$1006,3,FALSE),0) -> 0 | L25: =IFERROR(VLOOKUP(C25,'تقرير المصروفات حسب الشهر'!$C$1023:$AD$1133,3,FALSE),0) -> 0 | M25: =IFERROR(VLOOKUP(C25,'تقرير المصروفات حسب الشهر'!$C$1150:$AD$1261,3,FALSE),0) -> 0 | N25: =IFERROR(VLOOKUP(C25,'تقرير المصروفات حسب الشهر'!$C$1277:$AD$1388,3,FALSE),0) -> 0 | O25: =IFERROR(VLOOKUP(C25,'تقرير المصروفات حسب الشهر'!$C$1404:$AI$1519,3,FALSE),0) -> 0 | P25: =SUM(D25:O25) -> 2860
C26: التليفون الارضي | D26: =IFERROR(VLOOKUP(C26,'تقرير المصروفات حسب الشهر'!$C$10:$AD$119,3,FALSE),0) -> 0 | E26: =IFERROR(VLOOKUP(C26,'تقرير المصروفات حسب الشهر'!$C$136:$AD$245,3,FALSE),0) -> 1200 | F26: =VLOOKUP(C26,'تقرير المصروفات حسب الشهر'!C266:AI382,3,0) -> 0 | G26: =IFERROR(VLOOKUP(C26,'تقرير المصروفات حسب الشهر'!$C$391:$AD$510,3,FALSE),0) -> 0 | H26: =IFERROR(VLOOKUP(C26,'تقرير المصروفات حسب الشهر'!$C$519:$AD$627,3,FALSE),0) -> 0 | I26: =IFERROR(VLOOKUP(C26,'تقرير المصروفات حسب الشهر'!$C$644:$AD$753,3,FALSE),0) -> 0 | J26: =IFERROR(VLOOKUP(C26,'تقرير المصروفات حسب الشهر'!$C$770:$AD$879,3,FALSE),0) -> 0 | K26: =IFERROR(VLOOKUP(C26,'تقرير المصروفات حسب الشهر'!$C$897:$AD$1006,3,FALSE),0) -> 0 | L26: =IFERROR(VLOOKUP(C26,'تقرير المصروفات حسب الشهر'!$C$1023:$AD$1133,3,FALSE),0) -> 0 | M26: =IFERROR(VLOOKUP(C26,'تقرير المصروفات حسب الشهر'!$C$1150:$AD$1261,3,FALSE),0) -> 0 | N26: =IFERROR(VLOOKUP(C26,'تقرير المصروفات حسب الشهر'!$C$1277:$AD$1388,3,FALSE),0) -> 0 | O26: =IFERROR(VLOOKUP(C26,'تقرير المصروفات حسب الشهر'!$C$1404:$AI$1519,3,FALSE),0) -> 0 | P26: =SUM(D26:O26) -> 1200
C27: الايجار - الصيدلية | D27: =IFERROR(VLOOKUP(C27,'تقرير المصروفات حسب الشهر'!$C$10:$AD$119,3,FALSE),0) -> 170000 | E27: =IFERROR(VLOOKUP(C27,'تقرير المصروفات حسب الشهر'!$C$136:$AD$245,3,FALSE),0) -> 170000 | F27: =VLOOKUP(C27,'تقرير المصروفات حسب الشهر'!C267:AI383,3,0) -> 170000 | G27: =IFERROR(VLOOKUP(C27,'تقرير المصروفات حسب الشهر'!$C$391:$AD$510,3,FALSE),0) -> 170000 | H27: =IFERROR(VLOOKUP(C27,'تقرير المصروفات حسب الشهر'!$C$519:$AD$627,3,FALSE),0) -> 170000 | I27: =IFERROR(VLOOKUP(C27,'تقرير المصروفات حسب الشهر'!$C$644:$AD$753,3,FALSE),0) -> 0 | J27: =IFERROR(VLOOKUP(C27,'تقرير المصروفات حسب الشهر'!$C$770:$AD$879,3,FALSE),0) -> 0 | K27: =IFERROR(VLOOKUP(C27,'تقرير المصروفات حسب الشهر'!$C$897:$AD$1006,3,FALSE),0) -> 0 | L27: =IFERROR(VLOOKUP(C27,'تقرير المصروفات حسب الشهر'!$C$1023:$AD$1133,3,FALSE),0) -> 0 | M27: =IFERROR(VLOOKUP(C27,'تقرير المصروفات حسب الشهر'!$C$1150:$AD$1261,3,FALSE),0) -> 0 | N27: =IFERROR(VLOOKUP(C27,'تقرير المصروفات حسب الشهر'!$C$1277:$AD$1388,3,FALSE),0) -> 0 | O27: =IFERROR(VLOOKUP(C27,'تقرير المصروفات حسب الشهر'!$C$1404:$AI$1519,3,FALSE),0) -> 0 | P27: =SUM(D27:O27) -> 850000
C28: الايجار - الادارة | D28: =IFERROR(VLOOKUP(C28,'تقرير المصروفات حسب الشهر'!$C$10:$AD$119,3,FALSE),0) -> 0 | E28: =IFERROR(VLOOKUP(C28,'تقرير المصروفات حسب الشهر'!$C$136:$AD$245,3,FALSE),0) -> 0 | F28: =VLOOKUP(C28,'تقرير المصروفات حسب الشهر'!C268:AI384,3,0) -> 0 | G28: =IFERROR(VLOOKUP(C28,'تقرير المصروفات حسب الشهر'!$C$391:$AD$510,3,FALSE),0) -> 0 | H28: =IFERROR(VLOOKUP(C28,'تقرير المصروفات حسب الشهر'!$C$519:$AD$627,3,FALSE),0) -> 0 | I28: =IFERROR(VLOOKUP(C28,'تقرير المصروفات حسب الشهر'!$C$644:$AD$753,3,FALSE),0) -> 0 | J28: =IFERROR(VLOOKUP(C28,'تقرير المصروفات حسب الشهر'!$C$770:$AD$879,3,FALSE),0) -> 0 | K28: =IFERROR(VLOOKUP(C28,'تقرير المصروفات حسب الشهر'!$C$897:$AD$1006,3,FALSE),0) -> 0 | L28: =IFERROR(VLOOKUP(C28,'تقرير المصروفات حسب الشهر'!$C$1023:$AD$1133,3,FALSE),0) -> 0 | M28: =IFERROR(VLOOKUP(C28,'تقرير المصروفات حسب الشهر'!$C$1150:$AD$1261,3,FALSE),0) -> 0 | N28: =IFERROR(VLOOKUP(C28,'تقرير المصروفات حسب الشهر'!$C$1277:$AD$1388,3,FALSE),0) -> 0 | O28: =IFERROR(VLOOKUP(C28,'تقرير المصروفات حسب الشهر'!$C$1404:$AI$1519,3,FALSE),0) -> 0 | P28: =SUM(D28:O28) -> 0
C29: ايجارات متنوعه | D29: =IFERROR(VLOOKUP(C29,'تقرير المصروفات حسب الشهر'!$C$10:$AD$119,3,FALSE),0) -> 0 | E29: =IFERROR(VLOOKUP(C29,'تقرير المصروفات حسب الشهر'!$C$136:$AD$245,3,FALSE),0) -> 26250 | F29: =VLOOKUP(C29,'تقرير المصروفات حسب الشهر'!C269:AI385,3,0) -> 3500 | G29: =IFERROR(VLOOKUP(C29,'تقرير المصروفات حسب الشهر'!$C$391:$AD$510,3,FALSE),0) -> 3500 | H29: =IFERROR(VLOOKUP(C29,'تقرير المصروفات حسب الشهر'!$C$519:$AD$627,3,FALSE),0) -> 3500 | I29: =IFERROR(VLOOKUP(C29,'تقرير المصروفات حسب الشهر'!$C$644:$AD$753,3,FALSE),0) -> 0 | J29: =IFERROR(VLOOKUP(C29,'تقرير المصروفات حسب الشهر'!$C$770:$AD$879,3,FALSE),0) -> 0 | K29: =IFERROR(VLOOKUP(C29,'تقرير المصروفات حسب الشهر'!$C$897:$AD$1006,3,FALSE),0) -> 0 | L29: =IFERROR(VLOOKUP(C29,'تقرير المصروفات حسب الشهر'!$C$1023:$AD$1133,3,FALSE),0) -> 0 | M29: =IFERROR(VLOOKUP(C29,'تقرير المصروفات حسب الشهر'!$C$1150:$AD$1261,3,FALSE),0) -> 0 | N29: =IFERROR(VLOOKUP(C29,'تقرير المصروفات حسب الشهر'!$C$1277:$AD$1388,3,FALSE),0) -> 0 | O29: =IFERROR(VLOOKUP(C29,'تقرير المصروفات حسب الشهر'!$C$1404:$AI$1519,3,FALSE),0) -> 0 | P29: =SUM(D29:O29) -> 36750
C30: ادوات مكتبية | D30: =IFERROR(VLOOKUP(C30,'تقرير المصروفات حسب الشهر'!$C$10:$AD$119,3,FALSE),0) -> 65 | E30: =IFERROR(VLOOKUP(C30,'تقرير المصروفات حسب الشهر'!$C$136:$AD$245,3,FALSE),0) -> 0 | F30: =VLOOKUP(C30,'تقرير المصروفات حسب الشهر'!C270:AI386,3,0) -> 1130 | G30: =IFERROR(VLOOKUP(C30,'تقرير المصروفات حسب الشهر'!$C$391:$AD$510,3,FALSE),0) -> 30 | H30: =IFERROR(VLOOKUP(C30,'تقرير المصروفات حسب الشهر'!$C$519:$AD$627,3,FALSE),0) -> 1225 | I30: =IFERROR(VLOOKUP(C30,'تقرير المصروفات حسب الشهر'!$C$644:$AD$753,3,FALSE),0) -> 0 | J30: =IFERROR(VLOOKUP(C30,'تقرير المصروفات حسب الشهر'!$C$770:$AD$879,3,FALSE),0) -> 0 | K30: =IFERROR(VLOOKUP(C30,'تقرير المصروفات حسب الشهر'!$C$897:$AD$1006,3,FALSE),0) -> 0 | L30: =IFERROR(VLOOKUP(C30,'تقرير المصروفات حسب الشهر'!$C$1023:$AD$1133,3,FALSE),0) -> 0 | M30: =IFERROR(VLOOKUP(C30,'تقرير المصروفات حسب الشهر'!$C$1150:$AD$1261,3,FALSE),0) -> 0 | N30: =IFERROR(VLOOKUP(C30,'تقرير المصروفات حسب الشهر'!$C$1277:$AD$1388,3,FALSE),0) -> 0 | O30: =IFERROR(VLOOKUP(C30,'تقرير المصروفات حسب الشهر'!$C$1404:$AI$1519,3,FALSE),0) -> 0 | P30: =SUM(D30:O30) -> 2450
C31: فواتير الموبايل | D31: =IFERROR(VLOOKUP(C31,'تقرير المصروفات حسب الشهر'!$C$10:$AD$119,3,FALSE),0) -> 721.98 | E31: =IFERROR(VLOOKUP(C31,'تقرير المصروفات حسب الشهر'!$C$136:$AD$245,3,FALSE),0) -> 721 | F31: =VLOOKUP(C31,'تقرير المصروفات حسب الشهر'!C271:AI387,3,0) -> 724.56 | G31: =IFERROR(VLOOKUP(C31,'تقرير المصروفات حسب الشهر'!$C$391:$AD$510,3,FALSE),0) -> 721.98 | H31: =IFERROR(VLOOKUP(C31,'تقرير المصروفات حسب الشهر'!$C$519:$AD$627,3,FALSE),0) -> 721.98 | I31: =IFERROR(VLOOKUP(C31,'تقرير المصروفات حسب الشهر'!$C$644:$AD$753,3,FALSE),0) -> 0 | J31: =IFERROR(VLOOKUP(C31,'تقرير المصروفات حسب الشهر'!$C$770:$AD$879,3,FALSE),0) -> 0 | K31: =IFERROR(VLOOKUP(C31,'تقرير المصروفات حسب الشهر'!$C$897:$AD$1006,3,FALSE),0) -> 0 | L31: =IFERROR(VLOOKUP(C31,'تقرير المصروفات حسب الشهر'!$C$1023:$AD$1133,3,FALSE),0) -> 0 | M31: =IFERROR(VLOOKUP(C31,'تقرير المصروفات حسب الشهر'!$C$1150:$AD$1261,3,FALSE),0) -> 0 | N31: =IFERROR(VLOOKUP(C31,'تقرير المصروفات حسب الشهر'!$C$1277:$AD$1388,3,FALSE),0) -> 0 | O31: =IFERROR(VLOOKUP(C31,'تقرير المصروفات حسب الشهر'!$C$1404:$AI$1519,3,FALSE),0) -> 0 | P31: =SUM(D31:O31) -> 3611.5
C32: مكافات مبيعات الادوية | D32: =IFERROR(VLOOKUP(C32,'تقرير المصروفات حسب الشهر'!$C$10:$AD$119,3,FALSE),0) -> 0 | E32: =IFERROR(VLOOKUP(C32,'تقرير المصروفات حسب الشهر'!$C$136:$AD$245,3,FALSE),0) -> 0 | F32: =VLOOKUP(C32,'تقرير المصروفات حسب الشهر'!C272:AI388,3,0) -> 0 | G32: =IFERROR(VLOOKUP(C32,'تقرير المصروفات حسب الشهر'!$C$391:$AD$510,3,FALSE),0) -> 0 | H32: =IFERROR(VLOOKUP(C32,'تقرير المصروفات حسب الشهر'!$C$519:$AD$627,3,FALSE),0) -> 0 | I32: =IFERROR(VLOOKUP(C32,'تقرير المصروفات حسب الشهر'!$C$644:$AD$753,3,FALSE),0) -> 0 | J32: =IFERROR(VLOOKUP(C32,'تقرير المصروفات حسب الشهر'!$C$770:$AD$879,3,FALSE),0) -> 0 | K32: =IFERROR(VLOOKUP(C32,'تقرير المصروفات حسب الشهر'!$C$897:$AD$1006,3,FALSE),0) -> 0 | L32: =IFERROR(VLOOKUP(C32,'تقرير المصروفات حسب الشهر'!$C$1023:$AD$1133,3,FALSE),0) -> 0 | M32: =IFERROR(VLOOKUP(C32,'تقرير المصروفات حسب الشهر'!$C$1150:$AD$1261,3,FALSE),0) -> 0 | N32: =IFERROR(VLOOKUP(C32,'تقرير المصروفات حسب الشهر'!$C$1277:$AD$1388,3,FALSE),0) -> 0 | O32: =IFERROR(VLOOKUP(C32,'تقرير المصروفات حسب الشهر'!$C$1404:$AI$1519,3,FALSE),0) -> 0 | P32: =SUM(D32:O32) -> 0
C33: مكافات مبيعات التجميل | D33: =IFERROR(VLOOKUP(C33,'تقرير المصروفات حسب الشهر'!$C$10:$AD$119,3,FALSE),0) -> 1000 | E33: =IFERROR(VLOOKUP(C33,'تقرير المصروفات حسب الشهر'!$C$136:$AD$245,3,FALSE),0) -> 3760 | F33: =VLOOKUP(C33,'تقرير المصروفات حسب الشهر'!C273:AI389,3,0) -> 0 | G33: =IFERROR(VLOOKUP(C33,'تقرير المصروفات حسب الشهر'!$C$391:$AD$510,3,FALSE),0) -> 0 | H33: =IFERROR(VLOOKUP(C33,'تقرير المصروفات حسب الشهر'!$C$519:$AD$627,3,FALSE),0) -> 1780 | I33: =IFERROR(VLOOKUP(C33,'تقرير المصروفات حسب الشهر'!$C$644:$AD$753,3,FALSE),0) -> 0 | J33: =IFERROR(VLOOKUP(C33,'تقرير المصروفات حسب الشهر'!$C$770:$AD$879,3,FALSE),0) -> 0 | K33: =IFERROR(VLOOKUP(C33,'تقرير المصروفات حسب الشهر'!$C$897:$AD$1006,3,FALSE),0) -> 0 | L33: =IFERROR(VLOOKUP(C33,'تقرير المصروفات حسب الشهر'!$C$1023:$AD$1133,3,FALSE),0) -> 0 | M33: =IFERROR(VLOOKUP(C33,'تقرير المصروفات حسب الشهر'!$C$1150:$AD$1261,3,FALSE),0) -> 0 | N33: =IFERROR(VLOOKUP(C33,'تقرير المصروفات حسب الشهر'!$C$1277:$AD$1388,3,FALSE),0) -> 0 | O33: =IFERROR(VLOOKUP(C33,'تقرير المصروفات حسب الشهر'!$C$1404:$AI$1519,3,FALSE),0) -> 0 | P33: =SUM(D33:O33) -> 6540
... C109: هوالك وتوالف | D109: =IFERROR(VLOOKUP(C109,'تقرير المصروفات حسب الشهر'!$C$10:$AD$119,3,FALSE),0) -> 0 | E109: =IFERROR(VLOOKUP(C109,'تقرير المصروفات حسب الشهر'!$C$136:$AD$245,3,FALSE),0) -> 0 | F109: =VLOOKUP(C109,'تقرير المصروفات حسب الشهر'!C349:AI465,3,0) -> 11382.3 | G109: =IFERROR(VLOOKUP(C109,'تقرير المصروفات حسب الشهر'!$C$391:$AD$510,3,FALSE),0) -> 0 | H109: =IFERROR(VLOOKUP(C109,'تقرير المصروفات حسب الشهر'!$C$519:$AD$627,3,FALSE),0) -> 0 | I109: =IFERROR(VLOOKUP(C109,'تقرير المصروفات حسب الشهر'!$C$644:$AD$753,3,FALSE),0) -> 0 | J109: =IFERROR(VLOOKUP(C109,'تقرير المصروفات حسب الشهر'!$C$770:$AD$879,3,FALSE),0) -> 0 | K109: =IFERROR(VLOOKUP(C109,'تقرير المصروفات حسب الشهر'!$C$897:$AD$1006,3,FALSE),0) -> 0 | L109: =IFERROR(VLOOKUP(C109,'تقرير المصروفات حسب الشهر'!$C$1023:$AD$1133,3,FALSE),0) -> 0 | M109: =IFERROR(VLOOKUP(C109,'تقرير المصروفات حسب الشهر'!$C$1150:$AD$1261,3,FALSE),0) -> 0 | N109: =IFERROR(VLOOKUP(C109,'تقرير المصروفات حسب الشهر'!$C$1277:$AD$1388,3,FALSE),0) -> 0 | O109: =IFERROR(VLOOKUP(C109,'تقرير المصروفات حسب الشهر'!$C$1404:$AI$1519,3,FALSE),0) -> 0 | P109: =SUM(D109:O109) -> 11382.3
C110: عجز جرد | D110: 0.23 | E110: =IFERROR(VLOOKUP(C110,'تقرير المصروفات حسب الشهر'!$C$136:$AD$245,3,FALSE),0) -> 0 | F110: =VLOOKUP(C110,'تقرير المصروفات حسب الشهر'!C350:AI466,3,0) -> 0 | G110: =IFERROR(VLOOKUP(C110,'تقرير المصروفات حسب الشهر'!$C$391:$AD$510,3,FALSE),0) -> 564.93 | H110: =IFERROR(VLOOKUP(C110,'تقرير المصروفات حسب الشهر'!$C$519:$AD$627,3,FALSE),0) -> 0 | I110: =IFERROR(VLOOKUP(C110,'تقرير المصروفات حسب الشهر'!$C$644:$AD$753,3,FALSE),0) -> 0 | J110: =IFERROR(VLOOKUP(C110,'تقرير المصروفات حسب الشهر'!$C$770:$AD$879,3,FALSE),0) -> 0 | K110: =IFERROR(VLOOKUP(C110,'تقرير المصروفات حسب الشهر'!$C$897:$AD$1006,3,FALSE),0) -> 0 | L110: =IFERROR(VLOOKUP(C110,'تقرير المصروفات حسب الشهر'!$C$1023:$AD$1133,3,FALSE),0) -> 0 | M110: =IFERROR(VLOOKUP(C110,'تقرير المصروفات حسب الشهر'!$C$1150:$AD$1261,3,FALSE),0) -> 0 | N110: =IFERROR(VLOOKUP(C110,'تقرير المصروفات حسب الشهر'!$C$1277:$AD$1388,3,FALSE),0) -> 0 | O110: =IFERROR(VLOOKUP(C110,'تقرير المصروفات حسب الشهر'!$C$1404:$AI$1519,3,FALSE),0) -> 0 | P110: =SUM(D110:O110) -> 565.16
C111: تامين على السيارات | D111: =IFERROR(VLOOKUP(C111,'تقرير المصروفات حسب الشهر'!$C$10:$AD$119,3,FALSE),0) -> 0 | E111: =IFERROR(VLOOKUP(C111,'تقرير المصروفات حسب الشهر'!$C$136:$AD$245,3,FALSE),0) -> 0 | F111: =VLOOKUP(C111,'تقرير المصروفات حسب الشهر'!C351:AI467,3,0) -> 0 | G111: =IFERROR(VLOOKUP(C111,'تقرير المصروفات حسب الشهر'!$C$391:$AD$510,3,FALSE),0) -> 0 | H111: =IFERROR(VLOOKUP(C111,'تقرير المصروفات حسب الشهر'!$C$519:$AD$627,3,FALSE),0) -> 0 | I111: =IFERROR(VLOOKUP(C111,'تقرير المصروفات حسب الشهر'!$C$644:$AD$753,3,FALSE),0) -> 0 | J111: =IFERROR(VLOOKUP(C111,'تقرير المصروفات حسب الشهر'!$C$770:$AD$879,3,FALSE),0) -> 0 | K111: =IFERROR(VLOOKUP(C111,'تقرير المصروفات حسب الشهر'!$C$897:$AD$1006,3,FALSE),0) -> 0 | L111: =IFERROR(VLOOKUP(C111,'تقرير المصروفات حسب الشهر'!$C$1023:$AD$1133,3,FALSE),0) -> 0 | M111: =IFERROR(VLOOKUP(C111,'تقرير المصروفات حسب الشهر'!$C$1150:$AD$1261,3,FALSE),0) -> 0 | N111: =IFERROR(VLOOKUP(C111,'تقرير المصروفات حسب الشهر'!$C$1277:$AD$1388,3,FALSE),0) -> 0 | O111: =IFERROR(VLOOKUP(C111,'تقرير المصروفات حسب الشهر'!$C$1404:$AI$1519,3,FALSE),0) -> 0 | P111: =SUM(D111:O111) -> 0
C112: مصروفات عملاء تعاقدات | D112: =IFERROR(VLOOKUP(C112,'تقرير المصروفات حسب الشهر'!$C$10:$AD$119,3,FALSE),0) -> 0 | E112: =IFERROR(VLOOKUP(C112,'تقرير المصروفات حسب الشهر'!$C$136:$AD$245,3,FALSE),0) -> 0 | F112: =VLOOKUP(C112,'تقرير المصروفات حسب الشهر'!C352:AI468,3,0) -> 0 | G112: =IFERROR(VLOOKUP(C112,'تقرير المصروفات حسب الشهر'!$C$391:$AD$510,3,FALSE),0) -> 0 | H112: =IFERROR(VLOOKUP(C112,'تقرير المصروفات حسب الشهر'!$C$519:$AD$627,3,FALSE),0) -> 0 | I112: =IFERROR(VLOOKUP(C112,'تقرير المصروفات حسب الشهر'!$C$644:$AD$753,3,FALSE),0) -> 0 | J112: =IFERROR(VLOOKUP(C112,'تقرير المصروفات حسب الشهر'!$C$770:$AD$879,3,FALSE),0) -> 0 | K112: =IFERROR(VLOOKUP(C112,'تقرير المصروفات حسب الشهر'!$C$897:$AD$1006,3,FALSE),0) -> 0 | L112: =IFERROR(VLOOKUP(C112,'تقرير المصروفات حسب الشهر'!$C$1023:$AD$1133,3,FALSE),0) -> 0 | M112: =IFERROR(VLOOKUP(C112,'تقرير المصروفات حسب الشهر'!$C$1150:$AD$1261,3,FALSE),0) -> 0 | N112: =IFERROR(VLOOKUP(C112,'تقرير المصروفات حسب الشهر'!$C$1277:$AD$1388,3,FALSE),0) -> 0 | O112: =IFERROR(VLOOKUP(C112,'تقرير المصروفات حسب الشهر'!$C$1404:$AI$1519,3,FALSE),0) -> 0 | P112: =SUM(D112:O112) -> 0
C113: ارباح دائنون متنوعون | D113: =IFERROR(VLOOKUP(C113,'تقرير المصروفات حسب الشهر'!$C$10:$AD$119,3,FALSE),0) -> 0 | E113: =IFERROR(VLOOKUP(C113,'تقرير المصروفات حسب الشهر'!$C$136:$AD$245,3,FALSE),0) -> 0 | F113: =VLOOKUP(C113,'تقرير المصروفات حسب الشهر'!C353:AI469,3,0) -> 0 | G113: =IFERROR(VLOOKUP(C113,'تقرير المصروفات حسب الشهر'!$C$391:$AD$510,3,FALSE),0) -> 0 | H113: =IFERROR(VLOOKUP(C113,'تقرير المصروفات حسب الشهر'!$C$519:$AD$627,3,FALSE),0) -> 0 | I113: =IFERROR(VLOOKUP(C113,'تقرير المصروفات حسب الشهر'!$C$644:$AD$753,3,FALSE),0) -> 0 | J113: =IFERROR(VLOOKUP(C113,'تقرير المصروفات حسب الشهر'!$C$770:$AD$879,3,FALSE),0) -> 0 | K113: =IFERROR(VLOOKUP(C113,'تقرير المصروفات حسب الشهر'!$C$897:$AD$1006,3,FALSE),0) -> 0 | L113: =IFERROR(VLOOKUP(C113,'تقرير المصروفات حسب الشهر'!$C$1023:$AD$1133,3,FALSE),0) -> 0 | M113: =IFERROR(VLOOKUP(C113,'تقرير المصروفات حسب الشهر'!$C$1150:$AD$1261,3,FALSE),0) -> 0 | N113: =IFERROR(VLOOKUP(C113,'تقرير المصروفات حسب الشهر'!$C$1277:$AD$1388,3,FALSE),0) -> 0 | O113: =IFERROR(VLOOKUP(C113,'تقرير المصروفات حسب الشهر'!$C$1404:$AI$1519,3,FALSE),0) -> 0 | P113: =SUM(D113:O113) -> 0
